Workbook

Sheet PLP明细
A1: 统计周期 | B1: 广告活动 | C1: SKU | D1: ID | E1: 店铺 | F1: PLP开始日期 | G1: 实际上架日期 | H1: 首次出单日期 | I1: 4月分析人 | J1: 品类 | K1: 产品拓展 | L1: 广告曝光量 | M1: 广告点击量 | N1: 广告售出数 | O1: 广告花费 | P1: 广告销售额 | Q1: 总销售额 | R1: ROAS | S1: CVR | T1: CTR | U1: CPC | V1: CPA | W1: ACOS | X1: ACOAS
A2: 4.9-4.15 | B2: 总数据 | C2: 广告链接数量： | F2: 56 | J2: 总数据： | L2: 96271 | M2: 458 | N2: 54 | O2: 212.88 | P2: 5581.27 | R2: 26.217916 | S2: 0.11790393 | T2: 0.0047574036 | U2: 0.46480349 | V2: 3.9422222 | W2: 0.038141857
A3: 4.9-4.15 | B3: LYAP-X1929~张潇~smart | C3: LYAP-X1929 | D3: 177997475019 | E3: gogreenbike | F3: 46114 | G3: 46108 | H3: 46114 | I3: 张潇 | J3: 机盖及附件 | K3: 原开品 | L3: 845 | M3: 27 | N3: 12 | O3: 10.66 | P3: 454.26 | R3: 42.613508 | S3: 0.44444444 | T3: 0.031952663 | U3: 0.39481481 | V3: 0.88833333 | W3: 0.023466737
A4: 4.9-4.15 | B4: LYAP-X1992系列~张潇~smart~via | C4: LYAP-X1993 | D4: 227214980980 | E4: viautome | F4: 46077 | G4: 46066 | H4: 46070 | I4: 张潇 | J4: 饰条 | K4: 原开品 | L4: 5784 | M4: 18 | N4: 6 | O4: 8.26 | P4: 453.09 | R4: 54.853511 | S4: 0.33333333 | T4: 0.0031120332 | U4: 0.45888889 | V4: 1.3766667 | W4: 0.018230374
A5: 4.9-4.15 | B5: LYAM-X2575-2~张潇~smart~bap | C5: LYAM-X2575-2 | D5: 117032563600 | E5: best-autoparts(授权即将过期) | F5: 46083 | G5: 46062 | H5: 46068 | I5: 张潇 | J5: 车门系统 | K5: 拓展品 | L5: 5333 | M5: 50 | N5: 4 | O5: 20.21 | P5: 211.69 | R5: 10.474518 | S5: 0.08 | T5: 0.009375586 | U5: 0.4042 | V5: 5.0525 | W5: 0.095469791
A6: 4.9-4.15 | B6: LYAP-X1992系列~张潇~smart~via | C6: LYAP-X1992 | D6: 227214967031 | E6: viautome | F6: 46077 | G6: 46066 | H6: 46077 | I6: 张潇 | J6: 饰条 | K6: 原开品 | L6: 8199 | M6: 20 | N6: 4 | O6: 8.52 | P6: 295.23 | R6: 34.651408 | S6: 0.2 | T6: 0.0024393219 | U6: 0.426 | V6: 2.13 | W6: 0.028858856
A7: 4.9-4.15 | B7: LYAP-X2527~胡煜星~smart | C7: LYAP-X2527 | D7: 227241180103 | E7: viautome | F7: 46087 | G7: 46085 | H7: 46086 | I7: 胡煜星 | J7: 其他 | K7: 原开品 | L7: 7336 | M7: 37 | N7: 3 | O7: 10.08 | P7: 279.53 | R7: 27.731151 | S7: 0.081081081 | T7: 0.0050436205 | U7: 0.27243243 | V7: 3.36 | W7: 0.03606053
A8: 4.9-4.15 | B8: LYAP-838~张潇~smart~bike | C8: LYAP-838 | D8: 177997411142 | E8: gogreenbike | F8: 46109 | G8: 46108 | H8: 46116 | I8: 张潇 | J8: 饰条 | K8: 拓展品 | L8: 1944 | M8: 11 | N8: 3 | O8: 4.47 | P8: 276.64 | R8: 61.888143 | S8: 0.27272727 | T8: 0.0056584362 | U8: 0.40636364 | V8: 1.49 | W8: 0.016158184
A9: 4.9-4.15 | B9: MD-001~俞东旭 | C9: MD-001-RR | D9: 188171609056 | E9: gogreenbike | F9: 46098 | G9: 46097 | H9: 46099 | I9: 俞东旭 | J9: 车门系统 | K9: 原开品 | L9: 243 | M9: 14 | N9: 2 | O9: 13.58 | P9: 1252.73 | R9: 92.248159 | S9: 0.14285714 | T9: 0.057613169 | U9: 0.97 | V9: 6.79 | W9: 0.010840325
A10: 4.9-4.15 | B10: LYAM-X2570-1~章鹏~smart~flash | C10: LYAM-X2570-1 | D10: 117053097094 | E10: flashemotor | F10: 46115 | G10: 46070 | H10: 46073 | I10: 章鹏 | J10: 其他 | K10: 原开品 | L10: 1656 | M10: 5 | N10: 2 | O10: 2.27 | P10: 43.5 | R10: 19.162996 | S10: 0.4 | T10: 0.0030193237 | U10: 0.454 | V10: 1.135 | W10: 0.052183908
A11: 4.9-4.15 | B11: LYAP-X2148-1系列~王偲涵1 | C11: LYAP-X2148-1R | D11: 188144166107 | E11: gogreenbike | F11: 46114 | G11: 46092 | H11: 46112 | I11: 王偲涵 | J11: 饰条 | K11: 拓展品 | L11: 62 | M11: 2 | N11: 2 | O11: 0.74 | P11: 83.95 | R11: 113.44595 | S11: 1 | T11: 0.032258065 | U11: 0.37 | V11: 0.37 | W11: 0.0088147707
A12: 4.9-4.15 | B12: LYAP-X2289~张潇~smart | C12: LYAP-X2289 | D12: 177947769950 | E12: gogreenbike | F12: 46092 | G12: 46092 | H12: 46095 | I12: 张潇 | J12: 饰条 | K12: 原开品 | L12: 10215 | M12: 38 | N12: 1 | O12: 14.61 | P12: 123.46 | R12: 8.4503765 | S12: 0.026315789 | T12: 0.0037200196 | U12: 0.38447368 | V12: 14.61 | W12: 0.11833792
A13: 4.9-4.15 | B13: LYAP-X2527~胡煜星~flash | C13: LYAP-X2527 | D13: 117072634866 | E13: flashemotor | F13: 46095 | G13: 46085 | H13: 46086 | I13: 胡煜星 | J13: 其他 | K13: 原开品 | L13: 852 | M13: 18 | N13: 1 | O13: 7.41 | P13: 87.41 | R13: 11.796221 | S13: 0.055555556 | T13: 0.021126761 | U13: 0.41166667 | V13: 7.41 | W13: 0.084772909
A14: 4.9-4.15 | B14: LYAP-X2308~胡煜星 | C14: LYAP-X2308 | D14: 188126164114 | E14: gogreenbike | F14: 46099 | G14: 46085 | H14: 46091 | I14: 胡煜星 | J14: 其他 | K14: 原开品 | L14: 532 | M14: 15 | N14: 1 | O14: 7.63 | P14: 85 | R14: 11.140236 | S14: 0.066666667 | T14: 0.028195489 | U14: 0.50866667 | V14: 7.63 | W14: 0.089764706
... A26: 4.9-4.15 | B26: LYAP-X2216~章鹏~smart~xauto | C26: LYAP-X2216 | D26: 287173607865 | E26: x-autoparts1 | F26: 46087 | G26: 46081 | H26: 46101 | I26: 章鹏 | J26: 其他 | K26: 原开品 | L26: 480 | M26: 1 | N26: 1 | O26: 0.34 | P26: 62.08 | R26: 182.58824 | S26: 1 | T26: 0.0020833333 | U26: 0.34 | V26: 0.34 | W26: 0.0054768041
A27: 4.9-4.15 | B27: MD-001~俞东旭 | C27: MD-001-FL | D27: 188167194511 | E27: gogreenbike | F27: 46098 | G27: 46097 | H27: 46100 | I27: 俞东旭 | J27: 车门系统 | K27: 原开品 | L27: 0 | M27: 0 | N27: 1 | O27: 0 | P27: 627.41 | R27: #DIV/0! | S27: #DIV/0! | T27: #DIV/0! | U27: #DIV/0! | V27: 0 | W27: 0
A28: 4.9-4.15 | B28: LYAP-X1872~张潇~smart~flash | C28: LYAP-X1872 | D28: 117105229897 | E28: flashemotor | F28: 46120 | G28: 46104 | H28: 未出单 | I28: 张潇 | J28: 挡泥板 | K28: 原开品 | L28: 5539 | M28: 21 | N28: 0 | O28: 9.77 | P28: 0 | R28: 0 | S28: 0 | T28: 0.0037912981 | U28: 0.4652381 | V28: #DIV/0! | W28: #DIV/0!
A29: 4.9-4.15 | B29: LYAP-X1676~胡煜星~super | C29: LYAP-X1676 | D29: 336486052117 | E29: superiorparts11 | F29: 46098 | G29: 46097 | H29: 46103 | I29: 胡煜星 | J29: 车门系统 | K29: 原开品 | L29: 13146 | M29: 12 | N29: 0 | O29: 5.59 | P29: 0 | R29: 0 | S29: 0 | T29: 0.00091282519 | U29: 0.46583333 | V29: #DIV/0! | W29: #DIV/0!
A30: 4.9-4.15 | B30: LYAP-X1920系列~王偲涵 | C30: LYAP-X1920-BK | D30: 117042068584 | E30: flashemotor | F30: 46082 | G30: 46066 | H30: 46068 | I30: 朱培源 | J30: 饰条 | K30: 拓展品 | L30: 3700 | M30: 10 | N30: 0 | O30: 5.77 | P30: 0 | R30: 0 | S30: 0 | T30: 0.0027027027 | U30: 0.577 | V30: #DIV/0! | W30: #DIV/0!
A31: 4.9-4.15 | B31: LYAP-X1872~张潇 | C31: LYAP-X1872 | D31: 188197007336 | E31: gogreenbike | F31: 46104 | G31: 46104 | H31: 未出单 | I31: 张潇 | J31: 挡泥板 | K31: 原开品 | L31: 636 | M31: 9 | N31: 0 | O31: 7.79 | P31: 0 | R31: 0 | S31: 0 | T31: 0.014150943 | U31: 0.86555556 | V31: #DIV/0! | W31: #DIV/0!
A32: 4.9-4.15 | B32: MD-002-RR~俞东旭 | C32: MD-002-RR | D32: 117085067234 | E32: flashemotor | F32: 46123 | G32: 46092 | H32: 46096 | I32: 俞东旭 | J32: 车门系统 | K32: 原开品 | L32: 96 | M32: 8 | N32: 0 | O32: 6.2 | P32: 0 | R32: 0 | S32: 0 | T32: 0.083333333 | U32: 0.775 | V32: #DIV/0! | W32: #DIV/0!
A33: 4.9-4.15 | B33: MD-001~俞东旭 | C33: MD-001-RL | D33: 177967542795 | E33: gogreenbike | F33: 46098 | G33: 46097 | H33: 46103 | I33: 俞东旭 | J33: 车门系统 | K33: 原开品 | L33: 196 | M33: 7 | N33: 0 | O33: 6.29 | P33: 0 | R33: 0 | S33: 0 | T33: 0.035714286 | U33: 0.89857143 | V33: #DIV/0! | W33: #DIV/0!
A34: 4.9-4.15 | B34: LYAM-X2570-1~章鹏~smart~via | C34: LYAM-X2570-1 | D34: 227221720047 | E34: viautome | F34: 46115 | G34: 46070 | H34: 46073 | I34: 章鹏 | J34: 其他 | K34: 原开品 | L34: 1514 | M34: 6 | N34: 0 | O34: 2.39 | P34: 0 | R34: 0 | S34: 0 | T34: 0.0039630119 | U34: 0.39833333 | V34: #DIV/0! | W34: #DIV/0!
A35: 4.9-4.15 | B35: LYAP-X2190系列~张潇~smart~flash | C35: LYAP-X2190-R | D35: 117081148250 | E35: flashemotor | F35: 46099 | G35: 46091 | H35: 46106 | I35: 张潇 | J35: 饰条 | K35: 原开品 | L35: 1430 | M35: 6 | N35: 0 | O35: 2.22 | P35: 0 | R35: 0 | S35: 0 | T35: 0.0041958042 | U35: 0.37 | V35: #DIV/0! | W35: #DIV/0!
A36: 4.9-4.15 | B36: LYAP-X2190系列~张潇~smart~bike | C36: LYAP-X2190-L | D36: 188139762062 | E36: gogreenbike | F36: 46092 | G36: 46091 | H36: 46101 | I36: 张潇 | J36: 饰条 | K36: 原开品 | L36: 1361 | M36: 6 | N36: 0 | O36: 1.54 | P36: 0 | R36: 0 | S36: 0 | T36: 0.0044085231 | U36: 0.25666667 | V36: #DIV/0! | W36: #DIV/0!
A37: 4.9-4.15 | B37: LYAP-X2148-1~王偲涵smart | C37: LYAP-X2148-1L | D37: 117083102708 | E37: flashemotor | F37: 46121 | G37: 46092 | H37: 46096 | I37: 王偲涵 | J37: 饰条 | K37: 拓展品 | L37: 988 | M37: 4 | N37: 0 | O37: 1.47 | P37: 0 | R37: 0 | S37: 0 | T37: 0.004048583 | U37: 0.3675 | V37: #DIV/0! | W37: #DIV/0!
A38: 4.9-4.15 | B38: LYAP-X2148-1~王偲涵smart | C38: LYAP-X2148-1 | D38: 117070939739 | E38: flashemotor | F38: 46121 | G38: 46081 | H38: 46082 | I38: 王偲涵 | J38: 饰条 | K38: 原开品 | L38: 1648 | M38: 3 | N38: 0 | O38: 1.11 | P38: 0 | R38: 0 | S38: 0 | T38: 0.0018203883 | U38: 0.37 | V38: #DIV/0! | W38: #DIV/0!
A39: 4.9-4.15 | B39: LYAP-X1676~胡煜星~bike | C39: LYAP-X1676 | D39: 188167162085 | E39: gogreenbike | F39: 46098 | G39: 46097 | H39: 46103 | I39: 胡煜星 | J39: 车门系统 | K39: 原开品 | L39: 1082 | M39: 3 | N39: 0 | O39: 1.16 | P39: 0 | R39: 0 | S39: 0 | T39: 0.0027726433 | U39: 0.38666667 | V39: #DIV/0! | W39: #DIV/0!
A40: 4.9-4.15 | B40: LYAM-X2254-L~张潇~smart~xauto | C40: LYAM-X2254-L | D40: 287180832245 | E40: x-autoparts1 | F40: 46097 | G40: 46085 | H40: 46100 | I40: 张潇 | J40: 车门系统 | K40: 原开品 | L40: 449 | M40: 3 | N40: 0 | O40: 1.18 | P40: 0 | R40: 0 | S40: 0 | T40: 0.0066815145 | U40: 0.39333333 | V40: #DIV/0! | W40: #DIV/0!
A41: 4.9-4.15 | B41: LYAM-X2254-L~张潇~smart~bike | C41: LYAM-X2254-L | D41: 188126272697 | E41: gogreenbike | F41: 46097 | G41: 46085 | H41: 46100 | I41: 张潇 | J41: 车门系统 | K41: 原开品 | L41: 409 | M41: 2 | N41: 0 | O41: 0.72 | P41: 0 | R41: 0 | S41: 0 | T41: 0.0048899756 | U41: 0.36 | V41: #DIV/0! | W41: #DIV/0!
A42: 4.9-4.15 | B42: LYAP-X1920系列~王偲涵 | C42: LYAP-X1920-W | D42: 117042077894 | E42: flashemotor | F42: 46082 | G42: 46066 | H42: 46084 | I42: 朱培源 | J42: 饰条 | K42: 原开品 | L42: 383 | M42: 2 | N42: 0 | O42: 1.33 | P42: 0 | R42: 0 | S42: 0 | T42: 0.0052219321 | U42: 0.665 | V42: #DIV/0! | W42: #DIV/0!
A43: 4.9-4.15 | B43: LYAP-X2190系列~张潇~smart~flash | C43: LYAP-X2190-L | D43: 117081144249 | E43: flashemotor | F43: 46099 | G43: 46091 | H43: 46101 | I43: 张潇 | J43: 饰条 | K43: 原开品 | L43: 1332 | M43: 1 | N43: 0 | O43: 0.35 | P43: 0 | R43: 0 | S43: 0 | T43: 0.00075075075 | U43: 0.35 | V43: #DIV/0! | W43: #DIV/0!
... A50: 4.9-4.15 | B50: LYAM-X2569-1~章鹏~smart~flash | C50: LYAM-X2569-1 | D50: 117053094251 | E50: flashemotor | F50: 46087 | G50: 46070 | H50: 46086 | I50: 章鹏 | J50: 其他 | K50: 原开品 | L50: 216 | M50: 1 | N50: 0 | O50: 0.4 | P50: 0 | R50: 0 | S50: 0 | T50: 0.0046296296 | U50: 0.4 | V50: #DIV/0! | W50: #DIV/0!
A51: 4.9-4.15 | B51: LYAM-X2254-L~张潇~smart~via | C51: LYAM-X2254-L | D51: 227241168840 | E51: viautome | F51: 46097 | G51: 46085 | H51: 46100 | I51: 张潇 | J51: 车门系统 | K51: 原开品 | L51: 454 | M51: 0 | N51: 0 | O51: 0 | P51: 0 | R51: #DIV/0! | S51: #DIV/0! | T51: 0 | U51: #DIV/0! | V51: #DIV/0! | W51: #DIV/0!
A52: 4.9-4.15 | B52: LYAP-X2148-1系列~王偲涵1 | C52: LYAP-X2148-1L | D52: 177947728049 | E52: gogreenbike | F52: 46114 | G52: 46092 | H52: 46096 | I52: 王偲涵 | J52: 饰条 | K52: 拓展品 | L52: 51 | M52: 0 | N52: 0 | O52: 0 | P52: 0 | R52: #DIV/0! | S52: #DIV/0! | T52: 0 | U52: #DIV/0! | V52: #DIV/0! | W52: #DIV/0!
A53: 4.9-4.15 | B53: LYAP-X2085~俞东旭~smart | C53: LYAP-X2085 | D53: 117109082220 | E53: flashemotor | F53: 46120 | G53: 46105 | H53: 46125 | I53: 俞东旭 | J53: 车身外扩件 | K53: 原开品 | L53: 20 | M53: 0 | N53: 0 | O53: 0 | P53: 0 | R53: #DIV/0! | S53: #DIV/0! | T53: 0 | U53: #DIV/0! | V53: #DIV/0! | W53: #DIV/0!
A54: 4.9-4.15 | B54: LYAP-X2077~俞东旭~smart | C54: LYAP-X2077 | D54: 117109033287 | E54: flashemotor | F54: 46120 | G54: 46105 | H54: 46125 | I54: 俞东旭 | J54: 车身外扩件 | K54: 原开品 | L54: 18 | M54: 0 | N54: 0 | O54: 0 | P54: 0 | R54: #DIV/0! | S54: #DIV/0! | T54: 0 | U54: #DIV/0! | V54: #DIV/0! | W54: #DIV/0!
A55: 4.9-4.15 | B55: LYAP-X1800-1系列~胡煜星 | C55: LYAP-X1800-1 | D55: 227241156524 | E55: viautome | F55: 46087 | G55: 46085 | H55: 46089 | I55: 胡煜星 | J55: 车门系统 | K55: 原开品 | L55: 0 | M55: 0 | N55: 0 | O55: 0 | P55: 0 | R55: #DIV/0! | S55: #DIV/0! | T55: #DIV/0! | U55: #DIV/0! | V55: #DIV/0! | W55: #DIV/0!
A56: 4.9-4.15 | B56: LYAP-X1800-1系列~胡煜星 | C56: LYAP-X1800S-1L | D56: 227242599752 | E56: viautome | F56: 46087 | G56: 46086 | H56: 46089 | I56: 胡煜星 | J56: 车门系统 | K56: 原开品 | L56: 0 | M56: 0 | N56: 0 | O56: 0 | P56: 0 | R56: #DIV/0! | S56: #DIV/0! | T56: #DIV/0! | U56: #DIV/0! | V56: #DIV/0! | W56: #DIV/0!
A57: 4.9-4.15 | B57: LYAP-X1800-1系列~胡煜星 | C57: LYAP-X1800S-1R | D57: 227242600308 | E57: viautome | F57: 46087 | G57: 46086 | H57: 46094 | I57: 胡煜星 | J57: 车门系统 | K57: 原开品 | L57: 0 | M57: 0 | N57: 0 | O57: 0 | P57: 0 | R57: #DIV/0! | S57: #DIV/0! | T57: #DIV/0! | U57: #DIV/0! | V57: #DIV/0! | W57: #DIV/0!
...

Sheet 四三数据累计
A1: 销售编号 | B1: SKU | C1: 实际上架日期 | D1: 首次出单日期 | E1: 4月分析人 | F1: 品类 | G1: 产品拓展 | H1: 3.5-3.11销量 | I1: 3.12-3.18销量 | J1: 3.19-3.25销量 | K1: 3.26-4.1销量 | L1: 4.2-4.8销量 | M1: 4.9-4.15销量 | N1: 4.16-4.22销量 | O1: 4.23-4.29销量 | P1: 4.30-5.6销量 | Q1: 环比 | R1: 3.5-3.11销售额 | S1: 3.12-3.18销售额 | T1: 3.19-3.25销售额 | U1: 3.26-4.1销售额 | V1: 4.2-4.8销售额 | W1: 4.9-4.15销售额 | X1: 4.16-4.22销售额 | Y1: 4.23-4.29销售额 | Z1: 4.30-5.6销售额 | AA1: 环比 | AB1: 3.11对手销量 | AC1: 3.18对手销量 | AD1: 3.25对手销量 | AE1: 4.1对手销量 | AF1: 4.8对手销量 | AG1: 4.15对手销量 | AH1: 4.22对手销量 | AI1: 4.29对手销量 | AJ1: 5.6对手销量 | AK1: 3.11市占比 | AL1: 3.18市占比 | AM1: 3.25市占比 | AN1: 4.1市占比 | AO1: 4.8市占比 | AP1: 4.15市占比 | AQ1: 4.22市占比 | AR1: 4.29市占比 | AS1: 5.6市占比 | AT1: 3.11追踪间隔 | AU1: 3.18追踪间隔 | AV1: 3.25追踪间隔 | AW1: 4.1追踪间隔 | AX1: 4.8追踪间隔 | AY1: 4.15追踪间隔 | AZ1: 4.22追踪间隔 | BA1: 4.29追踪间隔 | BB1: 5.6追踪间隔 | BC1: 3.11 8日出单情况 | BD1: 3.18 8日出单情况 | BE1: 3.25 8日出单情况 | BF1: 4.1 8日出单情况 | BG1: 4.8 8日出单情况 | BH1: 4.15 8日出单情况 | BI1: 4.22 8日出单情况 | BJ1: 4.29 8日出单情况 | BK1: 5.6 8日出单情况 | BL1: 3.11 7日频次标签 | BM1: 3.18 7日频次标签 | BN1: 3.25 7日频次标签 | BO1: 4.1 7日频次标签 | BP1: 4.8 7日频次标签 | BQ1: 4.15 7日频次标签 | BR1: 4.22 7日频次标签 | BS1: 4.29 7日频次标签 | BT1: 5.6 7日频次标签 | BU1: 3.11 7日新品频次标签 | BV1: 3.18 7日新品频次标签 | BW1: 3.25 7日新品频次标签 | BX1: 4.1 7日新品频次标签 | BY1: 4.8 7日新品频次标签 | BZ1: 4.15 7日新品频次标签 | CA1: 4.22 7日新品频次标签 | CB1: 4.29 7日新品频次标签 | CC1: 5.6 7日新品频次标签 | CD1: 3.4市场状态 | CE1: 3.11市场状态 | CF1: 3.18市场状态 | CG1: 3.25市场状态 | CH1: 4.1市场状态 | CI1: 4.8市场状态 | CJ1: 4.15市场状态 | CK1: 4.22市场状态 | CL1: 4.29市场状态 | CM1: 5.6市场状态 | CN1: 3.5-3.11操作判断 | CO1: 3.12-3.18操作判断 | CP1: 3.19-3.25操作判断 | CQ1: 3.26-4.1操作判断 | CR1: 4.2-4.8操作判断 | CS1: 4.9-4.15操作判断 | CT1: 4.16-4.22操作判断 | CU1: 4.23-4.29操作判断 | CV1: 4.30-5.6操作判断 | CW1: 4.9-4.15开启PLP | CX1: 4.16-4.22开启PLP | CY1: 4.23-4.29开启PLP | CZ1: 4.30-5.6开启PLP | DA1: 4.16-4.22PLG最高费率 | DB1: 4.23-4.29PLG最高费率 | DC1: 4.30-5.6PLG最高费率
A2: 12073 | B2: LYAP-X1658 | C2: 46085 | D2: =IF(_xlfn.XLOOKUP(A2,[1]分配表!J:J,[1]分配表!M:M)=0,"未出单",_xlfn.XLOOKUP(A2,[1]分配表!J:J,[1]分配表!M:M)) -> 46093 | E2: =_xlfn.XLOOKUP(A2,[1]分配表!A:A,[1]分配表!C:C) -> 朱培源 | F2: 车门系统 | G2: 原开品 | H2: 0 | I2: 3 | J2: 3 | K2: 4 | L2: 0 | M2: 0 | N2: 1 | O2: 0 | P2: 1 | Q2: =IFERROR(P2-O2,P2) -> 1 | R2: 0 | S2: 1260 | T2: 1260 | U2: 1680 | V2: 0 | W2: 0 | X2: 420 | Y2: 0 | Z2: 420 | AA2: =IFERROR(Z2-Y2,Z2) -> 420 | AB2: 0 | AC2: 0 | AD2: 0 | AE2: 0 | AF2: 0 | AG2: 0 | AH2: 0 | AI2: 0 | AJ2: 0 | AK2: 市场无出单 | AL2: 1 | AM2: 1 | AN2: 1 | AO2: 0 | AP2: 0 | AQ2: 1 | AR2: 市场无出单 | AS2: 1 | AT2: 1 | AU2: 8 | AV2: 2 | AW2: 1 | AX2: 1 | AY2: 9 | AZ2: 9 | BA2: 16 | BB2: 23 | BC2: 未出单 | BD2: Y | BE2: Y | BF2: Y | BG2: Y | BH2: Y | BI2: Y | BJ2: Y | BK2: Y | BL2: 正常 | BM2: 异常 | BN2: 正常 | BO2: 正常 | BP2: 正常 | BQ2: 正常 | BR2: 正常 | BS2: 正常 | BT2: 正常 | BU2: 正常 | BV2: 正常 | BW2: 正常 | BX2: 正常 | BY2: 正常 | BZ2: 正常 | CA2: 正常 | CB2: 正常 | CC2: 正常 | CD2: 无市场 | CE2: 无市场 | CF2: 正常 | CG2: 正常 | CH2: 正常 | CI2: 正常 | CJ2: 无市场 | CK2: 正常 | CL2: 无市场 | CM2: 正常 | CN2: 广告-PLP | CO2: 无异常 | CP2: 未分析 | CQ2: 无异常 | CR2: 无异常 | CS2: 无异常 | CT2: 无异常 | CU2: 无异常 | CV2: 无异常 | CW2: N | CX2: N | CY2: N | CZ2: =IF(_xlfn.XLOOKUP(B2,[2]累计数据!$C$193:$C$245,[2]累计数据!$C$193:$C$245,"N")=B2,"Y","N") -> N | DA2: 0.045 | DB2: 0.02 | DC2: 0.02
A3: 12074 | B3: LYAP-X1658L | C3: 46085 | D3: =IF(_xlfn.XLOOKUP(A3,[1]分配表!J:J,[1]分配表!M:M)=0,"未出单",_xlfn.XLOOKUP(A3,[1]分配表!J:J,[1]分配表!M:M)) -> 46085 | E3: =_xlfn.XLOOKUP(A3,[1]分配表!A:A,[1]分配表!C:C) -> 朱培源 | F3: 车门系统 | G3: 拓展品 | H3: 8 | I3: 12 | J3: 5 | K3: 6 | L3: 3 | M3: 3 | N3: 9 | O3: 9 | P3: 8 | Q3: =IFERROR(P3-O3,P3) -> -1 | R3: 1760 | S3: 2640 | T3: 1080 | U3: 1320 | V3: 675 | W3: 679.1 | X3: 2147.72 | Y3: 2196.8 | Z3: 2010.88 | AA3: =IFERROR(Z3-Y3,Z3) -> -185.92 | AB3: 0 | AC3: 1 | AD3: 0 | AE3: 0 | AF3: 0 | AG3: 0 | AH3: 0 | AI3: 0 | AJ3: 0 | AK3: 1 | AL3: 0.9 | AM3: 1 | AN3: 1 | AO3: 1 | AP3: 1 | AQ3: 1 | AR3: 1 | AS3: 1 | AT3: 5 | AU3: 12 | AV3: 2 | AW3: 1 | AX3: 7 | AY3: 6 | AZ3: 12 | BA3: 19 | BB3: 26 | BC3: Y | BD3: Y | BE3: Y | BF3: Y | BG3: Y | BH3: Y | BI3: Y | BJ3: Y | BK3: Y | BL3: 正常 | BM3: 异常 | BN3: 正常 | BO3: 正常 | BP3: 正常 | BQ3: 正常 | BR3: 正常 | BS3: 正常 | BT3: 正常 | BU3: 异常 | BV3: 正常 | BW3: 正常 | BX3: 正常 | BY3: 正常 | BZ3: 正常 | CA3: 正常 | CB3: 正常 | CC3: 正常 | CD3: 无市场 | CE3: 正常 | CF3: 正常 | CG3: 正常 | CH3: 正常 | CI3: 正常 | CJ3: 正常 | CK3: 正常 | CL3: 正常 | CM3: 正常 | CN3: 无调整 | CO3: 无调整 | CP3: 未分析 | CQ3: 无异常 | CR3: 无异常 | CS3: 无异常 | CT3: 无异常 | CU3: 无异常 | CV3: 无异常 | CW3: N | CX3: N | CY3: N | CZ3: =IF(_xlfn.XLOOKUP(B3,[2]累计数据!$C$193:$C$245,[2]累计数据!$C$193:$C$245,"N")=B3,"Y","N") -> N | DA3: 0.05 | DB3: 0.02 | DC3: 0.02
A4: 12075 | B4: LYAP-X1658R | C4: 46085 | D4: =IF(_xlfn.XLOOKUP(A4,[1]分配表!J:J,[1]分配表!M:M)=0,"未出单",_xlfn.XLOOKUP(A4,[1]分配表!J:J,[1]分配表!M:M)) -> 46085 | E4: =_xlfn.XLOOKUP(A4,[1]分配表!A:A,[1]分配表!C:C) -> 朱培源 | F4: 车门系统 | G4: 拓展品 | H4: 1 | I4: 2 | J4: 0 | K4: 0 | L4: 0 | M4: 1 | N4: 0 | O4: 0 | P4: 1 | Q4: =IFERROR(P4-O4,P4) -> 1 | R4: 220 | S4: 440 | T4: 0 | U4: 0 | V4: 0 | W4: 220 | X4: 0 | Y4: 0 | Z4: 220 | AA4: =IFERROR(Z4-Y4,Z4) -> 220 | AB4: 0 | AC4: 0 | AD4: 0 | AE4: 0 | AF4: 0 | AG4: 0 | AH4: 0 | AI4: 0 | AJ4: 0 | AK4: 1 | AL4: 1 | AM4: 市场无出单 | AN4: 0 | AO4: 0 | AP4: 1 | AQ4: 市场无出单 | AR4: 市场无出单 | AS4: 1 | AT4: 5 | AU4: 12 | AV4: 2 | AW4: 1 | AX4: 1 | AY4: 9 | AZ4: 15 | BA4: 22 | BB4: 29 | BC4: Y | BD4: Y | BE4: Y | BF4: Y | BG4: Y | BH4: Y | BI4: Y | BJ4: Y | BK4: Y | BL4: 正常 | BM4: 异常 | BN4: 正常 | BO4: 正常 | BP4: 正常 | BQ4: 正常 | BR4: 正常 | BS4: 正常 | BT4: 正常 | BU4: 异常 | BV4: 正常 | BW4: 正常 | BX4: 正常 | BY4: 正常 | BZ4: 正常 | CA4: 正常 | CB4: 正常 | CC4: 正常 | CD4: 无市场 | CE4: 正常 | CF4: 正常 | CG4: 正常 | CH4: 无市场 | CI4: 无市场 | CJ4: 正常 | CK4: 无市场 | CL4: 无市场 | CM4: 正常 | CN4: 无调整 | CO4: 无调整 | CP4: 未分析 | CQ4: 无异常 | CR4: 无异常 | CS4: 无异常 | CT4: 无异常 | CU4: 无异常 | CV4: 无异常 | CW4: N | CX4: N | CY4: N | CZ4: =IF(_xlfn.XLOOKUP(B4,[2]累计数据!$C$193:$C$245,[2]累计数据!$C$193:$C$245,"N")=B4,"Y","N") -> N | DA4: 0.045 | DB4: 0.02 | DC4: 0.02
A5: 12252 | B5: LYAP-X1800-1 | C5: 46085 | D5: =IF(_xlfn.XLOOKUP(A5,[1]分配表!J:J,[1]分配表!M:M)=0,"未出单",_xlfn.XLOOKUP(A5,[1]分配表!J:J,[1]分配表!M:M)) -> 46089 | E5: =_xlfn.XLOOKUP(A5,[1]分配表!A:A,[1]分配表!C:C) -> 胡煜星 | F5: 车门系统 | G5: 原开品 | H5: 3 | I5: 4 | J5: 2 | K5: 1 | L5: 0 | M5: 0 | N5: 1 | O5: 0 | P5: 1 | Q5: =IFERROR(P5-O5,P5) -> 1 | R5: 122 | S5: 160 | T5: 80 | U5: 40 | V5: 0 | W5: 0 | X5: 40 | Y5: 0 | Z5: 40 | AA5: =IFERROR(Z5-Y5,Z5) -> 40 | AB5: 11 | AC5: 1 | AD5: 4 | AE5: 10 | AF5: 1 | AG5: 12 | AH5: 12 | AI5: 9 | AJ5: 7 | AK5: 0.21428571 | AL5: 0.8571 | AM5: 0.33333333 | AN5: 0.090909091 | AO5: 0 | AP5: 0 | AQ5: 0.0769 | AR5: 0 | AS5: 0.125 | AT5: 1 | AU5: 1 | AV5: 0 | AW5: 8 | AX5: 0 | AY5: 5 | AZ5: 6 | BA5: 13 | BB5: 0 | BC5: Y | BD5: Y | BE5: Y | BF5: Y | BG5: Y | BH5: Y | BI5: Y | BJ5: Y | BK5: Y | BL5: 正常 | BM5: 正常 | BN5: 正常 | BO5: 异常 | BP5: 正常 | BQ5: 正常 | BR5: 正常 | BS5: 异常 | BT5: 正常 | BU5: 正常 | BV5: 正常 | BW5: 正常 | BX5: 正常 | BY5: 正常 | BZ5: 正常 | CA5: 正常 | CB5: 正常 | CC5: 正常 | CD5: 无市场 | CE5: 竞争无优势 | CF5: 正常 | CG5: 竞争无优势 | CH5: 竞争无优势 | CI5: 竞争无优势 | CJ5: 竞争无优势 | CK5: 竞争无优势 | CL5: 竞争无优势 | CM5: 竞争无优势 | CN5: 广告-PLP | CO5: 无异常 | CP5: 无异常 | CQ5: 广告-PLG | CR5: 无异常 | CS5: 无异常 | CT5: 无异常 | CU5: 无异常 | CV5: 链接优化 | CW5: Y | CX5: Y | CY5: Y | CZ5: =IF(_xlfn.XLOOKUP(B5,[2]累计数据!$C$193:$C$245,[2]累计数据!$C$193:$C$245,"N")=B5,"Y","N") -> N | DA5: 0.08 | DB5: 0.07 | DC5: 0.05
A6: 12165 | B6: LYAP-X1877 | C6: 46085 | D6: =IF(_xlfn.XLOOKUP(A6,[1]分配表!J:J,[1]分配表!M:M)=0,"未出单",_xlfn.XLOOKUP(A6,[1]分配表!J:J,[1]分配表!M:M)) -> 46093 | E6: =_xlfn.XLOOKUP(A6,[1]分配表!A:A,[1]分配表!C:C) -> 朱培源 | F6: 挡泥板 | G6: 原开品 | H6: 0 | I6: 2 | J6: 0 | K6: 0 | L6: 0 | M6: 1 | N6: 2 | O6: 0 | P6: 1 | Q6: =IFERROR(P6-O6,P6) -> 1 | R6: 0 | S6: 338 | T6: 0 | U6: 0 | V6: 0 | W6: 169 | X6: 338 | Y6: 0 | Z6: 169 | AA6: =IFERROR(Z6-Y6,Z6) -> 169 | AB6: 0 | AC6: 0 | AD6: 1 | AE6: 0 | AF6: 3 | AG6: 6 | AH6: 3 | AI6: 3 | AJ6: 1 | AK6: 市场无出单 | AL6: 1 | AM6: 0 | AN6: 0 | AO6: 0 | AP6: 0.14285714 | AQ6: 0.4 | AR6: 0 | AS6: 0 | AT6: 5 | AU6: 1 | AV6: 2 | AW6: 1 | AX6: 7 | AY6: 6 | AZ6: 5 | BA6: 12 | BB6: 19 | BC6: 未出单 | BD6: Y | BE6: Y | BF6: Y | BG6: Y | BH6: Y | BI6: Y | BJ6: Y | BK6: Y | BL6: 正常 | BM6: 正常 | BN6: 正常 | BO6: 正常 | BP6: 异常 | BQ6: 正常 | BR6: 正常 | BS6: 异常 | BT6: 异常 | BU6: 异常 | BV6: 正常 | BW6: 正常 | BX6: 正常 | BY6: 正常 | BZ6: 正常 | CA6: 正常 | CB6: 正常 | CC6: 正常 | CD6: 无市场 | CE6: 无市场 | CF6: 正常 | CG6: 竞争无优势 | CH6: 站外出单 | CI6: 竞争无优势 | CJ6: 竞争无优势 | CK6: 竞争无优势 | CL6: 竞争无优势 | CM6: 竞争无优势 | CN6: 无调整 | CO6: 广告-PLG | CP6: 无异常 | CQ6: 无异常 | CR6: 广告-PLG | CS6: 广告-PLG | CT6: 无异常 | CU6: 无异常 | CV6: 广告-PLG | CW6: N | CX6: N | CY6: N | CZ6: =IF(_xlfn.XLOOKUP(B6,[2]累计数据!$C$193:$C$245,[2]累计数据!$C$193:$C$245,"N")=B6,"Y","N") -> N | DA6: 0.05 | DB6: 0.05 | DC6: 0.02
A7: 12247 | B7: LYAP-X2528 | C7: 46085 | D7: =IF(_xlfn.XLOOKUP(A7,[1]分配表!J:J,[1]分配表!M:M)=0,"未出单",_xlfn.XLOOKUP(A7,[1]分配表!J:J,[1]分配表!M:M)) -> 46089 | E7: =_xlfn.XLOOKUP(A7,[1]分配表!A:A,[1]分配表!C:C) -> 胡煜星 | F7: 其他 | G7: 原开品 | H7: 5 | I7: 8 | J7: 3 | K7: 6 | L7: 6 | M7: 2 | N7: 7 | O7: 1 | P7: 5 | Q7: =IFERROR(P7-O7,P7) -> 4 | R7: 475 | S7: 632 | T7: 237 | U7: 481 | V7: 534 | W7: 178 | X7: 647.28 | Y7: 111.25 | Z7: 490 | AA7: =IFERROR(Z7-Y7,Z7) -> 378.75 | AB7: 0 | AC7: 0 | AD7: 0 | AE7: 0 | AF7: 0 | AG7: 0 | AH7: 0 | AI7: 0 | AJ7: 0 | AK7: 1 | AL7: 1 | AM7: 1 | AN7: 1 | AO7: 1 | AP7: 1 | AQ7: 1 | AR7: 1 | AS7: 1 | AT7: 1 | AU7: 1 | AV7: 1 | AW7: 3 | AX7: 9 | AY7: 6 | AZ7: 12 | BA7: 4 | BB7: 11 | BC7: Y | BD7: Y | BE7: Y | BF7: Y | BG7: Y | BH7: Y | BI7: Y | BJ7: Y | BK7: Y | BL7: 正常 | BM7: 正常 | BN7: 正常 | BO7: 正常 | BP7: 正常 | BQ7: 正常 | BR7: 正常 | BS7: 正常 | BT7: 正常 | BU7: 正常 | BV7: 正常 | BW7: 正常 | BX7: 正常 | BY7: 正常 | BZ7: 正常 | CA7: 正常 | CB7: 正常 | CC7: 正常 | CD7: 无市场 | CE7: 正常 | CF7: 正常 | CG7: 正常 | CH7: 正常 | CI7: 正常 | CJ7: 正常 | CK7: 正常 | CL7: 正常 | CM7: 正常 | CN7: 广告-PLP | CO7: 无异常 | CP7: 无异常 | CQ7: 无异常 | CR7: 无异常 | CS7: 无异常 | CT7: 无异常 | CU7: 无异常 | CV7: 无异常 | CW7: Y | CX7: Y | CY7: Y | CZ7: =IF(_xlfn.XLOOKUP(B7,[2]累计数据!$C$193:$C$245,[2]累计数据!$C$193:$C$245,"N")=B7,"Y","N") -> N | DA7: 0.04 | DB7: 0.03 | DC7: 0
A8: 11102 | B8: LYAM-X2254-L | C8: 46085 | D8: =IF(_xlfn.XLOOKUP(A8,[1]分配表!J:J,[1]分配表!M:M)=0,"未出单",_xlfn.XLOOKUP(A8,[1]分配表!J:J,[1]分配表!M:M)) -> 46100 | E8: =_xlfn.XLOOKUP(A8,[1]分配表!A:A,[1]分配表!C:C) -> 张潇 | F8: 车门系统 | G8: 原开品 | H8: 0 | I8: 0 | J8: 2 | K8: 1 | L8: 3 | M8: 0 | N8: 3 | O8: 4 | P8: 5 | Q8: =IFERROR(P8-O8,P8) -> 1 | R8: 0 | S8: 0 | T8: 64 | U8: 32 | V8: 96 | W8: 0 | X8: 92.19 | Y8: 112.76 | Z8: 140.95 | AA8: =IFERROR(Z8-Y8,Z8) -> 28.19 | AB8: 2 | AC8: 5 | AD8: 3 | AE8: 2 | AF8: 0 | AG8: 6 | AH8: 5 | AI8: 2 | AJ8: 5 | AK8: 0 | AL8: 0 | AM8: 0.4 | AN8: 0.33333333 | AO8: 1 | AP8: 0 | AQ8: 0.2857 | AR8: 0.5 | AS8: 0.5833 | AT8: 7 | AU8: 2 | AV8: 2 | AW8: 3 | AX8: 9 | AY8: 3 | AZ8: 5 | BA8: 6 | BB8: 13 | BC8: 未出单 | BD8: 未出单 | BE8: N | BF8: N | BG8: N | BH8: N | BI8: N | BJ8: N | BK8: N | BL8: 正常 | BM8: 正常 | BN8: 正常 | BO8: 正常 | BP8: 正常 | BQ8: 正常 | BR8: 正常 | BS8: 正常 | BT8: 异常 | BU8: 异常 | BV8: 正常 | BW8: 正常 | BX8: 正常 | BY8: 正常 | BZ8: 正常 | CA8: 正常 | CB8: 正常 | CC8: 正常 | CD8: 无市场 | CE8: 站内无价格优势 | CF8: 站内无价格优势 | CG8: 竞争无优势 | CH8: 竞争无优势 | CI8: 正常 | CJ8: 竞争无优势 | CK8: 竞争无优势 | CL8: 竞争无优势 | CM8: 竞争无优势 | CN8: 链接优化 | CO8: 广告-PLP | CP8: 广告-PLG | CQ8: 无异常 | CR8: 无异常 | CS8: 无异常 | CT8: 无异常 | CU8: 无异常 | CV8: 无异常 | CW8: Y | CX8: Y | CY8: Y | CZ8: =IF(_xlfn.XLOOKUP(B8,[2]累计数据!$C$193:$C$245,[2]累计数据!$C$193:$C$245,"N")=B8,"Y","N") -> Y | DA8: 0.03 | DB8: 0.03 | DC8: 0
A9: 12071 | B9: LYAM-X2980-BK | C9: 46085 | D9: =IF(_xlfn.XLOOKUP(A9,[1]分配表!J:J,[1]分配表!M:M)=0,"未出单",_xlfn.XLOOKUP(A9,[1]分配表!J:J,[1]分配表!M:M)) -> 46092 | E9: =_xlfn.XLOOKUP(A9,[1]分配表!A:A,[1]分配表!C:C) -> 胡煜星 | F9: 车身外扩件 | G9: 拓展品 | H9: 1 | I9: 0 | J9: 0 | K9: 1 | L9: 0 | M9: 3 | N9: 1 | O9: 0 | P9: 0 | Q9: =IFERROR(P9-O9,P9) -> 0 | R9: 299 | S9: 0 | T9: 0 | U9: 299 | V9: 0 | W9: 897 | X9: 299 | Y9: 0 | Z9: 0 | AA9: =IFERROR(Z9-Y9,Z9) -> 0 | AB9: 1 | AC9: 0 | AD9: 0 | AE9: 0 | AF9: 0 | AG9: 0 | AH9: 0 | AI9: 1 | AJ9: 0 | AK9: 0.5 | AL9: 1 | AM9: 市场无出单 | AN9: 1 | AO9: 0 | AP9: 1 | AQ9: 市场无出单 | AR9: 0.5 | AS9: 市场无出单 | AT9: 1 | AU9: 8 | AV9: 1 | AW9: 9 | AX9: 0 | AY9: 8 | AZ9: 14 | BA9: 21 | BB9: 0 | BC9: Y | BD9: Y | BE9: Y | BF9: Y | BG9: Y | BH9: Y | BI9: Y | BJ9: Y | BK9: Y | BL9: 正常 | BM9: 异常 | BN9: 正常 | BO9: 异常 | BP9: 正常 | BQ9: 正常 | BR9: 正常 | BS9: 异常 | BT9: 正常 | BU9: 正常 | BV9: 正常 | BW9: 正常 | BX9: 正常 | BY9: 正常 | BZ9: 正常 | CA9: 正常 | CB9: 正常 | CC9: 正常 | CD9: 无市场 | CE9: 竞争无优势 | CF9: 正常 | CG9: 无市场 | CH9: 正常 | CI9: 无市场 | CJ9: 正常 | CK9: 无市场 | CL9: 竞争无优势 | CM9: 无市场 | CN9: 8日新品优化 | CO9: 无异常 | CP9: 无调整 | CQ9: 无调整 | CR9: 无异常 | CS9: 无异常 | CT9: 无异常 | CU9: 无异常 | CV9: 广告-PLG | CW9: N | CX9: N | CY9: N | CZ9: =IF(_xlfn.XLOOKUP(B9,[2]累计数据!$C$193:$C$245,[2]累计数据!$C$193:$C$245,"N")=B9,"Y","N") -> N | DA9: 0 | DB9: 0 | DC9: 0
A10: 12072 | B10: LYAM-X2980-GR | C10: 46085 | D10: =IF(_xlfn.XLOOKUP(A10,[1]分配表!J:J,[1]分配表!M:M)=0,"未出单",_xlfn.XLOOKUP(A10,[1]分配表!J:J,[1]分配表!M:M)) -> 46112 | E10: =_xlfn.XLOOKUP(A10,[1]分配表!A:A,[1]分配表!C:C) -> 胡煜星 | F10: 车身外扩件 | G10: 原开品 | H10: 0 | I10: 0 | J10: 0 | K10: 1 | L10: 0 | M10: 1 | N10: 1 | O10: 1 | P10: 0 | Q10: =IFERROR(P10-O10,P10) -> -1 | R10: 0 | S10: 0 | T10: 0 | U10: 299 | V10: 0 | W10: 299 | X10: 299 | Y10: 299 | Z10: 0 | AA10: =IFERROR(Z10-Y10,Z10) -> -299 | AB10: 0 | AC10: 0 | AD10: 0 | AE10: 0 | AF10: 0 | AG10: 0 | AH10: 0 | AI10: 0 | AJ10: 0 | AK10: 市场无出单 | AL10: 市场无出单 | AM10: 市场无出单 | AN10: 1 | AO10: 0 | AP10: 1 | AQ10: 1 | AR10: 1 | AS10: 市场无出单 | AT10: 1 | AU10: 8 | AV10: 不分析 | AW10: 9 | AX10: 0 | AY10: 8 | AZ10: 14 | BA10: 21 | BB10: 28 | BC10: 未出单 | BD10: 未出单 | BE10: 未出单 | BF10: N | BG10: N | BH10: N | BI10: N | BJ10: N | BK10: N | BL10: 正常 | BM10: 异常 | BN10: 不分析 | BO10: 异常 | BP10: 正常 | BQ10: 正常 | BR10: 正常 | BS10: 正常 | BT10: 正常 | BU10: 正常 | BV10: 正常 | BW10: 不分析 | BX10: 正常 | BY10: 正常 | BZ10: 正常 | CA10: 正常 | CB10: 正常 | CC10: 正常 | CD10: 无市场 | CE10: 无市场 | CF10: 无市场 | CG10: 无市场 | CH10: 无市场 | CI10: 无市场 | CJ10: 无市场 | CK10: 正常 | CL10: 正常 | CM10: 无市场 | CN10: 8日新品优化 | CO10: 无异常 | CP10: 无调整 | CQ10: 无调整 | CR10: 无异常 | CS10: 无异常 | CT10: 无异常 | CU10: 无异常 | CV10: 无异常 | CW10: N | CX10: N | CY10: N | CZ10: =IF(_xlfn.XLOOKUP(B10,[2]累计数据!$C$193:$C$245,[2]累计数据!$C$193:$C$245,"N")=B10,"Y","N") -> N | DA10: 0.02 | DB10: 0 | DC10: 0
A11: 12248 | B11: LYAP-X2308 | C11: 46085 | D11: =IF(_xlfn.XLOOKUP(A11,[1]分配表!J:J,[1]分配表!M:M)=0,"未出单",_xlfn.XLOOKUP(A11,[1]分配表!J:J,[1]分配表!M:M)) -> 46091 | E11: =_xlfn.XLOOKUP(A11,[1]分配表!A:A,[1]分配表!C:C) -> 胡煜星 | F11: 其他 | G11: 原开品 | H11: 3 | I11: 1 | J11: 3 | K11: 3 | L11: 5 | M11: 5 | N11: 5 | O11: 3 | P11: 3 | Q11: =IFERROR(P11-O11,P11) -> 0 | R11: 255 | S11: 85 | T11: 255 | U11: 255 | V11: 425 | W11: 425 | X11: 429 | Y11: 258 | Z11: 257 | AA11: =IFERROR(Z11-Y11,Z11) -> -1 | AB11: 1 | AC11: 1 | AD11: 0 | AE11: 4 | AF11: 1 | AG11: 3 | AH11: 1 | AI11: 4 | AJ11: 1 | AK11: 0.75 | AL11: 0.8 | AM11: 1 | AN11: 0.42857143 | AO11: 0.83333333 | AP11: 0.625 | AQ11: 0.8333 | AR11: 0.5 | AS11: 0.75 | AT11: 1 | AU11: 7 | AV11: 7 | AW11: 15 | AX11: 0 | AY11: 8 | AZ11: 5 | BA11: 12 | BB11: 0 | BC11: Y | BD11: Y | BE11: Y | BF11: Y | BG11: Y | BH11: Y | BI11: Y | BJ11: Y | BK11: Y | BL11: 正常 | BM11: 正常 | BN11: 正常 | BO11: 异常 | BP11: 正常 | BQ11: 异常 | BR11: 正常 | BS11: 异常 | BT11: 正常 | BU11: 正常 | BV11: 正常 | BW11: 正常 | BX11: 正常 | BY11: 正常 | BZ11: 正常 | CA11: 正常 | CB11: 正常 | CC11: 正常 | CD11: 无市场 | CE11: 竞争无优势 | CF11: 正常 | CG11: 正常 | CH11: 竞争无优势 | CI11: 正常 | CJ11: 竞争无优势 | CK11: 正常 | CL11: 竞争无优势 | CM11: 正常 | CN11: 广告-PLP | CO11: 无异常 | CP11: 无异常 | CQ11: 广告-PLP | CR11: 无异常 | CS11: 无异常 | CT11: 广告-PLG | CU11: 无异常 | CV11: 链接优化 | CW11: Y | CX11: Y | CY11: Y | CZ11: =IF(_xlfn.XLOOKUP(B11,[2]累计数据!$C$193:$C$245,[2]累计数据!$C$193:$C$245,"N")=B11,"Y","N") -> N | DA11: 0.04 | DB11: 0.04 | DC11: 0.02
A12: 12246 | B12: LYAP-X2527 | C12: 46085 | D12: =IF(_xlfn.XLOOKUP(A12,[1]分配表!J:J,[1]分配表!M:M)=0,"未出单",_xlfn.XLOOKUP(A12,[1]分配表!J:J,[1]分配表!M:M)) -> 46086 | E12: =_xlfn.XLOOKUP(A12,[1]分配表!A:A,[1]分配表!C:C) -> 胡煜星 | F12: 其他 | G12: 原开品 | H12: 11 | I12: 8 | J12: 8 | K12: 9 | L12: 15 | M12: 8 | N12: 12 | O12: 10 | P12: 9 | Q12: =IFERROR(P12-O12,P12) -> -1 | R12: 1185 | S12: 686 | T12: 690 | U12: 772 | V12: 1296 | W12: 685.75 | X12: 1033 | Y12: 879 | Z12: 833.5 | AA12: =IFERROR(Z12-Y12,Z12) -> -45.5 | AB12: 2 | AC12: 0 | AD12: 0 | AE12: 0 | AF12: 0 | AG12: 0 | AH12: 0 | AI12: 0 | AJ12: 0 | AK12: 0.84615385 | AL12: 1 | AM12: 1 | AN12: 1 | AO12: 1 | AP12: 1 | AQ12: 1 | AR12: 1 | AS12: 1 | AT12: 1 | AU12: 4 | AV12: 11 | AW12: 1 | AX12: 7 | AY12: 5 | AZ12: 11 | BA12: 4 | BB12: 1 | BC12: Y | BD12: Y | BE12: Y | BF12: Y | BG12: Y | BH12: Y | BI12: Y | BJ12: Y | BK12: Y | BL12: 正常 | BM12: 正常 | BN12: 异常 | BO12: 正常 | BP12: 正常 | BQ12: 正常 | BR12: 正常 | BS12: 正常 | BT12: 正常 | BU12: 正常 | BV12: 正常 | BW12: 正常 | BX12: 正常 | BY12: 正常 | BZ12: 正常 | CA12: 正常 | CB12: 正常 | CC12: 正常 | CD12: 无市场 | CE12: 正常 | CF12: 正常 | CG12: 正常 | CH12: 正常 | CI12: 正常 | CJ12: 正常 | CK12: 正常 | CL12: 正常 | CM12: 正常 | CN12: 广告-PLP | CO12: 无异常 | CP12: 无异常 | CQ12: 无异常 | CR12: 无异常 | CS12: 无异常 | CT12: 无异常 | CU12: 无异常 | CV12: 无异常 | CW12: Y | CX12: Y | CY12: Y | CZ12: =IF(_xlfn.XLOOKUP(B12,[2]累计数据!$C$193:$C$245,[2]累计数据!$C$193:$C$245,"N")=B12,"Y","N") -> Y | DA12: 0.02 | DB12: 0 | DC12: 0
A13: 12205 | B13: LYAP-X1800S-1L | C13: 46086 | D13: =IF(_xlfn.XLOOKUP(A13,[1]分配表!J:J,[1]分配表!M:M)=0,"未出单",_xlfn.XLOOKUP(A13,[1]分配表!J:J,[1]分配表!M:M)) -> 46089 | E13: =_xlfn.XLOOKUP(A13,[1]分配表!A:A,[1]分配表!C:C) -> 胡煜星 | F13: 车门系统 | G13: 原开品 | H13: 2 | I13: 9 | J13: 0 | K13: 7 | L13: 6 | M13: 1 | N13: 8 | O13: 15 | P13: 10 | Q13: =IFERROR(P13-O13,P13) -> -5 | R13: 44 | S13: 196 | T13: 0 | U13: 152 | V13: 132 | W13: 22 | X13: 176 | Y13: 330 | Z13: 220 | AA13: =IFERROR(Z13-Y13,Z13) -> -110 | AB13: 29 | AC13: 34 | AD13: 32 | AE13: 34 | AF13: 23 | AG13: 30 | AH13: 23 | AI13: 21 | AJ13: 20 | AK13: 0.064516129 | AL13: 0.2093 | AM13: 0 | AN13: 0.17073171 | AO13: 0.20689655 | AP13: 0.032258065 | AQ13: 0.2333 | AR13: 0.3824 | AS13: 0.3548 | AT13: 1 | AU13: 1 | AV13: 0 | AW13: 5 | AX13: 1 | AY13: 5 | AZ13: 1 | BA13: 8 | BB13: 0 | BC13: Y | BD13: Y | BE13: Y | BF13: Y | BG13: Y | BH13: Y | BI13: Y | BJ13: Y | BK13: Y | BL13: 正常 | BM13: 正常 | BN13: 正常 | BO13: 正常 | BP13: 正常 | BQ13: 正常 | BR13: 正常 | BS13: 异常 | BT13: 正常 | BU13: 正常 | BV13: 正常 | BW13: 正常 | BX13: 正常 | BY13: 正常 | BZ13: 正常 | CA13: 正常 | CB13: 正常 | CC13: 正常 | CD13: 未上架 | CE13: 竞争无优势 | CF13: 竞争无优势 | CG13: 竞争无优势 | CH13: 竞争无优势 | CI13: 竞争无优势 | CJ13: 竞争无优势 | CK13: 竞争无优势 | CL13: 竞争无优势 | CM13: 竞争无优势 | CN13: 未上架 | CO13: 无异常 | CP13: 无异常 | CQ13: 无异常 | CR13: 无异常 | CS13: 无异常 | CT13: 无异常 | CU13: 无异常 | CV13: 链接优化 | CW13: Y | CX13: Y | CY13: Y | CZ13: =IF(_xlfn.XLOOKUP(B13,[2]累计数据!$C$193:$C$245,[2]累计数据!$C$193:$C$245,"N")=B13,"Y","N") -> N | DA13: 0.07 | DB13: 0.07 | DC13: 0.05
A14: 12206 | B14: LYAP-X1800S-1R | C14: 46086 | D14: =IF(_xlfn.XLOOKUP(A14,[1]分配表!J:J,[1]分配表!M:M)=0,"未出单",_xlfn.XLOOKUP(A14,[1]分配表!J:J,[1]分配表!M:M)) -> 46094 | E14: =_xlfn.XLOOKUP(A14,[1]分配表!A:A,[1]分配表!C:C) -> 胡煜星 | F14: 车门系统 | G14: 原开品 | H14: 0 | I14: 2 | J14: 0 | K14: 0 | L14: 1 | M14: 1 | N14: 0 | O14: 2 | P14: 2 | Q14: =IFERROR(P14-O14,P14) -> 0 | R14: 0 | S14: 44 | T14: 0 | U14: 0 | V14: 22 | W14: 22 | X14: 0 | Y14: 44 | Z14: 44 | AA14: =IFERROR(Z14-Y14,Z14) -> 0 | AB14: 7 | AC14: 6 | AD14: 8 | AE14: 11 | AF14: 3 | AG14: 5 | AH14: 10 | AI14: 9 | AJ14: 6 | AK14: 0 | AL14: 0.25 | AM14: 0 | AN14: 0 | AO14: 0.25 | AP14: 0.16666667 | AQ14: 0 | AR14: 0.1818 | AS14: 0.25 | AT14: 1 | AU14: 1 | AV14: 0 | AW14: 8 | AX14: 0 | AY14: 6 | AZ14: 1 | BA14: 8 | BB14: 0 | BC14: 未出单 | BD14: Y | BE14: Y | BF14: Y | BG14: Y | BH14: Y | BI14: Y | BJ14: Y | BK14: Y | BL14: 正常 | BM14: 正常 | BN14: 正常 | BO14: 异常 | BP14: 正常 | BQ14: 正常 | BR14: 正常 | BS14: 异常 | BT14: 正常 | BU14: 正常 | BV14: 正常 | BW14: 正常 | BX14: 正常 | BY14: 正常 | BZ14: 正常 | CA14: 正常 | CB14: 正常 | CC14: 正常 | CD14: 未上架 | CE14: 竞争无优势 | CF14: 竞争无优势 | CG14: 竞争无优势 | CH14: 竞争无优势 | CI14: 竞争无优势 | CJ14: 竞争无优势 | CK14: 竞争无优势 | CL14: 竞争无优势 | CM14: 竞争无优势 | CN14: 未上架 | CO14: 无异常 | CP14: 无异常 | CQ14: 广告-PLG | CR14: 无异常 | CS14: 无异常 | CT14: 无异常 | CU14: 无异常 | CV14: 链接优化 | CW14: Y | CX14: Y | CY14: Y | CZ14: =IF(_xlfn.XLOOKUP(B14,[2]累计数据!$C$193:$C$245,[2]累计数据!$C$193:$C$245,"N")=B14,"Y","N") -> N | DA14: 0.07 | DB14: 0.05 | DC14: 0.04
A15: 11997 | B15: LYAM-X2896 | C15: 46091 | D15: =IF(_xlfn.XLOOKUP(A15,[1]分配表!J:J,[1]分配表!M:M)=0,"未出单",_xlfn.XLOOKUP(A15,[1]分配表!J:J,[1]分配表!M:M)) -> 46105 | E15: =_xlfn.XLOOKUP(A15,[1]分配表!A:A,[1]分配表!C:C) -> 张潇 | F15: 饰条 | G15: 原开品 | H15: 0 | I15: 0 | J15: 1 | K15: 0 | L15: 2 | M15: 2 | N15: 3 | O15: 0 | P15: 1 | Q15: =IFERROR(P15-O15,P15) -> 1 | R15: 0 | S15: 0 | T15: 139 | U15: 0 | V15: 278 | W15: 278 | X15: 410.05 | Y15: 0 | Z15: 139 | AA15: =IFERROR(Z15-Y15,Z15) -> 139 | AB15: 0 | AC15: 1 | AD15: 0 | AE15: 2 | AF15: 0 | AG15: 1 | AH15: 0 | AI15: 0 | AJ15: 0 | AK15: 市场无出单 | AL15: 0 | AM15: 1 | AN15: 0 | AO15: 1 | AP15: 0.66666667 | AQ15: 1 | AR15: 1 | AS15: 1 | AT15: 未分析 | AU15: 7 | AV15: 7 | AW15: 15 | AX15: 1 | AY15: 9 | AZ15: 2 | BA15: 9 | BB15: 16 | BC15: 未出单 | BD15: 未出单 | BE15: N | BF15: N | BG15: N | BH15: N | BI15: N | BJ15: N | BK15: N | BL15: 异常 | BM15: 正常 | BN15: 正常 | BO15: 异常 | BP15: 正常 | BQ15: 异常 | BR15: 正常 | BS15: 正常 | BT15: 正常 | BU15: 异常 | BV15: 正常 | BW15: 正常 | BX15: 正常 | BY15: 正常 | BZ15: 正常 | CA15: 正常 | CB15: 正常 | CC15: 正常 | CD15: 未上架 | CE15: 无市场 | CF15: 竞争无优势 | CG15: 无市场 | CH15: 正常 | CI15: 正常 | CJ15: 竞争无优势 | CK15: 正常 | CL15: 正常 | CM15: 正常 | CN15: 未上架 | CO15: 降价测试-市场无对手 | CP15: 未分析 | CQ15: 无调整 | CR15: 无异常 | CS15: 无异常 | CT15: 无调整 | CU15: 无异常 | CV15: 无异常 | CW15: N | CX15: N | CY15: N | CZ15: =IF(_xlfn.XLOOKUP(B15,[2]累计数据!$C$193:$C$245,[2]累计数据!$C$193:$C$245,"N")=B15,"Y","N") -> N | DA15: 0.02 | DB15: 0.02 | DC15: 0.02
A16: 12262 | B16: LYAP-X2170 | C16: 46091 | D16: =IF(_xlfn.XLOOKUP(A16,[1]分配表!J:J,[1]分配表!M:M)=0,"未出单",_xlfn.XLOOKUP(A16,[1]分配表!J:J,[1]分配表!M:M)) -> 46094 | E16: =_xlfn.XLOOKUP(A16,[1]分配表!A:A,[1]分配表!C:C) -> 张潇 | F16: 机盖及附件 | G16: 原开品 | H16: 0 | I16: 1 | J16: 1 | K16: 1 | L16: 2 | M16: 2 | N16: 0 | O16: 0 | P16: 1 | Q16: =IFERROR(P16-O16,P16) -> 1 | R16: 0 | S16: 142 | T16: 142 | U16: 142 | V16: 284 | W16: 284 | X16: 0 | Y16: 0 | Z16: 142 | AA16: =IFERROR(Z16-Y16,Z16) -> 142 | AB16: 0 | AC16: 1 | AD16: 0 | AE16: 0 | AF16: 1 | AG16: 0 | AH16: 0 | AI16: 0 | AJ16: 0 | AK16: 市场无出单 | AL16: 0.5 | AM16: 1 | AN16: 1 | AO16: 0.66666667 | AP16: 1 | AQ16: 1 | AR16: 市场无出单 | AS16: 市场无出单 | AT16: 未分析 | AU16: 7 | AV16: 14 | AW16: 3 | AX16: 9 | AY16: 5 | AZ16: 11 | BA16: 18 | BB16: 25 | BC16: 未出单 | BD16: Y | BE16: Y | BF16: Y | BG16: Y | BH16: Y | BI16: Y | BJ16: Y | BK16: Y | BL16: 异常 | BM16: 正常 | BN16: 异常 | BO16: 正常 | BP16: 异常 | BQ16: 正常 | BR16: 正常 | BS16: 正常 | BT16: 正常 | BU16: 异常 | BV16: 正常 | BW16: 正常 | BX16: 正常 | BY16: 正常 | BZ16: 正常 | CA16: 正常 | CB16: 正常 | CC16: 正常 | CD16: 未上架 | CE16: 无市场 | CF16: 竞争无优势 | CG16: 正常 | CH16: 正常 | CI16: 竞争无优势 | CJ16: 正常 | CK16: 正常 | CL16: 无市场 | CM16: 站外出单 | CN16: 未上架 | CO16: 无调整 | CP16: 无异常 | CQ16: 无异常 | CR16: 无异常 | CS16: 无调整 | CT16: 无异常 | CU16: 无异常 | CV16: 无异常 | CW16: N | CX16: N | CY16: N | CZ16: =IF(_xlfn.XLOOKUP(B16,[2]累计数据!$C$193:$C$245,[2]累计数据!$C$193:$C$245,"N")=B16,"Y","N") -> N | DA16: 0.02 | DB16: 0.02 | DC16: 0.02
A17: 12244 | B17: LYAP-X2190-L | C17: 46091 | D17: =IF(_xlfn.XLOOKUP(A17,[1]分配表!J:J,[1]分配表!M:M)=0,"未出单",_xlfn.XLOOKUP(A17,[1]分配表!J:J,[1]分配表!M:M)) -> 46101 | E17: =_xlfn.XLOOKUP(A17,[1]分配表!A:A,[1]分配表!C:C) -> 张潇 | F17: 饰条 | G17: 原开品 | H17: 0 | I17: 0 | J17: 1 | K17: 3 | L17: 2 | M17: 0 | N17: 1 | O17: 0 | P17: 0 | Q17: =IFERROR(P17-O17,P17) -> 0 | R17: 0 | S17: 0 | T17: 38 | U17: 114 | V17: 76 | W17: 0 | X17: 38 | Y17: 0 | Z17: 0 | AA17: =IFERROR(Z17-Y17,Z17) -> 0 | AB17: 0 | AC17: 0 | AD17: 1 | AE17: 0 | AF17: 0 | AG17: 0 | AH17: 1 | AI17: 0 | AJ17: 1 | AK17: 市场无出单 | AL17: 市场无出单 | AM17: 0.5 | AN17: 1 | AO17: 1 | AP17: 0 | AQ17: 0.5 | AR17: 市场无出单 | AS17: 0 | AT17: 未分析 | AU17: 7 | AV17: 7 | AW17: 15 | AX17: 0 | AY17: 8 | AZ17: 0 | BA17: 0 | BB17: 7 | BC17: 未出单 | BD17: 未出单 | BE17: N | BF17: N | BG17: N | BH17: N | BI17: N | BJ17: N | BK17: N | BL17: 异常 | BM17: 正常 | BN17: 正常 | BO17: 异常 | BP17: 正常 | BQ17: 正常 | BR17: 正常 | BS17: 正常 | BT17: 异常 | BU17: 异常 | BV17: 正常 | BW17: 正常 | BX17: 正常 | BY17: 正常 | BZ17: 正常 | CA17: 正常 | CB17: 正常 | CC17: 正常 | CD17: 未上架 | CE17: 无市场 | CF17: 无市场 | CG17: 竞争无优势 | CH17: 正常 | CI17: 正常 | CJ17: 正常 | CK17: 竞争无优势 | CL17: 无市场 | CM17: 竞争无优势 | CN17: 未上架 | CO17: 8日新品优化 | CP17: 未分析 | CQ17: 无调整 | CR17: 无异常 | CS17: 无异常 | CT17: 无异常 | CU17: 无异常 | CV17: 无异常 | CW17: Y | CX17: Y | CY17: Y | CZ17: =IF(_xlfn.XLOOKUP(B17,[2]累计数据!$C$193:$C$245,[2]累计数据!$C$193:$C$245,"N")=B17,"Y","N") -> Y | DA17: 0.02 | DB17: 0 | DC17: 0
A18: 12243 | B18: LYAP-X2190-R | C18: 46091 | D18: =IF(_xlfn.XLOOKUP(A18,[1]分配表!J:J,[1]分配表!M:M)=0,"未出单",_xlfn.XLOOKUP(A18,[1]分配表!J:J,[1]分配表!M:M)) -> 46106 | E18: =_xlfn.XLOOKUP(A18,[1]分配表!A:A,[1]分配表!C:C) -> 张潇 | F18: 饰条 | G18: 原开品 | H18: 0 | I18: 0 | J18: 1 | K18: 5 | L18: 0 | M18: 0 | N18: 1 | O18: 1 | P18: 1 | Q18: =IFERROR(P18-O18,P18) -> 0 | R18: 0 | S18: 0 | T18: 38 | U18: 190 | V18: 0 | W18: 0 | X18: 38 | Y18: 38 | Z18: 38 | AA18: =IFERROR(Z18-Y18,Z18) -> 0 | AB18: 0 | AC18: 3 | AD18: 1 | AE18: 0 | AF18: 2 | AG18: 2 | AH18: 1 | AI18: 2 | AJ18: 1 | AK18: 市场无出单 | AL18: 0 | AM18: 0.5 | AN18: 1 | AO18: 0 | AP18: 0 | AQ18: 0.5 | AR18: 0.3333 | AS18: 0.5 | AT18: 未分析 | AU18: 7 | AV18: 7 | AW18: 15 | AX18: 0 | AY18: 8 | AZ18: 14 | BA18: 0 | BB18: 7 | BC18: 未出单 | BD18: 未出单 | BE18: N | BF18: N | BG18: N | BH18: N | BI18: N | BJ18: N | BK18: N | BL18: 异常 | BM18: 正常 | BN18: 正常 | BO18: 异常 | BP18: 正常 | BQ18: 正常 | BR18: 异常 | BS18: 正常 | BT18: 异常 | BU18: 异常 | BV18: 正常 | BW18: 正常 | BX18: 正常 | BY18: 正常 | BZ18: 正常 | CA18: 正常 | CB18: 正常 | CC18: 正常 | CD18: 未上架 | CE18: 无市场 | CF18: 竞争无优势 | CG18: 竞争无优势 | CH18: 正常 | CI18: 竞争无优势 | CJ18: 无市场 | CK18: 竞争无优势 | CL18: 竞争无优势 | CM18: 竞争无优势 | CN18: 未上架 | CO18: 8日新品优化 | CP18: 未分析 | CQ18: 无调整 | CR18: 无异常 | CS18: 无异常 | CT18: 无异常 | CU18: 无调整 | CV18: 无异常 | CW18: Y | CX18: Y | CY18: Y | CZ18: =IF(_xlfn.XLOOKUP(B18,[2]累计数据!$C$193:$C$245,[2]累计数据!$C$193:$C$245,"N")=B18,"Y","N") -> Y | DA18: 0.02 | DB18: 0.02 | DC18: 0
A19: 12304 | B19: LYAP-X1642-GR | C19: 46092 | D19: =IF(_xlfn.XLOOKUP(A19,[1]分配表!J:J,[1]分配表!M:M)=0,"未出单",_xlfn.XLOOKUP(A19,[1]分配表!J:J,[1]分配表!M:M)) -> 46095 | E19: =_xlfn.XLOOKUP(A19,[1]分配表!A:A,[1]分配表!C:C) -> 俞东旭 | F19: 车门系统 | G19: 原开品 | H19: 0 | I19: 2 | J19: 3 | K19: 2 | L19: 2 | M19: 0 | N19: 0 | O19: 1 | P19: 0 | Q19: =IFERROR(P19-O19,P19) -> -1 | R19: 0 | S19: 998 | T19: 1497 | U19: 998 | V19: 998 | W19: 0 | X19: 0 | Y19: 499 | Z19: 0 | AA19: =IFERROR(Z19-Y19,Z19) -> -499 | AB19: 0 | AC19: 0 | AD19: 0 | AE19: 0 | AF19: 1 | AG19: 1 | AH19: 1 | AI19: 0 | AJ19: 1 | AK19: 市场无出单 | AL19: 1 | AM19: 1 | AN19: 1 | AO19: 0.66666667 | AP19: 0 | AQ19: 0 | AR19: 1 | AS19: 0 | AT19: 未上架 | AU19: 6 | AV19: 0 | AW19: 8 | AX19: 0 | AY19: 8 | AZ19: 5 | BA19: 12 | BB19: 19 | BC19: 未上架 | BD19: Y | BE19: Y | BF19: Y | BG19: Y | BH19: Y | BI19: Y | BJ19: Y | BK19: Y | BL19: 未上架 | BM19: 正常 | BN19: 正常 | BO19: 异常 | BP19: 正常 | BQ19: 异常 | BR19: 正常 | BS19: 正常 | BT19: 异常 | BU19: 未上架 | BV19: 异常 | BW19: 正常 | BX19: 正常 | BY19: 正常 | BZ19: 正常 | CA19: 正常 | CB19: 正常 | CC19: 正常 | CD19: 未上架 | CE19: 未上架 | CF19: 正常 | CG19: 正常 | CH19: 正常 | CI19: 竞争无优势 | CJ19: 竞争无优势 | CK19: 竞争无优势 | CL19: 正常 | CM19: 竞争无优势 | CN19: 未上架 | CO19: 未上架 | CP19: 无调整 | CQ19: 链接优化 | CR19: 无异常 | CS19: 无异常 | CT19: 链接优化 | CU19: 无异常 | CV19: 无异常 | CW19: N | CX19: N | CY19: N | CZ19: =IF(_xlfn.XLOOKUP(B19,[2]累计数据!$C$193:$C$245,[2]累计数据!$C$193:$C$245,"N")=B19,"Y","N") -> N | DA19: 0.02 | DB19: 0.02 | DC19: 0.02
A20: 12085 | B20: LYAP-X1911-BK | C20: 46092 | D20: =IF(_xlfn.XLOOKUP(A20,[1]分配表!J:J,[1]分配表!M:M)=0,"未出单",_xlfn.XLOOKUP(A20,[1]分配表!J:J,[1]分配表!M:M)) -> 46099 | E20: =_xlfn.XLOOKUP(A20,[1]分配表!A:A,[1]分配表!C:C) -> 张潇 | F20: 机盖及附件 | G20: 拓展品 | H20: 0 | I20: 1 | J20: 2 | K20: 2 | L20: 2 | M20: 6 | N20: 1 | O20: 1 | P20: 2 | Q20: =IFERROR(P20-O20,P20) -> 1 | R20: 0 | S20: 85 | T20: 170 | U20: 170 | V20: 170 | W20: 505.75 | X20: 85 | Y20: 85 | Z20: 170 | AA20: =IFERROR(Z20-Y20,Z20) -> 85 | AB20: 0 | AC20: 3 | AD20: 0 | AE20: 3 | AF20: 4 | AG20: 2 | AH20: 1 | AI20: 3 | AJ20: 1 | AK20: 市场无出单 | AL20: 0 | AM20: 1 | AN20: 0.4 | AO20: 0.33333333 | AP20: 0.75 | AQ20: 0.6667 | AR20: 0 | AS20: 0.6667 | AT20: 未上架 | AU20: 6 | AV20: 2 | AW20: 10 | AX20: 0 | AY20: 8 | AZ20: 5 | BA20: 12 | BB20: 1 | BC20: 未上架 | BD20: 未出单 | BE20: Y | BF20: Y | BG20: Y | BH20: Y | BI20: Y | BJ20: Y | BK20: Y | BL20: 未上架 | BM20: 正常 | BN20: 正常 | BO20: 异常 | BP20: 正常 | BQ20: 正常 | BR20: 正常 | BS20: 异常 | BT20: 正常 | BU20: 未上架 | BV20: 异常 | BW20: 正常 | BX20: 正常 | BY20: 正常 | BZ20: 正常 | CA20: 正常 | CB20: 正常 | CC20: 正常 | CD20: 未上架 | CE20: 未上架 | CF20: 竞争无优势 | CG20: 竞争无优势 | CH20: 竞争无优势 | CI20: 竞争无优势 | CJ20: 正常 | CK20: 竞争无优势 | CL20: 竞争无优势 | CM20: 竞争无优势 | CN20: 未上架 | CO20: 未上架 | CP20: 广告-PLP | CQ20: 无调整 | CR20: 无异常 | CS20: 无异常 | CT20: 无异常 | CU20: 无异常 | CV20: 无调整 | CW20: N | CX20: N | CY20: N | CZ20: =IF(_xlfn.XLOOKUP(B20,[2]累计数据!$C$193:$C$245,[2]累计数据!$C$193:$C$245,"N")=B20,"Y","N") -> N | DA20: 0.02 | DB20: 0.02 | DC20: 0.02
A21: 12086 | B21: LYAP-X1911-C | C21: 46092 | D21: =IF(_xlfn.XLOOKUP(A21,[1]分配表!J:J,[1]分配表!M:M)=0,"未出单",_xlfn.XLOOKUP(A21,[1]分配表!J:J,[1]分配表!M:M)) -> 46100 | E21: =_xlfn.XLOOKUP(A21,[1]分配表!A:A,[1]分配表!C:C) -> 张潇 | F21: 机盖及附件 | G21: 原开品 | H21: 0 | I21: 0 | J21: 2 | K21: 4 | L21: 2 | M21: 2 | N21: 3 | O21: 8 | P21: 3 | Q21: =IFERROR(P21-O21,P21) -> -5 | R21: 0 | S21: 0 | T21: 150 | U21: 300 | V21: 146.25 | W21: 150 | X21: 225 | Y21: 600 | Z21: 225 | AA21: =IFERROR(Z21-Y21,Z21) -> -375 | AB21: 0 | AC21: 3 | AD21: 7 | AE21: 5 | AF21: 5 | AG21: 5 | AH21: 6 | AI21: 4 | AJ21: 1 | AK21: 市场无出单 | AL21: 0 | AM21: 0.22222222 | AN21: 0.44444444 | AO21: 0.28571429 | AP21: 0.28571429 | AQ21: 0.25 | AR21: 0.6364 | AS21: 0.75 | AT21: 未上架 | AU21: 6 | AV21: 2 | AW21: 10 | AX21: 0 | AY21: 8 | AZ21: 2 | BA21: 9 | BB21: 1 | BC21: 未上架 | BD21: 未出单 | BE21: Y | BF21: Y | BG21: Y | BH21: Y | BI21: Y | BJ21: Y | BK21: Y | BL21: 未上架 | BM21: 正常 | BN21: 正常 | BO21: 异常 | BP21: 正常 | BQ21: 异常 | BR21: 正常 | BS21: 异常 | BT21: 正常 | BU21: 未上架 | BV21: 异常 | BW21: 正常 | BX21: 正常 | BY21: 正常 | BZ21: 正常 | CA21: 正常 | CB21: 正常 | CC21: 正常 | CD21: 未上架 | CE21: 未上架 | CF21: 竞争无优势 | CG21: 竞争无优势 | CH21: 竞争无优势 | CI21: 竞争无优势 | CJ21: 竞争无优势 | CK21: 竞争无优势 | CL21: 竞争无优势 | CM21: 正常 | CN21: 未上架 | CO21: 未上架 | CP21: 链接优化 | CQ21: 广告-PLP | CR21: 无异常 | CS21: 无异常 | CT21: 链接优化 | CU21: 无异常 | CV21: 无调整 | CW21: N | CX21: N | CY21: N | CZ21: =IF(_xlfn.XLOOKUP(B21,[2]累计数据!$C$193:$C$245,[2]累计数据!$C$193:$C$245,"N")=B21,"Y","N") -> N | DA21: 0.02 | DB21: 0.02 | DC21: 0.02
A22: 12258 | B22: LYAP-X1927 | C22: 46092 | D22: =IF(_xlfn.XLOOKUP(A22,[1]分配表!J:J,[1]分配表!M:M)=0,"未出单",_xlfn.XLOOKUP(A22,[1]分配表!J:J,[1]分配表!M:M)) -> 46099 | E22: =_xlfn.XLOOKUP(A22,[1]分配表!A:A,[1]分配表!C:C) -> 张潇 | F22: 机盖及附件 | G22: 原开品 | H22: 0 | I22: 1 | J22: 7 | K22: 3 | L22: 8 | M22: 8 | N22: 7 | O22: 7 | P22: 13 | Q22: =IFERROR(P22-O22,P22) -> 6 | R22: 0 | S22: 28 | T22: 196 | U22: 84 | V22: 224 | W22: 224 | X22: 196 | Y22: 196 | Z22: 364 | AA22: =IFERROR(Z22-Y22,Z22) -> 168 | AB22: 0 | AC22: 14 | AD22: 12 | AE22: 12 | AF22: 13 | AG22: 17 | AH22: 16 | AI22: 19 | AJ22: 17 | AK22: 市场无出单 | AL22: 0 | AM22: 0.36842105 | AN22: 0.2 | AO22: 0.38095238 | AP22: 0.32 | AQ22: 0.2727 | AR22: 0.24 | AS22: 0.3462 | AT22: 未上架 | AU22: 6 | AV22: 2 | AW22: 10 | AX22: 0 | AY22: 8 | AZ22: 2 | BA22: 9 | BB22: 0 | BC22: 未上架 | BD22: Y | BE22: Y | BF22: Y | BG22: Y | BH22: Y | BI22: Y | BJ22: Y | BK22: Y | BL22: 未上架 | BM22: 正常 | BN22: 正常 | BO22: 异常 | BP22: 正常 | BQ22: 异常 | BR22: 正常 | BS22: 异常 | BT22: 正常 | BU22: 未上架 | BV22: 异常 | BW22: 正常 | BX22: 正常 | BY22: 正常 | BZ22: 正常 | CA22: 正常 | CB22: 正常 | CC22: 正常 | CD22: 未上架 | CE22: 未上架 | CF22: 竞争无优势 | CG22: 竞争无优势 | CH22: 竞争无优势 | CI22: 竞争无优势 | CJ22: 竞争无优势 | CK22: 竞争无优势 | CL22: 竞争无优势 | CM22: 竞争无优势 | CN22: 未上架 | CO22: 未上架 | CP22: 无调整 | CQ22: 无调整 | CR22: 无异常 | CS22: 无异常 | CT22: 无调整 | CU22: 无异常 | CV22: 链接优化 | CW22: N | CX22: N | CY22: N | CZ22: =IF(_xlfn.XLOOKUP(B22,[2]累计数据!$C$193:$C$245,[2]累计数据!$C$193:$C$245,"N")=B22,"Y","N") -> N | DA22: 0.02 | DB22: 0.02 | DC22: 0.02
A23: 12210 | B23: LYAP-X1934 | C23: 46092 | D23: =IF(_xlfn.XLOOKUP(A23,[1]分配表!J:J,[1]分配表!M:M)=0,"未出单",_xlfn.XLOOKUP(A23,[1]分配表!J:J,[1]分配表!M:M)) -> 46104 | E23: =_xlfn.XLOOKUP(A23,[1]分配表!A:A,[1]分配表!C:C) -> 张潇 | F23: 饰条 | G23: 原开品 | H23: 0 | I23: 0 | J23: 1 | K23: 3 | L23: 17 | M23: 5 | N23: 4 | O23: 2 | P23: 6 | Q23: =IFERROR(P23-O23,P23) -> 4 | R23: 0 | S23: 0 | T23: 12 | U23: 36 | V23: 204 | W23: 60 | X23: 47.59 | Y23: 23.08 | Z23: 69.04 | AA23: =IFERROR(Z23-Y23,Z23) -> 45.96 | AB23: 0 | AC23: 39 | AD23: 28 | AE23: 40 | AF23: 23 | AG23: 24 | AH23: 25 | AI23: 26 | AJ23: 20 | AK23: 市场无出单 | AL23: 0 | AM23: 0.034482759 | AN23: 0.069767442 | AO23: 0.425 | AP23: 0.17241379 | AQ23: 0.1667 | AR23: 0.0714 | AS23: 0.1667 | AT23: 未上架 | AU23: 6 | AV23: 2 | AW23: 10 | AX23: 0 | AY23: 3 | AZ23: 5 | BA23: 12 | BB23: 0 | BC23: 未上架 | BD23: 未出单 | BE23: N | BF23: N | BG23: N | BH23: N | BI23: N | BJ23: N | BK23: N | BL23: 未上架 | BM23: 正常 | BN23: 正常 | BO23: 异常 | BP23: 正常 | BQ23: 正常 | BR23: 正常 | BS23: 异常 | BT23: 正常 | BU23: 未上架 | BV23: 异常 | BW23: 正常 | BX23: 正常 | BY23: 正常 | BZ23: 正常 | CA23: 正常 | CB23: 正常 | CC23: 正常 | CD23: 未上架 | CE23: 未上架 | CF23: 竞争无优势 | CG23: 竞争无优势 | CH23: 竞争无优势 | CI23: 竞争无优势 | CJ23: 竞争无优势 | CK23: 竞争无优势 | CL23: 竞争无优势 | CM23: 竞争无优势 | CN23: 未上架 | CO23: 未上架 | CP23: 广告-PLP | CQ23: 无调整 | CR23: 无异常 | CS23: 无异常 | CT23: 无异常 | CU23: 无异常 | CV23: 链接优化 | CW23: Y | CX23: Y | CY23: Y | CZ23: =IF(_xlfn.XLOOKUP(B23,[2]累计数据!$C$193:$C$245,[2]累计数据!$C$193:$C$245,"N")=B23,"Y","N") -> N | DA23: 0.02 | DB23: 0 | DC23: 0
A24: 12250 | B24: LYAP-X2148-1L | C24: 46092 | D24: =IF(_xlfn.XLOOKUP(A24,[1]分配表!J:J,[1]分配表!M:M)=0,"未出单",_xlfn.XLOOKUP(A24,[1]分配表!J:J,[1]分配表!M:M)) -> 46096 | E24: =_xlfn.XLOOKUP(A24,[1]分配表!A:A,[1]分配表!C:C) -> 王偲涵 | F24: 饰条 | G24: 拓展品 | H24: 0 | I24: 1 | J24: 0 | K24: 1 | L24: 1 | M24: 0 | N24: 0 | O24: 0 | P24: 2 | Q24: =IFERROR(P24-O24,P24) -> 2 | R24: 0 | S24: 39 | T24: 0 | U24: 39 | V24: 39 | W24: 0 | X24: 0 | Y24: 0 | Z24: 78 | AA24: =IFERROR(Z24-Y24,Z24) -> 78 | AB24: 0 | AC24: 1 | AD24: 2 | AE24: 0 | AF24: 1 | AG24: 0 | AH24: 0 | AI24: 0 | AJ24: 2 | AK24: 市场无出单 | AL24: 0.5 | AM24: 0 | AN24: 1 | AO24: 0.5 | AP24: 0 | AQ24: 市场无出单 | AR24: 市场无出单 | AS24: 0.5 | AT24: 未上架 | AU24: 7 | AV24: 14 | AW24: 22 | AX24: 28 | AY24: 7 | AZ24: 5 | BA24: 0 | BB24: 0 | BC24: 未上架 | BD24: Y | BE24: Y | BF24: Y | BG24: Y | BH24: Y | BI24: Y | BJ24: Y | BK24: Y | BL24: 未上架 | BM24: 正常 | BN24: 异常 | BO24: 异常 | BP24: 异常 | BQ24: 正常 | BR24: 正常 | BS24: 正常 | BT24: 正常 | BU24: 未上架 | BV24: 异常 | BW24: 正常 | BX24: 正常 | BY24: 正常 | BZ24: 正常 | CA24: 正常 | CB24: 正常 | CC24: 正常 | CD24: 未上架 | CE24: 未上架 | CF24: 竞争无优势 | CG24: 竞争无优势 | CH24: 无市场 | CI24: 竞争无优势 | CJ24: 无市场 | CK24: 无市场 | CL24: 站外出单 | CM24: 竞争无优势 | CN24: 未上架 | CO24: 未上架 | CP24: 未分析 | CQ24: 广告-PLP | CR24: 广告-PLP | CS24: 广告-PLP | CT24: 无异常 | CU24: 无异常 | CV24: 无异常 | CW24: Y | CX24: Y | CY24: Y | CZ24: =IF(_xlfn.XLOOKUP(B24,[2]累计数据!$C$193:$C$245,[2]累计数据!$C$193:$C$245,"N")=B24,"Y","N") -> Y | DA24: 0.02 | DB24: 0 | DC24: 0
A25: 12251 | B25: LYAP-X2148-1R | C25: 46092 | D25: =IF(_xlfn.XLOOKUP(A25,[1]分配表!J:J,[1]分配表!M:M)=0,"未出单",_xlfn.XLOOKUP(A25,[1]分配表!J:J,[1]分配表!M:M)) -> 46112 | E25: =_xlfn.XLOOKUP(A25,[1]分配表!A:A,[1]分配表!C:C) -> 王偲涵 | F25: 饰条 | G25: 拓展品 | H25: 0 | I25: 0 | J25: 0 | K25: 1 | L25: 0 | M25: 2 | N25: 0 | O25: 0 | P25: 0 | Q25: =IFERROR(P25-O25,P25) -> 0 | R25: 0 | S25: 0 | T25: 0 | U25: 39 | V25: 0 | W25: 78 | X25: 0 | Y25: 0 | Z25: 0 | AA25: =IFERROR(Z25-Y25,Z25) -> 0 | AB25: 0 | AC25: 1 | AD25: 1 | AE25: 2 | AF25: 0 | AG25: 1 | AH25: 0 | AI25: 0 | AJ25: 0 | AK25: 市场无出单 | AL25: 0 | AM25: 0 | AN25: 0.33333333 | AO25: 0 | AP25: 0.66666667 | AQ25: 1 | AR25: 市场无出单 | AS25: 市场无出单 | AT25: 未上架 | AU25: 7 | AV25: 14 | AW25: 22 | AX25: 28 | AY25: 7 | AZ25: 5 | BA25: 4 | BB25: 0 | BC25: 未上架 | BD25: 未出单 | BE25: 未出单 | BF25: N | BG25: N | BH25: N | BI25: N | BJ25: N | BK25: N | BL25: 未上架 | BM25: 正常 | BN25: 异常 | BO25: 异常 | BP25: 异常 | BQ25: 正常 | BR25: 正常 | BS25: 正常 | BT25: 正常 | BU25: 未上架 | BV25: 异常 | BW25: 正常 | BX25: 正常 | BY25: 正常 | BZ25: 正常 | CA25: 正常 | CB25: 正常 | CC25: 正常 | CD25: 未上架 | CE25: 未上架 | CF25: 竞争无优势 | CG25: 竞争无优势 | CH25: 竞争无优势 | CI25: 无市场 | CJ25: 无市场 | CK25: 正常 | CL25: 站外出单 | CM25: 无市场 | CN25: 未上架 | CO25: 未上架 | CP25: 未分析 | CQ25: 广告-PLP | CR25: 广告-PLP | CS25: 广告-PLP | CT25: 无异常 | CU25: 无异常 | CV25: 无异常 | CW25: Y | CX25: Y | CY25: Y | CZ25: =IF(_xlfn.XLOOKUP(B25,[2]累计数据!$C$193:$C$245,[2]累计数据!$C$193:$C$245,"N")=B25,"Y","N") -> Y | DA25: 0.02 | DB25: 0.02 | DC25: 0.02
A26: 12332 | B26: LYAP-X2289 | C26: 46092 | D26: =IF(_xlfn.XLOOKUP(A26,[1]分配表!J:J,[1]分配表!M:M)=0,"未出单",_xlfn.XLOOKUP(A26,[1]分配表!J:J,[1]分配表!M:M)) -> 46095 | E26: =_xlfn.XLOOKUP(A26,[1]分配表!A:A,[1]分配表!C:C) -> 张潇 | F26: 饰条 | G26: 原开品 | H26: 0 | I26: 3 | J26: 6 | K26: 5 | L26: 5 | M26: 5 | N26: 5 | O26: 3 | P26: 2 | Q26: =IFERROR(P26-O26,P26) -> -1 | R26: 0 | S26: 327 | T26: 654 | U26: 545 | V26: 570 | W26: 570 | X26: 570 | Y26: 342 | Z26: 228 | AA26: =IFERROR(Z26-Y26,Z26) -> -114 | AB26: 0 | AC26: 2 | AD26: 1 | AE26: 0 | AF26: 0 | AG26: 1 | AH26: 2 | AI26: 1 | AJ26: 3 | AK26: 市场无出单 | AL26: 0.3333 | AM26: 0.85714286 | AN26: 1 | AO26: 1 | AP26: 0.83333333 | AQ26: 0.7143 | AR26: 0.8 | AS26: 0.5 | AT26: 未上架 | AU26: 7 | AV26: 14 | AW26: 22 | AX26: 0 | AY26: 8 | AZ26: 14 | BA26: 2 | BB26: 9 | BC26: 未上架 | BD26: Y | BE26: Y | BF26: Y | BG26: Y | BH26: Y | BI26: Y | BJ26: Y | BK26: Y | BL26: 未上架 | BM26: 正常 | BN26: 异常 | BO26: 异常 | BP26: 正常 | BQ26: 正常 | BR26: 异常 | BS26: 正常 | BT26: 异常 | BU26: 未上架 | BV26: 异常 | BW26: 正常 | BX26: 正常 | BY26: 正常 | BZ26: 正常 | CA26: 正常 | CB26: 正常 | CC26: 正常 | CD26: 未上架 | CE26: 未上架 | CF26: 站内无价格优势 | CG26: 正常 | CH26: 正常 | CI26: 正常 | CJ26: 正常 | CK26: 正常 | CL26: 正常 | CM26: 竞争无优势 | CN26: 未上架 | CO26: 未上架 | CP26: 未分析 | CQ26: 无调整 | CR26: 无异常 | CS26: 无异常 | CT26: 无异常 | CU26: 无调整 | CV26: 无异常 | CW26: Y | CX26: Y | CY26: Y | CZ26: =IF(_xlfn.XLOOKUP(B26,[2]累计数据!$C$193:$C$245,[2]累计数据!$C$193:$C$245,"N")=B26,"Y","N") -> N | DA26: 0.02 | DB26: 0.02 | DC26: 0
A27: 12227 | B27: LYAP-X2418 | C27: 46092 | D27: =IF(_xlfn.XLOOKUP(A27,[1]分配表!J:J,[1]分配表!M:M)=0,"未出单",_xlfn.XLOOKUP(A27,[1]分配表!J:J,[1]分配表!M:M)) -> 46097 | E27: =_xlfn.XLOOKUP(A27,[1]分配表!A:A,[1]分配表!C:C) -> 章鹏 | F27: 其他 | G27: 原开品 | H27: 0 | I27: 2 | J27: 4 | K27: 2 | L27: 3 | M27: 1 | N27: 4 | O27: 3 | P27: 5 | Q27: =IFERROR(P27-O27,P27) -> 2 | R27: 0 | S27: 138 | T27: 276 | U27: 138 | V27: 207 | W27: 69 | X27: 276 | Y27: 197 | Z27: 345 | AA27: =IFERROR(Z27-Y27,Z27) -> 148 | AB27: 0 | AC27: 4 | AD27: 0 | AE27: 0 | AF27: 1 | AG27: 1 | AH27: 3 | AI27: 1 | AJ27: 0 | AK27: 市场无出单 | AL27: 0.3333 | AM27: 1 | AN27: 1 | AO27: 0.75 | AP27: 0.5 | AQ27: 0.5 | AR27: 0.6667 | AS27: 1 | AT27: 未上架 | AU27: 6 | AV27: 2 | AW27: 10 | AX27: 5 | AY27: 13 | AZ27: 19 | BA27: 6 | BB27: 13 | BC27: 未上架 | BD27: Y | BE27: Y | BF27: Y | BG27: Y | BH27: Y | BI27: Y | BJ27: Y | BK27: Y | BL27: 未上架 | BM27: 正常 | BN27: 正常 | BO27: 异常 | BP27: 正常 | BQ27: 正常 | BR27: 异常 | BS27: 正常 | BT27: 正常 | BU27: 未上架 | BV27: 异常 | BW27: 正常 | BX27: 正常 | BY27: 正常 | BZ27: 正常 | CA27: 正常 | CB27: 正常 | CC27: 正常 | CD27: 未上架 | CE27: 未上架 | CF27: 竞争无优势 | CG27: 正常 | CH27: 正常 | CI27: 正常 | CJ27: 正常 | CK27: 竞争无优势 | CL27: 竞争无优势 | CM27: 正常 | CN27: 未上架 | CO27: 未上架 | CP27: 无调整 | CQ27: 链接优化 | CR27: 无异常 | CS27: 无异常 | CT27: 无异常 | CU27: 无调整 | CV27: 无异常 | CW27: N | CX27: N | CY27: N | CZ27: =IF(_xlfn.XLOOKUP(B27,[2]累计数据!$C$193:$C$245,[2]累计数据!$C$193:$C$245,"N")=B27,"Y","N") -> N | DA27: 0.02 | DB27: 0.02 | DC27: 0.02
A28: 12309 | B28: MD-002-FL | C28: 46092 | D28: =IF(_xlfn.XLOOKUP(A28,[1]分配表!J:J,[1]分配表!M:M)=0,"未出单",_xlfn.XLOOKUP(A28,[1]分配表!J:J,[1]分配表!M:M)) -> 46101 | E28: =_xlfn.XLOOKUP(A28,[1]分配表!A:A,[1]分配表!C:C) -> 俞东旭 | F28: 车门系统 | G28: 原开品 | H28: 0 | I28: 0 | J28: 2 | K28: 2 | L28: 1 | M28: 0 | N28: 0 | O28: 1 | P28: 0 | Q28: =IFERROR(P28-O28,P28) -> -1 | R28: 0 | S28: 0 | T28: 960 | U28: 960 | V28: 480 | W28: 0 | X28: 0 | Y28: 480 | Z28: 0 | AA28: =IFERROR(Z28-Y28,Z28) -> -480 | AB28: 0 | AC28: 3 | AD28: 2 | AE28: 0 | AF28: 1 | AG28: 1 | AH28: 1 | AI28: 1 | AJ28: 1 | AK28: 市场无出单 | AL28: 0 | AM28: 0.5 | AN28: 1 | AO28: 0.5 | AP28: 0 | AQ28: 0 | AR28: 0.5 | AS28: 0 | AT28: 未上架 | AU28: 6 | AV28: 0 | AW28: 8 | AX28: 0 | AY28: 8 | AZ28: 14 | BA28: 0 | BB28: 1 | BC28: 未上架 | BD28: 未出单 | BE28: N | BF28: N | BG28: N | BH28: N | BI28: N | BJ28: N | BK28: N | BL28: 未上架 | BM28: 正常 | BN28: 正常 | BO28: 异常 | BP28: 正常 | BQ28: 正常 | BR28: 异常 | BS28: 正常 | BT28: 正常 | BU28: 未上架 | BV28: 异常 | BW28: 正常 | BX28: 正常 | BY28: 正常 | BZ28: 正常 | CA28: 正常 | CB28: 正常 | CC28: 正常 | CD28: 未上架 | CE28: 未上架 | CF28: 竞争无优势 | CG28: 竞争无优势 | CH28: 正常 | CI28: 竞争无优势 | CJ28: 无市场 | CK28: 竞争无优势 | CL28: 竞争无优势 | CM28: 竞争无优势 | CN28: 未上架 | CO28: 未上架 | CP28: 无调整 | CQ28: 无调整 | CR28: 无异常 | CS28: 无异常 | CT28: 无异常 | CU28: 无调整 | CV28: 无异常 | CW28: N | CX28: N | CY28: N | CZ28: =IF(_xlfn.XLOOKUP(B28,[2]累计数据!$C$193:$C$245,[2]累计数据!$C$193:$C$245,"N")=B28,"Y","N") -> N | DA28: 0.02 | DB28: 0.02 | DC28: 0.02
A29: 12310 | B29: MD-002-FR | C29: 46092 | D29: =IF(_xlfn.XLOOKUP(A29,[1]分配表!J:J,[1]分配表!M:M)=0,"未出单",_xlfn.XLOOKUP(A29,[1]分配表!J:J,[1]分配表!M:M)) -> 46096 | E29: =_xlfn.XLOOKUP(A29,[1]分配表!A:A,[1]分配表!C:C) -> 俞东旭 | F29: 车门系统 | G29: 原开品 | H29: 0 | I29: 2 | J29: 0 | K29: 3 | L29: 1 | M29: 2 | N29: 1 | O29: 2 | P29: 1 | Q29: =IFERROR(P29-O29,P29) -> -1 | R29: 0 | S29: 960 | T29: 0 | U29: 1440 | V29: 480 | W29: 960 | X29: 485 | Y29: 969 | Z29: 483 | AA29: =IFERROR(Z29-Y29,Z29) -> -486 | AB29: 0 | AC29: 1 | AD29: 1 | AE29: 2 | AF29: 0 | AG29: 2 | AH29: 0 | AI29: 0 | AJ29: 4 | AK29: 市场无出单 | AL29: 0.6667 | AM29: 0 | AN29: 0.6 | AO29: 1 | AP29: 0.5 | AQ29: 1 | AR29: 1 | AS29: 0.3333 | AT29: 未上架 | AU29: 6 | AV29: 0 | AW29: 5 | AX29: 11 | AY29: 1 | AZ29: 2 | BA29: 9 | BB29: 16 | BC29: 未上架 | BD29: Y | BE29: Y | BF29: Y | BG29: Y | BH29: Y | BI29: Y | BJ29: Y | BK29: Y | BL29: 未上架 | BM29: 正常 | BN29: 正常 | BO29: 正常 | BP29: 异常 | BQ29: 正常 | BR29: 正常 | BS29: 正常 | BT29: 异常 | BU29: 未上架 | BV29: 异常 | BW29: 正常 | BX29: 正常 | BY29: 正常 | BZ29: 正常 | CA29: 正常 | CB29: 正常 | CC29: 正常 | CD29: 未上架 | CE29: 未上架 | CF29: 竞争无优势 | CG29: 竞争无优势 | CH29: 正常 | CI29: 正常 | CJ29: 正常 | CK29: 正常 | CL29: 正常 | CM29: 竞争无优势 | CN29: 未上架 | CO29: 未上架 | CP29: 无调整 | CQ29: 无异常 | CR29: 无异常 | CS29: 链接优化 | CT29: 无异常 | CU29: 无异常 | CV29: 无异常 | CW29: N | CX29: N | CY29: N | CZ29: =IF(_xlfn.XLOOKUP(B29,[2]累计数据!$C$193:$C$245,[2]累计数据!$C$193:$C$245,"N")=B29,"Y","N") -> N | DA29: 0.025 | DB29: 0.02 | DC29: 0.02
A30: 12311 | B30: MD-002-RL | C30: 46092 | D30: =IF(_xlfn.XLOOKUP(A30,[1]分配表!J:J,[1]分配表!M:M)=0,"未出单",_xlfn.XLOOKUP(A30,[1]分配表!J:J,[1]分配表!M:M)) -> 46102 | E30: =_xlfn.XLOOKUP(A30,[1]分配表!A:A,[1]分配表!C:C) -> 俞东旭 | F30: 车门系统 | G30: 原开品 | H30: 0 | I30: 0 | J30: 1 | K30: 0 | L30: 1 | M30: 1 | N30: 0 | O30: 0 | P30: 0 | Q30: =IFERROR(P30-O30,P30) -> 0 | R30: 0 | S30: 0 | T30: 480 | U30: 0 | V30: 480 | W30: 480 | X30: 0 | Y30: 0 | Z30: 0 | AA30: =IFERROR(Z30-Y30,Z30) -> 0 | AB30: 0 | AC30: 1 | AD30: 3 | AE30: 1 | AF30: 0 | AG30: 2 | AH30: 2 | AI30: 1 | AJ30: 2 | AK30: 市场无出单 | AL30: 0 | AM30: 0.25 | AN30: 0 | AO30: 1 | AP30: 0.33333333 | AQ30: 0.3333 | AR30: 0 | AS30: 0 | AT30: 未上架 | AU30: 6 | AV30: 0 | AW30: 8 | AX30: 0 | AY30: 6 | AZ30: 12 | BA30: 0 | BB30: 1 | BC30: 未上架 | BD30: 未出单 | BE30: N | BF30: N | BG30: N | BH30: N | BI30: N | BJ30: N | BK30: N | BL30: 未上架 | BM30: 正常 | BN30: 正常 | BO30: 异常 | BP30: 正常 | BQ30: 正常 | BR30: 异常 | BS30: 正常 | BT30: 正常 | BU30: 未上架 | BV30: 异常 | BW30: 正常 | BX30: 正常 | BY30: 正常 | BZ30: 正常 | CA30: 正常 | CB30: 正常 | CC30: 正常 | CD30: 未上架 | CE30: 未上架 | CF30: 竞争无优势 | CG30: 竞争无优势 | CH30: 竞争无优势 | CI30: 正常 | CJ30: 竞争无优势 | CK30: 竞争无优势 | CL30: 竞争无优势 | CM30: 竞争无优势 | CN30: 未上架 | CO30: 未上架 | CP30: 无调整 | CQ30: 无调整 | CR30: 无异常 | CS30: 无异常 | CT30: 无异常 | CU30: 无调整 | CV30: 无异常 | CW30: N | CX30: N | CY30: N | CZ30: =IF(_xlfn.XLOOKUP(B30,[2]累计数据!$C$193:$C$245,[2]累计数据!$C$193:$C$245,"N")=B30,"Y","N") -> N | DA30: 0.02 | DB30: 0.02 | DC30: 0.02
A31: 12312 | B31: MD-002-RR | C31: 46092 | D31: =IF(_xlfn.XLOOKUP(A31,[1]分配表!J:J,[1]分配表!M:M)=0,"未出单",_xlfn.XLOOKUP(A31,[1]分配表!J:J,[1]分配表!M:M)) -> 46096 | E31: =_xlfn.XLOOKUP(A31,[1]分配表!A:A,[1]分配表!C:C) -> 俞东旭 | F31: 车门系统 | G31: 原开品 | H31: 0 | I31: 2 | J31: 0 | K31: 3 | L31: 0 | M31: 0 | N31: 0 | O31: 2 | P31: 1 | Q31: =IFERROR(P31-O31,P31) -> -1 | R31: 0 | S31: 960 | T31: 0 | U31: 1440 | V31: 0 | W31: 0 | X31: 0 | Y31: 956 | Z31: 478 | AA31: =IFERROR(Z31-Y31,Z31) -> -478 | AB31: 0 | AC31: 3 | AD31: 3 | AE31: 0 | AF31: 1 | AG31: 4 | AH31: 2 | AI31: 2 | AJ31: 4 | AK31: 市场无出单 | AL31: 0.4 | AM31: 0 | AN31: 1 | AO31: 0 | AP31: 0 | AQ31: 0 | AR31: 0.3333 | AS31: 0.3333 | AT31: 未上架 | AU31: 6 | AV31: 0 | AW31: 5 | AX31: 11 | AY31: 1 | AZ31: 5 | BA31: 4 | BB31: 1 | BC31: 未上架 | BD31: Y | BE31: Y | BF31: Y | BG31: Y | BH31: Y | BI31: Y | BJ31: Y | BK31: Y | BL31: 未上架 | BM31: 正常 | BN31: 正常 | BO31: 正常 | BP31: 异常 | BQ31: 正常 | BR31: 正常 | BS31: 正常 | BT31: 正常 | BU31: 未上架 | BV31: 异常 | BW31: 正常 | BX31: 正常 | BY31: 正常 | BZ31: 正常 | CA31: 正常 | CB31: 正常 | CC31: 正常 | CD31: 未上架 | CE31: 未上架 | CF31: 站内无价格优势 | CG31: 竞争无优势 | CH31: 竞争无优势 | CI31: 竞争无优势 | CJ31: 竞争无优势 | CK31: 竞争无优势 | CL31: 竞争无优势 | CM31: 竞争无优势 | CN31: 未上架 | CO31: 未上架 | CP31: 无调整 | CQ31: 无异常 | CR31: 无异常 | CS31: 广告-PLP | CT31: 无异常 | CU31: 无异常 | CV31: 无异常 | CW31: Y | CX31: Y | CY31: Y | CZ31: =IF(_xlfn.XLOOKUP(B31,[2]累计数据!$C$193:$C$245,[2]累计数据!$C$193:$C$245,"N")=B31,"Y","N") -> Y | DA31: 0.025 | DB31: 0 | DC31: 0
A32: 12441 | B32: LYAM-X2862 | C32: 46093 | D32: =IF(_xlfn.XLOOKUP(A32,[1]分配表!J:J,[1]分配表!M:M)=0,"未出单",_xlfn.XLOOKUP(A32,[1]分配表!J:J,[1]分配表!M:M)) -> 46100 | E32: =_xlfn.XLOOKUP(A32,[1]分配表!A:A,[1]分配表!C:C) -> 张潇 | F32: 机盖及附件 | G32: 原开品 | H32: 0 | I32: 0 | J32: 3 | K32: 2 | L32: 1 | M32: 4 | N32: 0 | O32: 1 | P32: 2 | Q32: =IFERROR(P32-O32,P32) -> 1 | R32: 0 | S32: 0 | T32: 417 | U32: 278 | V32: 143 | W32: 556 | X32: 0 | Y32: 139 | Z32: 278 | AA32: =IFERROR(Z32-Y32,Z32) -> 139 | AB32: 0 | AC32: 1 | AD32: 1 | AE32: 1 | AF32: 2 | AG32: 0 | AH32: 0 | AI32: 0 | AJ32: 1 | AK32: 市场无出单 | AL32: 0 | AM32: 0.75 | AN32: 0.66666667 | AO32: 0.33333333 | AP32: 1 | AQ32: 1 | AR32: 1 | AS32: 0.5 | AT32: 未上架 | AU32: 5 | AV32: 0 | AW32: 8 | AX32: 0 | AY32: 6 | AZ32: 12 | BA32: 19 | BB32: 26 | BC32: 未上架 | BD32: 未出单 | BE32: Y | BF32: Y | BG32: Y | BH32: Y | BI32: Y | BJ32: Y | BK32: Y | BL32: 未上架 | BM32: 正常 | BN32: 正常 | BO32: 异常 | BP32: 正常 | BQ32: 正常 | BR32: 正常 | BS32: 正常 | BT32: 异常 | BU32: 未上架 | BV32: 异常 | BW32: 正常 | BX32: 正常 | BY32: 正常 | BZ32: 正常 | CA32: 正常 | CB32: 正常 | CC32: 正常 | CD32: 未上架 | CE32: 未上架 | CF32: 竞争无优势 | CG32: 竞争无优势 | CH32: 竞争无优势 | CI32: 竞争无优势 | CJ32: 竞争无优势 | CK32: 正常 | CL32: 正常 | CM32: 竞争无优势 | CN32: 未上架 | CO32: 未上架 | CP32: 无调整 | CQ32: 降价测试-市场无对手 | CR32: 无异常 | CS32: 无异常 | CT32: 无异常 | CU32: 无异常 | CV32: 无异常 | CW32: Y | CX32: Y | CY32: Y | CZ32: =IF(_xlfn.XLOOKUP(B32,[2]累计数据!$C$193:$C$245,[2]累计数据!$C$193:$C$245,"N")=B32,"Y","N") -> N | DA32: 0.02 | DB32: 0 | DC32: 0
