Workbook

Sheet 近三月新品明细数据
A1: 销售编号 | B1: SKU | C1: 最新上架日期 | D1: 首次出单日期 | E1: 4月分析人 | F1: 5月分析人 | G1: 品类 | H1: 产品拓展 | I1: 4月分析频次 | J1: 5月分析频次 | K1: 4月 8日出单 | L1: 5月 8日出单 | M1: 4月市场状态 | N1: 5月市场状态 | O1: 4月销量 | P1: 5月销量 | Q1: 4月销售额 | R1: 5月销售额 | S1: 4月对手出单 | T1: 5月对手出单 | U1: 4月市容 | V1: 5月市容 | W1: 4月市占比 | X1: 5月市占比 | Y1: 4月 PLP广告销量 | Z1: 4月 PLP广告销售额 | AA1: 4月 PLP广告花费 | AB1: 4月 PLP广告ACOS1 | AC1: 4月 PLP广告ACOAS | AD1: 5月 PLP广告销量 | AE1: 5月 PLP广告销售额 | AF1: 5月 PLP广告花费 | AG1: 5月 PLP广告ACOS1 | AH1: 5月 PLP广告ACOAS | AI1: 4月 PLG广告花费 | AJ1: 4月 PLG广告销售额 | AK1: 4月 PLG广告ACOS | AL1: 4月 PLG广告ACOAS | AM1: 4月 总广告ACOAS | AN1: 5月 PLG广告花费 | AO1: 5月 PLG广告销售额 | AP1: 5月 PLG广告ACOS | AQ1: 5月 PLG广告ACOAS | AR1: 5月 总广告ACOAS
A2: 12073 | B2: LYAP-X1658 | C2: =_xlfn.XLOOKUP(A2,[1]分配表!J:J,[1]分配表!L:L) -> 46085 | D2: =IF(_xlfn.XLOOKUP(A2,[1]分配表!J:J,[1]分配表!M:M)=0,"未出单",_xlfn.XLOOKUP(A2,[1]分配表!J:J,[1]分配表!M:M)) -> 46093 | E2: 朱培源 | F2: =_xlfn.XLOOKUP(A2,[1]分配表!A:A,[1]分配表!C:C) -> 朱培源 | G2: =IF(_xlfn.XLOOKUP($A2,[1]分配表!$A:$A,[1]分配表!D:D)=0,"未分类",_xlfn.XLOOKUP($A2,[1]分配表!$A:$A,[1]分配表!D:D)) -> 车门系统 | H2: =_xlfn.XLOOKUP(A2,[1]分配表!J:J,[1]分配表!I:I) -> 原开品 | I2: =COUNTIFS([1]月销售数据!L:L,A2,[1]月销售数据!M:M,">=2026-4-1",[1]月销售数据!M:M,"<=2026-4-30") -> 3 | J2: =COUNTIFS([1]月销售数据!L:L,A2,[1]月销售数据!M:M,">=2026-5-1",[1]月销售数据!M:M,"<=2026-5-31") -> 1 | K2: Y | L2: Y | M2: 无市场 | N2: 正常 | O2: 2 | P2: 8 | Q2: 840 | R2: 3360 | S2: 0 | T2: 0 | U2: 2 | V2: =T2+P2 -> 8 | W2: 1 | X2: 1 | Y2: 0 | Z2: 0 | AA2: 18.23 | AB2: #DIV/0! | AC2: 0.021702381 | AD2: 0 | AE2: 0 | AF2: 0 | AG2: #DIV/0! | AH2: 0 | AI2: 32.09 | AJ2: 911.4 | AK2: 0.035209568 | AL2: 0.038202381 | AM2: 0.065904762 | AN2: 181.75 | AO2: 4546.92 | AP2: 0.039972113 | AQ2: 0.054092262 | AR2: 0.055464286
A3: 12074 | B3: LYAP-X1658L | C3: =_xlfn.XLOOKUP(A3,[1]分配表!J:J,[1]分配表!L:L) -> 46085 | D3: =IF(_xlfn.XLOOKUP(A3,[1]分配表!J:J,[1]分配表!M:M)=0,"未出单",_xlfn.XLOOKUP(A3,[1]分配表!J:J,[1]分配表!M:M)) -> 46085 | E3: 朱培源 | F3: =_xlfn.XLOOKUP(A3,[1]分配表!A:A,[1]分配表!C:C) -> 朱培源 | G3: =IF(_xlfn.XLOOKUP($A3,[1]分配表!$A:$A,[1]分配表!D:D)=0,"未分类",_xlfn.XLOOKUP($A3,[1]分配表!$A:$A,[1]分配表!D:D)) -> 车门系统 | H3: =_xlfn.XLOOKUP(A3,[1]分配表!J:J,[1]分配表!I:I) -> 拓展品 | I3: =COUNTIFS([1]月销售数据!L:L,A3,[1]月销售数据!M:M,">=2026-4-1",[1]月销售数据!M:M,"<=2026-4-30") -> 2 | J3: =COUNTIFS([1]月销售数据!L:L,A3,[1]月销售数据!M:M,">=2026-5-1",[1]月销售数据!M:M,"<=2026-5-31") -> 1 | K3: Y | L3: Y | M3: 正常 | N3: 正常 | O3: 24 | P3: 23 | Q3: 5698.62 | R3: 5766.52 | S3: 0 | T3: 1 | U3: 24 | V3: =T3+P3 -> 24 | W3: 1 | X3: 0.95833333 | Y3: 1 | Z3: 211.81 | AA3: 29.89 | AB3: 0.14111704 | AC3: 0.0052451295 | AD3: 1 | AE3: 295.77 | AF3: 0 | AG3: 0 | AH3: 0 | AI3: 225.24 | AJ3: 6105.74 | AK3: 0.036889877 | AL3: 0.039525359 | AM3: 0.049269823 | AN3: 191.15 | AO3: 5155.87 | AP3: 0.037074247 | AQ3: 0.033148242 | AR3: 0.035253498
A4: 12075 | B4: LYAP-X1658R | C4: =_xlfn.XLOOKUP(A4,[1]分配表!J:J,[1]分配表!L:L) -> 46085 | D4: =IF(_xlfn.XLOOKUP(A4,[1]分配表!J:J,[1]分配表!M:M)=0,"未出单",_xlfn.XLOOKUP(A4,[1]分配表!J:J,[1]分配表!M:M)) -> 46085 | E4: 朱培源 | F4: =_xlfn.XLOOKUP(A4,[1]分配表!A:A,[1]分配表!C:C) -> 朱培源 | G4: =IF(_xlfn.XLOOKUP($A4,[1]分配表!$A:$A,[1]分配表!D:D)=0,"未分类",_xlfn.XLOOKUP($A4,[1]分配表!$A:$A,[1]分配表!D:D)) -> 车门系统 | H4: =_xlfn.XLOOKUP(A4,[1]分配表!J:J,[1]分配表!I:I) -> 拓展品 | I4: =COUNTIFS([1]月销售数据!L:L,A4,[1]月销售数据!M:M,">=2026-4-1",[1]月销售数据!M:M,"<=2026-4-30") -> 2 | J4: =COUNTIFS([1]月销售数据!L:L,A4,[1]月销售数据!M:M,">=2026-5-1",[1]月销售数据!M:M,"<=2026-5-31") -> 1 | K4: Y | L4: Y | M4: 无市场 | N4: 无市场 | O4: 1 | P4: 3 | Q4: 220 | R4: 660 | S4: 0 | T4: 0 | U4: 1 | V4: =T4+P4 -> 3 | W4: 1 | X4: 1 | Y4: 0 | Z4: 0 | AA4: 4.81 | AB4: #DIV/0! | AC4: 0.021863636 | AD4: 0 | AE4: 0 | AF4: 0 | AG4: #DIV/0! | AH4: 0 | AI4: 11.98 | AJ4: 239.58 | AK4: 0.050004174 | AL4: 0.054454545 | AM4: 0.085045455 | AN4: 36.73 | AO4: 951.39 | AP4: 0.03860667 | AQ4: 0.055651515 | AR4: 0.059848485
A5: 12252 | B5: LYAP-X1800-1 | C5: =_xlfn.XLOOKUP(A5,[1]分配表!J:J,[1]分配表!L:L) -> 46085 | D5: =IF(_xlfn.XLOOKUP(A5,[1]分配表!J:J,[1]分配表!M:M)=0,"未出单",_xlfn.XLOOKUP(A5,[1]分配表!J:J,[1]分配表!M:M)) -> 46089 | E5: 胡煜星 | F5: =_xlfn.XLOOKUP(A5,[1]分配表!A:A,[1]分配表!C:C) -> 胡煜星 | G5: =IF(_xlfn.XLOOKUP($A5,[1]分配表!$A:$A,[1]分配表!D:D)=0,"未分类",_xlfn.XLOOKUP($A5,[1]分配表!$A:$A,[1]分配表!D:D)) -> 车门系统 | H5: =_xlfn.XLOOKUP(A5,[1]分配表!J:J,[1]分配表!I:I) -> 原开品 | I5: =COUNTIFS([1]月销售数据!L:L,A5,[1]月销售数据!M:M,">=2026-4-1",[1]月销售数据!M:M,"<=2026-4-30") -> 3 | J5: =COUNTIFS([1]月销售数据!L:L,A5,[1]月销售数据!M:M,">=2026-5-1",[1]月销售数据!M:M,"<=2026-5-31") -> 4 | K5: Y | L5: Y | M5: 竞争无优势 | N5: 竞争无优势 | O5: 1 | P5: 4 | Q5: 40 | R5: 160 | S5: 13 | T5: 10 | U5: 14 | V5: =T5+P5 -> 14 | W5: 0.071428571 | X5: 0.28571429 | Y5: 0 | Z5: 0 | AA5: 1.95 | AB5: #DIV/0! | AC5: 0.04875 | AD5: 1 | AE5: 42.65 | AF5: 15.31 | AG5: 0.35896835 | AH5: 0.0956875 | AI5: 3.38 | AJ5: 42.2 | AK5: 0.080094787 | AL5: 0.0845 | AM5: 0.138 | AN5: 6.46 | AO5: 129.2 | AP5: 0.05 | AQ5: 0.040375 | AR5: 0.136875
A6: 12165 | B6: LYAP-X1877 | C6: =_xlfn.XLOOKUP(A6,[1]分配表!J:J,[1]分配表!L:L) -> 46085 | D6: =IF(_xlfn.XLOOKUP(A6,[1]分配表!J:J,[1]分配表!M:M)=0,"未出单",_xlfn.XLOOKUP(A6,[1]分配表!J:J,[1]分配表!M:M)) -> 46093 | E6: 朱培源 | F6: =_xlfn.XLOOKUP(A6,[1]分配表!A:A,[1]分配表!C:C) -> 朱培源 | G6: =IF(_xlfn.XLOOKUP($A6,[1]分配表!$A:$A,[1]分配表!D:D)=0,"未分类",_xlfn.XLOOKUP($A6,[1]分配表!$A:$A,[1]分配表!D:D)) -> 挡泥板 | H6: =_xlfn.XLOOKUP(A6,[1]分配表!J:J,[1]分配表!I:I) -> 原开品 | I6: =COUNTIFS([1]月销售数据!L:L,A6,[1]月销售数据!M:M,">=2026-4-1",[1]月销售数据!M:M,"<=2026-4-30") -> 3 | J6: =COUNTIFS([1]月销售数据!L:L,A6,[1]月销售数据!M:M,">=2026-5-1",[1]月销售数据!M:M,"<=2026-5-31") -> 3 | K6: Y | L6: Y | M6: 竞争无优势 | N6: 竞争无优势 | O6: 3 | P6: 3 | Q6: 507 | R6: 510 | S6: 14 | T6: 7 | U6: 17 | V6: =T6+P6 -> 10 | W6: 0.17647059 | X6: 0.3 | Y6: 0 | Z6: 0 | AA6: 0 | AB6: #DIV/0! | AC6: 0 | AD6: 0 | AE6: 0 | AF6: 0 | AG6: #DIV/0! | AH6: 0 | AI6: 27.21 | AJ6: 544.18 | AK6: 0.050001838 | AL6: 0.053668639 | AM6: 0.055621302 | AN6: 28.64 | AO6: 717.2 | AP6: 0.039933073 | AQ6: 0.056156863 | AR6: 0.063098039
A7: 12247 | B7: LYAP-X2528 | C7: =_xlfn.XLOOKUP(A7,[1]分配表!J:J,[1]分配表!L:L) -> 46085 | D7: =IF(_xlfn.XLOOKUP(A7,[1]分配表!J:J,[1]分配表!M:M)=0,"未出单",_xlfn.XLOOKUP(A7,[1]分配表!J:J,[1]分配表!M:M)) -> 46089 | E7: 胡煜星 | F7: =_xlfn.XLOOKUP(A7,[1]分配表!A:A,[1]分配表!C:C) -> 胡煜星 | G7: =IF(_xlfn.XLOOKUP($A7,[1]分配表!$A:$A,[1]分配表!D:D)=0,"未分类",_xlfn.XLOOKUP($A7,[1]分配表!$A:$A,[1]分配表!D:D)) -> 其他 | H7: =_xlfn.XLOOKUP(A7,[1]分配表!J:J,[1]分配表!I:I) -> 原开品 | I7: =COUNTIFS([1]月销售数据!L:L,A7,[1]月销售数据!M:M,">=2026-4-1",[1]月销售数据!M:M,"<=2026-4-30") -> 2 | J7: =COUNTIFS([1]月销售数据!L:L,A7,[1]月销售数据!M:M,">=2026-5-1",[1]月销售数据!M:M,"<=2026-5-31") -> 1 | K7: Y | L7: Y | M7: 正常 | N7: 正常 | O7: 17 | P7: 21 | Q7: 1556.53 | R7: 2089.5 | S7: 0 | T7: 0 | U7: 17 | V7: =T7+P7 -> 21 | W7: 1 | X7: 1 | Y7: 0 | Z7: 0 | AA7: 0 | AB7: #DIV/0! | AC7: 0 | AD7: 0 | AE7: 0 | AF7: 0 | AG7: #DIV/0! | AH7: 0 | AI7: 40.41 | AJ7: 1649.29 | AK7: 0.024501452 | AL7: 0.025961594 | AM7: 0.030953467 | AN7: 62.67 | AO7: 2088.7 | AP7: 0.030004309 | AQ7: 0.029992821 | AR7: 0.035472601
A8: 11102 | B8: LYAM-X2254-L | C8: =_xlfn.XLOOKUP(A8,[1]分配表!J:J,[1]分配表!L:L) -> 46085 | D8: =IF(_xlfn.XLOOKUP(A8,[1]分配表!J:J,[1]分配表!M:M)=0,"未出单",_xlfn.XLOOKUP(A8,[1]分配表!J:J,[1]分配表!M:M)) -> 46100 | E8: 张潇 | F8: =_xlfn.XLOOKUP(A8,[1]分配表!A:A,[1]分配表!C:C) -> 张潇 | G8: =IF(_xlfn.XLOOKUP($A8,[1]分配表!$A:$A,[1]分配表!D:D)=0,"未分类",_xlfn.XLOOKUP($A8,[1]分配表!$A:$A,[1]分配表!D:D)) -> 车门系统 | H8: =_xlfn.XLOOKUP(A8,[1]分配表!J:J,[1]分配表!I:I) -> 原开品 | I8: =COUNTIFS([1]月销售数据!L:L,A8,[1]月销售数据!M:M,">=2026-4-1",[1]月销售数据!M:M,"<=2026-4-30") -> 4 | J8: =COUNTIFS([1]月销售数据!L:L,A8,[1]月销售数据!M:M,">=2026-5-1",[1]月销售数据!M:M,"<=2026-5-31") -> 3 | K8: N | L8: N | M8: 竞争无优势 | N8: 竞争无优势 | O8: 10 | P8: 16 | Q8: 300.95 | R8: 448.96 | S8: 7 | T8: 12 | U8: 17 | V8: =T8+P8 -> 28 | W8: 0.58823529 | X8: 0.57142857 | Y8: 6 | Z8: 200.2 | AA8: 21.5 | AB8: 0.10739261 | AC8: 0.071440439 | AD8: 9 | AE8: 286.96 | AF8: 18.59 | AG8: 0.064782548 | AH8: 0.041406807 | AI8: 6.04 | AJ8: 201.47 | AK8: 0.02997965 | AL8: 0.020069779 | AM8: 0.099052999 | AN8: 0 | AO8: 0 | AP8: #DIV/0! | AQ8: 0 | AR8: 0.066732003
A9: 12071 | B9: LYAM-X2980-BK | C9: =_xlfn.XLOOKUP(A9,[1]分配表!J:J,[1]分配表!L:L) -> 46085 | D9: =IF(_xlfn.XLOOKUP(A9,[1]分配表!J:J,[1]分配表!M:M)=0,"未出单",_xlfn.XLOOKUP(A9,[1]分配表!J:J,[1]分配表!M:M)) -> 46092 | E9: 胡煜星 | F9: =_xlfn.XLOOKUP(A9,[1]分配表!A:A,[1]分配表!C:C) -> 胡煜星 | G9: =IF(_xlfn.XLOOKUP($A9,[1]分配表!$A:$A,[1]分配表!D:D)=0,"未分类",_xlfn.XLOOKUP($A9,[1]分配表!$A:$A,[1]分配表!D:D)) -> 车身外扩件 | H9: =_xlfn.XLOOKUP(A9,[1]分配表!J:J,[1]分配表!I:I) -> 拓展品 | I9: =COUNTIFS([1]月销售数据!L:L,A9,[1]月销售数据!M:M,">=2026-4-1",[1]月销售数据!M:M,"<=2026-4-30") -> 1 | J9: =COUNTIFS([1]月销售数据!L:L,A9,[1]月销售数据!M:M,">=2026-5-1",[1]月销售数据!M:M,"<=2026-5-31") -> 1 | K9: Y | L9: Y | M9: 竞争无优势 | N9: 无市场 | O9: 4 | P9: 5 | Q9: 1196 | R9: 1480.05 | S9: 1 | T9: 1 | U9: 5 | V9: =T9+P9 -> 6 | W9: 0.8 | X9: 0.83333333 | Y9: 0 | Z9: 0 | AA9: 0 | AB9: #DIV/0! | AC9: 0 | AD9: 0 | AE9: 0 | AF9: 0 | AG9: #DIV/0! | AH9: 0 | AI9: 19.14 | AJ9: 956.73 | AK9: 0.020005644 | AL9: 0.016003344 | AM9: 0.019498328 | AN9: 18.76 | AO9: 937.96 | AP9: 0.020000853 | AQ9: 0.012675247 | AR9: 0.018046688
A10: 12072 | B10: LYAM-X2980-GR | C10: =_xlfn.XLOOKUP(A10,[1]分配表!J:J,[1]分配表!L:L) -> 46085 | D10: =IF(_xlfn.XLOOKUP(A10,[1]分配表!J:J,[1]分配表!M:M)=0,"未出单",_xlfn.XLOOKUP(A10,[1]分配表!J:J,[1]分配表!M:M)) -> 46112 | E10: 胡煜星 | F10: =_xlfn.XLOOKUP(A10,[1]分配表!A:A,[1]分配表!C:C) -> 胡煜星 | G10: =IF(_xlfn.XLOOKUP($A10,[1]分配表!$A:$A,[1]分配表!D:D)=0,"未分类",_xlfn.XLOOKUP($A10,[1]分配表!$A:$A,[1]分配表!D:D)) -> 车身外扩件 | H10: =_xlfn.XLOOKUP(A10,[1]分配表!J:J,[1]分配表!I:I) -> 原开品 | I10: =COUNTIFS([1]月销售数据!L:L,A10,[1]月销售数据!M:M,">=2026-4-1",[1]月销售数据!M:M,"<=2026-4-30") -> 1 | J10: =COUNTIFS([1]月销售数据!L:L,A10,[1]月销售数据!M:M,">=2026-5-1",[1]月销售数据!M:M,"<=2026-5-31") -> 1 | K10: N | L10: N | M10: 正常 | N10: 无市场 | O10: 3 | P10: 2 | Q10: 897 | R10: 598 | S10: 0 | T10: 0 | U10: 3 | V10: =T10+P10 -> 2 | W10: 1 | X10: 1 | Y10: 0 | Z10: 0 | AA10: 0 | AB10: #DIV/0! | AC10: 0 | AD10: 0 | AE10: 0 | AF10: 0 | AG10: #DIV/0! | AH10: 0 | AI10: 18.92 | AJ10: 945.96 | AK10: 0.020000846 | AL10: 0.021092531 | AM10: 0.02425864 | AN10: 0 | AO10: 0 | AP10: #DIV/0! | AQ10: 0 | AR10: 0.0053846154
A11: 12248 | B11: LYAP-X2308 | C11: =_xlfn.XLOOKUP(A11,[1]分配表!J:J,[1]分配表!L:L) -> 46085 | D11: =IF(_xlfn.XLOOKUP(A11,[1]分配表!J:J,[1]分配表!M:M)=0,"未出单",_xlfn.XLOOKUP(A11,[1]分配表!J:J,[1]分配表!M:M)) -> 46091 | E11: 胡煜星 | F11: =_xlfn.XLOOKUP(A11,[1]分配表!A:A,[1]分配表!C:C) -> 胡煜星 | G11: =IF(_xlfn.XLOOKUP($A11,[1]分配表!$A:$A,[1]分配表!D:D)=0,"未分类",_xlfn.XLOOKUP($A11,[1]分配表!$A:$A,[1]分配表!D:D)) -> 其他 | H11: =_xlfn.XLOOKUP(A11,[1]分配表!J:J,[1]分配表!I:I) -> 原开品 | I11: =COUNTIFS([1]月销售数据!L:L,A11,[1]月销售数据!M:M,">=2026-4-1",[1]月销售数据!M:M,"<=2026-4-30") -> 2 | J11: =COUNTIFS([1]月销售数据!L:L,A11,[1]月销售数据!M:M,">=2026-5-1",[1]月销售数据!M:M,"<=2026-5-31") -> 2 | K11: Y | L11: Y | M11: 竞争无优势 | N11: 竞争无优势 | O11: 19 | P11: 17 | Q11: 1622 | R11: 1454 | S11: 9 | T11: 11 | U11: 28 | V11: =T11+P11 -> 28 | W11: 0.67857143 | X11: 0.60714286 | Y11: 3 | Z11: 260.1 | AA11: 24.54 | AB11: 0.094348328 | AC11: 0.01512947 | AD11: 0 | AE11: 0 | AF11: 0 | AG11: #DIV/0! | AH11: 0 | AI11: 41.76 | AJ11: 1725.73 | AK11: 0.024198455 | AL11: 0.025745993 | AM11: 0.04662762 | AN11: 52.74 | AO11: 1636.79 | AP11: 0.032221604 | AQ11: 0.036272352 | AR11: 0.040687758
A12: 12246 | B12: LYAP-X2527 | C12: =_xlfn.XLOOKUP(A12,[1]分配表!J:J,[1]分配表!L:L) -> 46085 | D12: =IF(_xlfn.XLOOKUP(A12,[1]分配表!J:J,[1]分配表!M:M)=0,"未出单",_xlfn.XLOOKUP(A12,[1]分配表!J:J,[1]分配表!M:M)) -> 46086 | E12: 胡煜星 | F12: =_xlfn.XLOOKUP(A12,[1]分配表!A:A,[1]分配表!C:C) -> 胡煜星 | G12: =IF(_xlfn.XLOOKUP($A12,[1]分配表!$A:$A,[1]分配表!D:D)=0,"未分类",_xlfn.XLOOKUP($A12,[1]分配表!$A:$A,[1]分配表!D:D)) -> 其他 | H12: =_xlfn.XLOOKUP(A12,[1]分配表!J:J,[1]分配表!I:I) -> 原开品 | I12: =COUNTIFS([1]月销售数据!L:L,A12,[1]月销售数据!M:M,">=2026-4-1",[1]月销售数据!M:M,"<=2026-4-30") -> 3 | J12: =COUNTIFS([1]月销售数据!L:L,A12,[1]月销售数据!M:M,">=2026-5-1",[1]月销售数据!M:M,"<=2026-5-31") -> 4 | K12: Y | L12: Y | M12: 正常 | N12: 正常 | O12: 48 | P12: 36 | Q12: 4153.75 | R12: 3323 | S12: 0 | T12: 2 | U12: 48 | V12: =T12+P12 -> 38 | W12: 1 | X12: 0.94736842 | Y12: 10 | Z12: 923.47 | AA12: 69.28 | AB12: 0.075021387 | AC12: 0.016678905 | AD12: 6 | AE12: 579.93 | AF12: 32.63 | AG12: 0.056265411 | AH12: 0.0098194403 | AI12: 42.01 | AJ12: 2100.56 | AK12: 0.019999429 | AL12: 0.010113753 | AM12: 0.030815528 | AN12: 16.87 | AO12: 559.71 | AP12: 0.030140609 | AQ12: 0.0050767379 | AR12: 0.019226602
A13: 12205 | B13: LYAP-X1800-1L | C13: =_xlfn.XLOOKUP(A13,[1]分配表!J:J,[1]分配表!L:L) -> 46086 | D13: =IF(_xlfn.XLOOKUP(A13,[1]分配表!J:J,[1]分配表!M:M)=0,"未出单",_xlfn.XLOOKUP(A13,[1]分配表!J:J,[1]分配表!M:M)) -> 46089 | E13: 胡煜星 | F13: =_xlfn.XLOOKUP(A13,[1]分配表!A:A,[1]分配表!C:C) -> 胡煜星 | G13: =IF(_xlfn.XLOOKUP($A13,[1]分配表!$A:$A,[1]分配表!D:D)=0,"未分类",_xlfn.XLOOKUP($A13,[1]分配表!$A:$A,[1]分配表!D:D)) -> 车门系统 | H13: =_xlfn.XLOOKUP(A13,[1]分配表!J:J,[1]分配表!I:I) -> 原开品 | I13: =COUNTIFS([1]月销售数据!L:L,A13,[1]月销售数据!M:M,">=2026-4-1",[1]月销售数据!M:M,"<=2026-4-30") -> 5 | J13: =COUNTIFS([1]月销售数据!L:L,A13,[1]月销售数据!M:M,">=2026-5-1",[1]月销售数据!M:M,"<=2026-5-31") -> 4 | K13: Y | L13: Y | M13: 竞争无优势 | N13: 竞争无优势 | O13: 33 | P13: 19 | Q13: 726 | R13: 417.36 | S13: 85 | T13: 58 | U13: 118 | V13: =T13+P13 -> 77 | W13: 0.27966102 | X13: 0.24675325 | Y13: 2 | Z13: 47.3 | AA13: 1.18 | AB13: 0.024947146 | AC13: 0.0016253444 | AD13: 3 | AE13: 72.56 | AF13: 5.28 | AG13: 0.072767365 | AH13: 0.012650949 | AI13: 51.02 | AJ13: 782.16 | AK13: 0.065229621 | AL13: 0.070275482 | AM13: 0.086253444 | AN13: 26.58 | AO13: 448.77 | AP13: 0.059228558 | AQ13: 0.063686026 | AR13: 0.089970289
A14: 12206 | B14: LYAP-X1800-1R | C14: =_xlfn.XLOOKUP(A14,[1]分配表!J:J,[1]分配表!L:L) -> 46086 | D14: =IF(_xlfn.XLOOKUP(A14,[1]分配表!J:J,[1]分配表!M:M)=0,"未出单",_xlfn.XLOOKUP(A14,[1]分配表!J:J,[1]分配表!M:M)) -> 46094 | E14: 胡煜星 | F14: =_xlfn.XLOOKUP(A14,[1]分配表!A:A,[1]分配表!C:C) -> 胡煜星 | G14: =IF(_xlfn.XLOOKUP($A14,[1]分配表!$A:$A,[1]分配表!D:D)=0,"未分类",_xlfn.XLOOKUP($A14,[1]分配表!$A:$A,[1]分配表!D:D)) -> 车门系统 | H14: =_xlfn.XLOOKUP(A14,[1]分配表!J:J,[1]分配表!I:I) -> 原开品 | I14: =COUNTIFS([1]月销售数据!L:L,A14,[1]月销售数据!M:M,">=2026-4-1",[1]月销售数据!M:M,"<=2026-4-30") -> 3 | J14: =COUNTIFS([1]月销售数据!L:L,A14,[1]月销售数据!M:M,">=2026-5-1",[1]月销售数据!M:M,"<=2026-5-31") -> 2 | K14: Y | L14: Y | M14: 竞争无优势 | N14: 竞争无优势 | O14: 4 | P14: 8 | Q14: 88 | R14: 176 | S14: 10 | T14: 18 | U14: 14 | V14: =T14+P14 -> 26 | W14: 0.28571429 | X14: 0.30769231 | Y14: 0 | Z14: 0 | AA14: 0 | AB14: #DIV/0! | AC14: 0 | AD14: 1 | AE14: 23.87 | AF14: 2.04 | AG14: 0.085462924 | AH14: 0.011590909 | AI14: 3.29 | AJ14: 46.98 | AK14: 0.0700298 | AL14: 0.037386364 | AM14: 0.045909091 | AN14: 8.33 | AO14: 190.72 | AP14: 0.043676594 | AQ14: 0.047329545 | AR14: 0.064375
A15: 11997 | B15: LYAM-X2896 | C15: =_xlfn.XLOOKUP(A15,[1]分配表!J:J,[1]分配表!L:L) -> 46091 | D15: =IF(_xlfn.XLOOKUP(A15,[1]分配表!J:J,[1]分配表!M:M)=0,"未出单",_xlfn.XLOOKUP(A15,[1]分配表!J:J,[1]分配表!M:M)) -> 46105 | E15: 张潇 | F15: =_xlfn.XLOOKUP(A15,[1]分配表!A:A,[1]分配表!C:C) -> 张潇 | G15: =IF(_xlfn.XLOOKUP($A15,[1]分配表!$A:$A,[1]分配表!D:D)=0,"未分类",_xlfn.XLOOKUP($A15,[1]分配表!$A:$A,[1]分配表!D:D)) -> 饰条 | H15: =_xlfn.XLOOKUP(A15,[1]分配表!J:J,[1]分配表!I:I) -> 原开品 | I15: =COUNTIFS([1]月销售数据!L:L,A15,[1]月销售数据!M:M,">=2026-4-1",[1]月销售数据!M:M,"<=2026-4-30") -> 4 | J15: =COUNTIFS([1]月销售数据!L:L,A15,[1]月销售数据!M:M,">=2026-5-1",[1]月销售数据!M:M,"<=2026-5-31") -> 0 | K15: N | L15: N | M15: 正常 | N15: 正常 | O15: 7 | P15: 6 | Q15: 966.05 | R15: 827.05 | S15: 1 | T15: 0 | U15: 8 | V15: =T15+P15 -> 6 | W15: 0.875 | X15: 1 | Y15: 0 | Z15: 0 | AA15: 0.66 | AB15: #DIV/0! | AC15: 0.00068319445 | AD15: 0 | AE15: 0 | AF15: 0 | AG15: #DIV/0! | AH15: 0 | AI15: 20.57 | AJ15: 1029.17 | AK15: 0.01998698 | AL15: 0.021292894 | AM15: 0.022286631 | AN15: 17.51 | AO15: 875.86 | AP15: 0.01999178 | AQ15: 0.021171634 | AR15: 0.022042198
A16: 12262 | B16: LYAP-X2170 | C16: =_xlfn.XLOOKUP(A16,[1]分配表!J:J,[1]分配表!L:L) -> 46091 | D16: =IF(_xlfn.XLOOKUP(A16,[1]分配表!J:J,[1]分配表!M:M)=0,"未出单",_xlfn.XLOOKUP(A16,[1]分配表!J:J,[1]分配表!M:M)) -> 46094 | E16: 张潇 | F16: =_xlfn.XLOOKUP(A16,[1]分配表!A:A,[1]分配表!C:C) -> 张潇 | G16: =IF(_xlfn.XLOOKUP($A16,[1]分配表!$A:$A,[1]分配表!D:D)=0,"未分类",_xlfn.XLOOKUP($A16,[1]分配表!$A:$A,[1]分配表!D:D)) -> 机盖及附件 | H16: =_xlfn.XLOOKUP(A16,[1]分配表!J:J,[1]分配表!I:I) -> 原开品 | I16: =COUNTIFS([1]月销售数据!L:L,A16,[1]月销售数据!M:M,">=2026-4-1",[1]月销售数据!M:M,"<=2026-4-30") -> 1 | J16: =COUNTIFS([1]月销售数据!L:L,A16,[1]月销售数据!M:M,">=2026-5-1",[1]月销售数据!M:M,"<=2026-5-31") -> 0 | K16: Y | L16: Y | M16: 无市场 | N16: 竞争无优势 | O16: 4 | P16: 3 | Q16: 568 | R16: 426 | S16: 1 | T16: 2 | U16: 5 | V16: =T16+P16 -> 5 | W16: 0.8 | X16: 0.6 | Y16: 0 | Z16: 0 | AA16: 0 | AB16: #DIV/0! | AC16: 0 | AD16: 0 | AE16: 0 | AF16: 0 | AG16: #DIV/0! | AH16: 0 | AI16: 11.95 | AJ16: 597.32 | AK16: 0.020006027 | AL16: 0.021038732 | AM16: 0.02278169 | AN16: 9.07 | AO16: 453.34 | AP16: 0.020007059 | AQ16: 0.02129108 | AR16: 0.024624413
A17: 12244 | B17: LYAP-X2190-L | C17: =_xlfn.XLOOKUP(A17,[1]分配表!J:J,[1]分配表!L:L) -> 46091 | D17: =IF(_xlfn.XLOOKUP(A17,[1]分配表!J:J,[1]分配表!M:M)=0,"未出单",_xlfn.XLOOKUP(A17,[1]分配表!J:J,[1]分配表!M:M)) -> 46101 | E17: 张潇 | F17: =_xlfn.XLOOKUP(A17,[1]分配表!A:A,[1]分配表!C:C) -> 张潇 | G17: =IF(_xlfn.XLOOKUP($A17,[1]分配表!$A:$A,[1]分配表!D:D)=0,"未分类",_xlfn.XLOOKUP($A17,[1]分配表!$A:$A,[1]分配表!D:D)) -> 饰条 | H17: =_xlfn.XLOOKUP(A17,[1]分配表!J:J,[1]分配表!I:I) -> 原开品 | I17: =COUNTIFS([1]月销售数据!L:L,A17,[1]月销售数据!M:M,">=2026-4-1",[1]月销售数据!M:M,"<=2026-4-30") -> 4 | J17: =COUNTIFS([1]月销售数据!L:L,A17,[1]月销售数据!M:M,">=2026-5-1",[1]月销售数据!M:M,"<=2026-5-31") -> 4 | K17: N | L17: N | M17: 无市场 | N17: 竞争无优势 | O17: 5 | P17: 1 | Q17: 190 | R17: 38 | S17: 1 | T17: 3 | U17: 6 | V17: =T17+P17 -> 4 | W17: 0.83333333 | X17: 0.25 | Y17: 5 | Z17: 208.11 | AA17: 7.57 | AB17: 0.036374994 | AC17: 0.039842105 | AD17: 1 | AE17: 40.52 | AF17: 3.91 | AG17: 0.096495558 | AH17: 0.10289474 | AI17: 5 | AJ17: 249.63 | AK17: 0.020029644 | AL17: 0.026315789 | AM17: 0.071210526 | AN17: 0 | AO17: 0 | AP17: #DIV/0! | AQ17: 0 | AR17: 0.14605263
A18: 12243 | B18: LYAP-X2190-R | C18: =_xlfn.XLOOKUP(A18,[1]分配表!J:J,[1]分配表!L:L) -> 46091 | D18: =IF(_xlfn.XLOOKUP(A18,[1]分配表!J:J,[1]分配表!M:M)=0,"未出单",_xlfn.XLOOKUP(A18,[1]分配表!J:J,[1]分配表!M:M)) -> 46106 | E18: 张潇 | F18: =_xlfn.XLOOKUP(A18,[1]分配表!A:A,[1]分配表!C:C) -> 张潇 | G18: =IF(_xlfn.XLOOKUP($A18,[1]分配表!$A:$A,[1]分配表!D:D)=0,"未分类",_xlfn.XLOOKUP($A18,[1]分配表!$A:$A,[1]分配表!D:D)) -> 饰条 | H18: =_xlfn.XLOOKUP(A18,[1]分配表!J:J,[1]分配表!I:I) -> 原开品 | I18: =COUNTIFS([1]月销售数据!L:L,A18,[1]月销售数据!M:M,">=2026-4-1",[1]月销售数据!M:M,"<=2026-4-30") -> 4 | J18: =COUNTIFS([1]月销售数据!L:L,A18,[1]月销售数据!M:M,">=2026-5-1",[1]月销售数据!M:M,"<=2026-5-31") -> 3 | K18: N | L18: N | M18: 竞争无优势 | N18: 竞争无优势 | O18: 4 | P18: 7 | Q18: 152 | R18: 261.82 | S18: 6 | T18: 4 | U18: 10 | V18: =T18+P18 -> 11 | W18: 0.4 | X18: 0.63636364 | Y18: 4 | Z18: 164.69 | AA18: 17.84 | AB18: 0.10832473 | AC18: 0.11736842 | AD18: 5 | AE18: 199.94 | AF18: 6.11 | AG18: 0.030559168 | AH18: 0.023336643 | AI18: 1.65 | AJ18: 82.09 | AK18: 0.02009989 | AL18: 0.010855263 | AM18: 0.12822368 | AN18: 0.77 | AO18: 38.36 | AP18: 0.020072993 | AQ18: 0.0029409518 | AR18: 0.027041479
A19: 12304 | B19: LYAP-X1642-GR | C19: =_xlfn.XLOOKUP(A19,[1]分配表!J:J,[1]分配表!L:L) -> 46092 | D19: =IF(_xlfn.XLOOKUP(A19,[1]分配表!J:J,[1]分配表!M:M)=0,"未出单",_xlfn.XLOOKUP(A19,[1]分配表!J:J,[1]分配表!M:M)) -> 46095 | E19: 俞东旭 | F19: =_xlfn.XLOOKUP(A19,[1]分配表!A:A,[1]分配表!C:C) -> 俞东旭 | G19: =IF(_xlfn.XLOOKUP($A19,[1]分配表!$A:$A,[1]分配表!D:D)=0,"未分类",_xlfn.XLOOKUP($A19,[1]分配表!$A:$A,[1]分配表!D:D)) -> 车门系统 | H19: =_xlfn.XLOOKUP(A19,[1]分配表!J:J,[1]分配表!I:I) -> 原开品 | I19: =COUNTIFS([1]月销售数据!L:L,A19,[1]月销售数据!M:M,">=2026-4-1",[1]月销售数据!M:M,"<=2026-4-30") -> 2 | J19: =COUNTIFS([1]月销售数据!L:L,A19,[1]月销售数据!M:M,">=2026-5-1",[1]月销售数据!M:M,"<=2026-5-31") -> 1 | K19: Y | L19: Y | M19: 正常 | N19: 正常 | O19: 3 | P19: 3 | Q19: 1497 | R19: 1472.05 | S19: 4 | T19: 1 | U19: 7 | V19: =T19+P19 -> 4 | W19: 0.42857143 | X19: 0.75 | Y19: 0 | Z19: 0 | AA19: 0 | AB19: #DIV/0! | AC19: 0 | AD19: 0 | AE19: 0 | AF19: 0 | AG19: #DIV/0! | AH19: 0 | AI19: 32.52 | AJ19: 1625.99 | AK19: 0.020000123 | AL19: 0.021723447 | AM19: 0.022150969 | AN19: 31.89 | AO19: 1594.37 | AP19: 0.020001631 | AQ19: 0.021663666 | AR19: 0.022125607
A20: 12085 | B20: LYAP-X1911-BK | C20: =_xlfn.XLOOKUP(A20,[1]分配表!J:J,[1]分配表!L:L) -> 46092 | D20: =IF(_xlfn.XLOOKUP(A20,[1]分配表!J:J,[1]分配表!M:M)=0,"未出单",_xlfn.XLOOKUP(A20,[1]分配表!J:J,[1]分配表!M:M)) -> 46099 | E20: 张潇 | F20: =_xlfn.XLOOKUP(A20,[1]分配表!A:A,[1]分配表!C:C) -> 张潇 | G20: =IF(_xlfn.XLOOKUP($A20,[1]分配表!$A:$A,[1]分配表!D:D)=0,"未分类",_xlfn.XLOOKUP($A20,[1]分配表!$A:$A,[1]分配表!D:D)) -> 机盖及附件 | H20: =_xlfn.XLOOKUP(A20,[1]分配表!J:J,[1]分配表!I:I) -> 拓展品 | I20: =COUNTIFS([1]月销售数据!L:L,A20,[1]月销售数据!M:M,">=2026-4-1",[1]月销售数据!M:M,"<=2026-4-30") -> 2 | J20: =COUNTIFS([1]月销售数据!L:L,A20,[1]月销售数据!M:M,">=2026-5-1",[1]月销售数据!M:M,"<=2026-5-31") -> 2 | K20: Y | L20: Y | M20: 竞争无优势 | N20: 竞争无优势 | O20: 10 | P20: 10 | Q20: 845.75 | R20: 845.75 | S20: 9 | T20: 4 | U20: 19 | V20: =T20+P20 -> 14 | W20: 0.52631579 | X20: 0.71428571 | Y20: 0 | Z20: 0 | AA20: 10.66 | AB20: #DIV/0! | AC20: 0.012604197 | AD20: 0 | AE20: 0 | AF20: 0 | AG20: #DIV/0! | AH20: 0 | AI20: 16.26 | AJ20: 813.22 | AK20: 0.019994589 | AL20: 0.019225539 | AM20: 0.031829737 | AN20: 18 | AO20: 899.99 | AP20: 0.020000222 | AQ20: 0.021282885 | AR20: 0.021590304
A21: 12086 | B21: LYAP-X1911-C | C21: =_xlfn.XLOOKUP(A21,[1]分配表!J:J,[1]分配表!L:L) -> 46092 | D21: =IF(_xlfn.XLOOKUP(A21,[1]分配表!J:J,[1]分配表!M:M)=0,"未出单",_xlfn.XLOOKUP(A21,[1]分配表!J:J,[1]分配表!M:M)) -> 46100 | E21: 张潇 | F21: =_xlfn.XLOOKUP(A21,[1]分配表!A:A,[1]分配表!C:C) -> 张潇 | G21: =IF(_xlfn.XLOOKUP($A21,[1]分配表!$A:$A,[1]分配表!D:D)=0,"未分类",_xlfn.XLOOKUP($A21,[1]分配表!$A:$A,[1]分配表!D:D)) -> 机盖及附件 | H21: =_xlfn.XLOOKUP(A21,[1]分配表!J:J,[1]分配表!I:I) -> 原开品 | I21: =COUNTIFS([1]月销售数据!L:L,A21,[1]月销售数据!M:M,">=2026-4-1",[1]月销售数据!M:M,"<=2026-4-30") -> 3 | J21: =COUNTIFS([1]月销售数据!L:L,A21,[1]月销售数据!M:M,">=2026-5-1",[1]月销售数据!M:M,"<=2026-5-31") -> 4 | K21: Y | L21: Y | M21: 竞争无优势 | N21: 竞争无优势 | O21: 17 | P21: 9 | Q21: 1271.25 | R21: 664.3 | S21: 20 | T21: 25 | U21: 37 | V21: =T21+P21 -> 34 | W21: 0.45945946 | X21: 0.26470588 | Y21: 1 | Z21: 81 | AA21: 18.25 | AB21: 0.22530864 | AC21: 0.014355949 | AD21: 1 | AE21: 77.69 | AF21: 4.03 | AG21: 0.051872828 | AH21: 0.0060665362 | AI21: 27.22 | AJ21: 1361.04 | AK21: 0.019999412 | AL21: 0.021411996 | AM21: 0.036287119 | AN21: 15.77 | AO21: 788.32 | AP21: 0.020004567 | AQ21: 0.023739274 | AR21: 0.030648803
A22: 12258 | B22: LYAP-X1927 | C22: =_xlfn.XLOOKUP(A22,[1]分配表!J:J,[1]分配表!L:L) -> 46092 | D22: =IF(_xlfn.XLOOKUP(A22,[1]分配表!J:J,[1]分配表!M:M)=0,"未出单",_xlfn.XLOOKUP(A22,[1]分配表!J:J,[1]分配表!M:M)) -> 46099 | E22: 张潇 | F22: =_xlfn.XLOOKUP(A22,[1]分配表!A:A,[1]分配表!C:C) -> 张潇 | G22: =IF(_xlfn.XLOOKUP($A22,[1]分配表!$A:$A,[1]分配表!D:D)=0,"未分类",_xlfn.XLOOKUP($A22,[1]分配表!$A:$A,[1]分配表!D:D)) -> 机盖及附件 | H22: =_xlfn.XLOOKUP(A22,[1]分配表!J:J,[1]分配表!I:I) -> 原开品 | I22: =COUNTIFS([1]月销售数据!L:L,A22,[1]月销售数据!M:M,">=2026-4-1",[1]月销售数据!M:M,"<=2026-4-30") -> 2 | J22: =COUNTIFS([1]月销售数据!L:L,A22,[1]月销售数据!M:M,">=2026-5-1",[1]月销售数据!M:M,"<=2026-5-31") -> 3 | K22: Y | L22: Y | M22: 竞争无优势 | N22: 竞争无优势 | O22: 33 | P22: 57 | Q22: 924 | R22: 1594.6 | S22: 67 | T22: 90 | U22: 100 | V22: =T22+P22 -> 147 | W22: 0.33 | X22: 0.3877551 | Y22: 0 | Z22: 0 | AA22: 0 | AB22: #DIV/0! | AC22: 0 | AD22: 12 | AE22: 360.12 | AF22: 26.36 | AG22: 0.073197823 | AH22: 0.016530791 | AI22: 18.77 | AJ22: 938.96 | AK22: 0.019990202 | AL22: 0.020313853 | AM22: 0.020313853 | AN22: 18.03 | AO22: 899.11 | AP22: 0.020053164 | AQ22: 0.011306911 | AR22: 0.028151261
A23: 12210 | B23: LYAP-X1934 | C23: =_xlfn.XLOOKUP(A23,[1]分配表!J:J,[1]分配表!L:L) -> 46092 | D23: =IF(_xlfn.XLOOKUP(A23,[1]分配表!J:J,[1]分配表!M:M)=0,"未出单",_xlfn.XLOOKUP(A23,[1]分配表!J:J,[1]分配表!M:M)) -> 46104 | E23: 张潇 | F23: =_xlfn.XLOOKUP(A23,[1]分配表!A:A,[1]分配表!C:C) -> 张潇 | G23: =IF(_xlfn.XLOOKUP($A23,[1]分配表!$A:$A,[1]分配表!D:D)=0,"未分类",_xlfn.XLOOKUP($A23,[1]分配表!$A:$A,[1]分配表!D:D)) -> 饰条 | H23: =_xlfn.XLOOKUP(A23,[1]分配表!J:J,[1]分配表!I:I) -> 原开品 | I23: =COUNTIFS([1]月销售数据!L:L,A23,[1]月销售数据!M:M,">=2026-4-1",[1]月销售数据!M:M,"<=2026-4-30") -> 6 | J23: =COUNTIFS([1]月销售数据!L:L,A23,[1]月销售数据!M:M,">=2026-5-1",[1]月销售数据!M:M,"<=2026-5-31") -> 3 | K23: N | L23: N | M23: 竞争无优势 | N23: 竞争无优势 | O23: 30 | P23: 30 | Q23: 358.16 | R23: 342.2 | S23: 102 | T23: 96 | U23: 132 | V23: =T23+P23 -> 126 | W23: 0.22727273 | X23: 0.23809524 | Y23: 21 | Z23: 270.51 | AA23: 27.82 | AB23: 0.10284278 | AC23: 0.077674782 | AD23: 19 | AE23: 231.96 | AF23: 28.26 | AG23: 0.12183135 | AH23: 0.082583285 | AI23: 7.2 | AJ23: 360.2 | AK23: 0.019988895 | AL23: 0.020102747 | AM23: 0.099006031 | AN23: 1.67 | AO23: 48.19 | AP23: 0.034654493 | AQ23: 0.004880187 | AR23: 0.087463472
A24: 12250 | B24: LYAP-X2148-1L | C24: =_xlfn.XLOOKUP(A24,[1]分配表!J:J,[1]分配表!L:L) -> 46092 | D24: =IF(_xlfn.XLOOKUP(A24,[1]分配表!J:J,[1]分配表!M:M)=0,"未出单",_xlfn.XLOOKUP(A24,[1]分配表!J:J,[1]分配表!M:M)) -> 46096 | E24: 王偲涵 | F24: =_xlfn.XLOOKUP(A24,[1]分配表!A:A,[1]分配表!C:C) -> 王偲涵 | G24: =IF(_xlfn.XLOOKUP($A24,[1]分配表!$A:$A,[1]分配表!D:D)=0,"未分类",_xlfn.XLOOKUP($A24,[1]分配表!$A:$A,[1]分配表!D:D)) -> 饰条 | H24: =_xlfn.XLOOKUP(A24,[1]分配表!J:J,[1]分配表!I:I) -> 拓展品 | I24: =COUNTIFS([1]月销售数据!L:L,A24,[1]月销售数据!M:M,">=2026-4-1",[1]月销售数据!M:M,"<=2026-4-30") -> 5 | J24: =COUNTIFS([1]月销售数据!L:L,A24,[1]月销售数据!M:M,">=2026-5-1",[1]月销售数据!M:M,"<=2026-5-31") -> 3 | K24: Y | L24: Y | M24: 站外出单 | N24: 正常 | O24: 2 | P24: 4 | Q24: 78 | R24: 141 | S24: 2 | T24: 2 | U24: 4 | V24: =T24+P24 -> 6 | W24: 0.5 | X24: 0.66666667 | Y24: 0 | Z24: 0 | AA24: 2.42 | AB24: #DIV/0! | AC24: 0.031025641 | AD24: 1 | AE24: 36.21 | AF24: 0.39 | AG24: 0.010770505 | AH24: 0.0027659574 | AI24: 0.85 | AJ24: 42.71 | AK24: 0.019901662 | AL24: 0.010897436 | AM24: 0.041923077 | AN24: 0 | AO24: 0 | AP24: #DIV/0! | AQ24: 0 | AR24: 0.0027659574
A25: 12251 | B25: LYAP-X2148-1R | C25: =_xlfn.XLOOKUP(A25,[1]分配表!J:J,[1]分配表!L:L) -> 46092 | D25: =IF(_xlfn.XLOOKUP(A25,[1]分配表!J:J,[1]分配表!M:M,"未出单")=0,"未出单",_xlfn.XLOOKUP(A25,[1]分配表!J:J,[1]分配表!M:M,"未出单")) -> 46112 | E25: 王偲涵 | F25: =_xlfn.XLOOKUP(A25,[1]分配表!A:A,[1]分配表!C:C) -> 王偲涵 | G25: =IF(_xlfn.XLOOKUP($A25,[1]分配表!$A:$A,[1]分配表!D:D)=0,"未分类",_xlfn.XLOOKUP($A25,[1]分配表!$A:$A,[1]分配表!D:D)) -> 饰条 | H25: =_xlfn.XLOOKUP(A25,[1]分配表!J:J,[1]分配表!I:I) -> 拓展品 | I25: =COUNTIFS([1]月销售数据!L:L,A25,[1]月销售数据!M:M,">=2026-4-1",[1]月销售数据!M:M,"<=2026-4-30") -> 4 | J25: =COUNTIFS([1]月销售数据!L:L,A25,[1]月销售数据!M:M,">=2026-5-1",[1]月销售数据!M:M,"<=2026-5-31") -> 5 | K25: N | L25: N | M25: 站外出单 | N25: 竞争无优势 | O25: 2 | P25: 1 | Q25: 78 | R25: 34 | S25: 1 | T25: 3 | U25: 3 | V25: =T25+P25 -> 4 | W25: 0.66666667 | X25: 0.25 | Y25: 2 | Z25: 83.95 | AA25: 3.05 | AB25: 0.036331149 | AC25: 0.039102564 | AD25: 0 | AE25: 0 | AF25: 4.76 | AG25: #DIV/0! | AH25: 0.14 | AI25: 1.67 | AJ25: 83.95 | AK25: 0.019892793 | AL25: 0.021410256 | AM25: 0.060512821 | AN25: 0.72 | AO25: 36.21 | AP25: 0.01988401 | AQ25: 0.021176471 | AR25: 0.16117647
A26: 12332 | B26: LYAP-X2289 | C26: =_xlfn.XLOOKUP(A26,[1]分配表!J:J,[1]分配表!L:L) -> 46092 | D26: =IF(_xlfn.XLOOKUP(A26,[1]分配表!J:J,[1]分配表!M:M,"未出单")=0,"未出单",_xlfn.XLOOKUP(A26,[1]分配表!J:J,[1]分配表!M:M,"未出单")) -> 46095 | E26: 张潇 | F26: =_xlfn.XLOOKUP(A26,[1]分配表!A:A,[1]分配表!C:C) -> 张潇 | G26: =IF(_xlfn.XLOOKUP($A26,[1]分配表!$A:$A,[1]分配表!D:D)=0,"未分类",_xlfn.XLOOKUP($A26,[1]分配表!$A:$A,[1]分配表!D:D)) -> 饰条 | H26: =_xlfn.XLOOKUP(A26,[1]分配表!J:J,[1]分配表!I:I) -> 原开品 | I26: =COUNTIFS([1]月销售数据!L:L,A26,[1]月销售数据!M:M,">=2026-4-1",[1]月销售数据!M:M,"<=2026-4-30") -> 2 | J26: =COUNTIFS([1]月销售数据!L:L,A26,[1]月销售数据!M:M,">=2026-5-1",[1]月销售数据!M:M,"<=2026-5-31") -> 1 | K26: Y | L26: Y | M26: 正常 | N26: 正常 | O26: 19 | P26: 14 | Q26: 2166 | R26: 1596 | S26: 5 | T26: 6 | U26: 24 | V26: =T26+P26 -> 20 | W26: 0.79166667 | X26: 0.7 | Y26: 8 | Z26: 982.46 | AA26: 47.68 | AB26: 0.048531238 | AC26: 0.022012927 | AD26: 8 | AE26: 973.25 | AF26: 24.46 | AG26: 0.025132289 | AH26: 0.015325815 | AI26: 36.43 | AJ26: 1820.65 | AK26: 0.020009337 | AL26: 0.016819021 | AM26: 0.038831948 | AN26: 9.83 | AO26: 491.49 | AP26: 0.020000407 | AQ26: 0.0061591479 | AR26: 0.021892231
A27: 12227 | B27: LYAP-X2418 | C27: =_xlfn.XLOOKUP(A27,[1]分配表!J:J,[1]分配表!L:L) -> 46092 | D27: =IF(_xlfn.XLOOKUP(A27,[1]分配表!J:J,[1]分配表!M:M,"未出单")=0,"未出单",_xlfn.XLOOKUP(A27,[1]分配表!J:J,[1]分配表!M:M,"未出单")) -> 46097 | E27: 章鹏 | F27: =_xlfn.XLOOKUP(A27,[1]分配表!A:A,[1]分配表!C:C) -> 章鹏 | G27: =IF(_xlfn.XLOOKUP($A27,[1]分配表!$A:$A,[1]分配表!D:D)=0,"未分类",_xlfn.XLOOKUP($A27,[1]分配表!$A:$A,[1]分配表!D:D)) -> 其他 | H27: =_xlfn.XLOOKUP(A27,[1]分配表!J:J,[1]分配表!I:I) -> 原开品 | I27: =COUNTIFS([1]月销售数据!L:L,A27,[1]月销售数据!M:M,">=2026-4-1",[1]月销售数据!M:M,"<=2026-4-30") -> 2 | J27: =COUNTIFS([1]月销售数据!L:L,A27,[1]月销售数据!M:M,">=2026-5-1",[1]月销售数据!M:M,"<=2026-5-31") -> 1 | K27: Y | L27: Y | M27: 竞争无优势 | N27: 正常 | O27: 11 | P27: 17 | Q27: 749 | R27: 1192.07 | S27: 5 | T27: 5 | U27: 16 | V27: =T27+P27 -> 22 | W27: 0.6875 | X27: 0.77272727 | Y27: 0 | Z27: 0 | AA27: 0 | AB27: #DIV/0! | AC27: 0 | AD27: 0 | AE27: 0 | AF27: 0 | AG27: #DIV/0! | AH27: 0 | AI27: 15.95 | AJ27: 797.16 | AK27: 0.02000853 | AL27: 0.02129506 | AM27: 0.029092123 | AN27: 25.64 | AO27: 1282.29 | AP27: 0.019995477 | AQ27: 0.021508804 | AR27: 0.026030351
A28: 12309 | B28: MD-002-FL | C28: =_xlfn.XLOOKUP(A28,[1]分配表!J:J,[1]分配表!L:L) -> 46092 | D28: =IF(_xlfn.XLOOKUP(A28,[1]分配表!J:J,[1]分配表!M:M,"未出单")=0,"未出单",_xlfn.XLOOKUP(A28,[1]分配表!J:J,[1]分配表!M:M,"未出单")) -> 46101 | E28: 俞东旭 | F28: =_xlfn.XLOOKUP(A28,[1]分配表!A:A,[1]分配表!C:C) -> 俞东旭 | G28: =IF(_xlfn.XLOOKUP($A28,[1]分配表!$A:$A,[1]分配表!D:D)=0,"未分类",_xlfn.XLOOKUP($A28,[1]分配表!$A:$A,[1]分配表!D:D)) -> 车门系统 | H28: =_xlfn.XLOOKUP(A28,[1]分配表!J:J,[1]分配表!I:I) -> 原开品 | I28: =COUNTIFS([1]月销售数据!L:L,A28,[1]月销售数据!M:M,">=2026-4-1",[1]月销售数据!M:M,"<=2026-4-30") -> 2 | J28: =COUNTIFS([1]月销售数据!L:L,A28,[1]月销售数据!M:M,">=2026-5-1",[1]月销售数据!M:M,"<=2026-5-31") -> 3 | K28: N | L28: N | M28: 竞争无优势 | N28: 竞争无优势 | O28: 3 | P28: 2 | Q28: 1440 | R28: 957 | S28: 4 | T28: 9 | U28: 7 | V28: =T28+P28 -> 11 | W28: 0.42857143 | X28: 0.18181818 | Y28: 0 | Z28: 0 | AA28: 0 | AB28: #DIV/0! | AC28: 0 | AD28: 0 | AE28: 0 | AF28: 0 | AG28: #DIV/0! | AH28: 0 | AI28: 31.27 | AJ28: 1563.6 | AK28: 0.019998721 | AL28: 0.021715278 | AM28: 0.021722222 | AN28: 20.76 | AO28: 1037.73 | AP28: 0.020005204 | AQ28: 0.02169279 | AR28: 0.02199582
A29: 12310 | B29: MD-002-FR | C29: =_xlfn.XLOOKUP(A29,[1]分配表!J:J,[1]分配表!L:L) -> 46092 | D29: =IF(_xlfn.XLOOKUP(A29,[1]分配表!J:J,[1]分配表!M:M,"未出单")=0,"未出单",_xlfn.XLOOKUP(A29,[1]分配表!J:J,[1]分配表!M:M,"未出单")) -> 46096 | E29: 俞东旭 | F29: =_xlfn.XLOOKUP(A29,[1]分配表!A:A,[1]分配表!C:C) -> 俞东旭 | G29: =IF(_xlfn.XLOOKUP($A29,[1]分配表!$A:$A,[1]分配表!D:D)=0,"未分类",_xlfn.XLOOKUP($A29,[1]分配表!$A:$A,[1]分配表!D:D)) -> 车门系统 | H29: =_xlfn.XLOOKUP(A29,[1]分配表!J:J,[1]分配表!I:I) -> 原开品 | I29: =COUNTIFS([1]月销售数据!L:L,A29,[1]月销售数据!M:M,">=2026-4-1",[1]月销售数据!M:M,"<=2026-4-30") -> 3 | J29: =COUNTIFS([1]月销售数据!L:L,A29,[1]月销售数据!M:M,">=2026-5-1",[1]月销售数据!M:M,"<=2026-5-31") -> 2 | K29: Y | L29: Y | M29: 正常 | N29: 竞争无优势 | O29: 7 | P29: 1 | Q29: 3374 | R29: 483 | S29: 2 | T29: 6 | U29: 9 | V29: =T29+P29 -> 7 | W29: 0.77777778 | X29: 0.14285714 | Y29: 0 | Z29: 0 | AA29: 0 | AB29: #DIV/0! | AC29: 0 | AD29: 0 | AE29: 0 | AF29: 0 | AG29: #DIV/0! | AH29: 0 | AI29: 85.53 | AJ29: 3518.09 | AK29: 0.024311487 | AL29: 0.025349733 | AM29: 0.025349733 | AN29: 12.8 | AO29: 511.98 | AP29: 0.025000977 | AQ29: 0.026501035 | AR29: 0.027225673
A30: 12311 | B30: MD-002-RL | C30: =_xlfn.XLOOKUP(A30,[1]分配表!J:J,[1]分配表!L:L) -> 46092 | D30: =IF(_xlfn.XLOOKUP(A30,[1]分配表!J:J,[1]分配表!M:M,"未出单")=0,"未出单",_xlfn.XLOOKUP(A30,[1]分配表!J:J,[1]分配表!M:M,"未出单")) -> 46102 | E30: 俞东旭 | F30: =_xlfn.XLOOKUP(A30,[1]分配表!A:A,[1]分配表!C:C) -> 俞东旭 | G30: =IF(_xlfn.XLOOKUP($A30,[1]分配表!$A:$A,[1]分配表!D:D)=0,"未分类",_xlfn.XLOOKUP($A30,[1]分配表!$A:$A,[1]分配表!D:D)) -> 车门系统 | H30: =_xlfn.XLOOKUP(A30,[1]分配表!J:J,[1]分配表!I:I) -> 原开品 | I30: =COUNTIFS([1]月销售数据!L:L,A30,[1]月销售数据!M:M,">=2026-4-1",[1]月销售数据!M:M,"<=2026-4-30") -> 4 | J30: =COUNTIFS([1]月销售数据!L:L,A30,[1]月销售数据!M:M,">=2026-5-1",[1]月销售数据!M:M,"<=2026-5-31") -> 3 | K30: N | L30: N | M30: 竞争无优势 | N30: 竞争无优势 | O30: 2 | P30: 2 | Q30: 960 | R30: 960 | S30: 4 | T30: 8 | U30: 6 | V30: =T30+P30 -> 10 | W30: 0.33333333 | X30: 0.2 | Y30: 0 | Z30: 0 | AA30: 0 | AB30: #DIV/0! | AC30: 0 | AD30: 0 | AE30: 0 | AF30: 0 | AG30: #DIV/0! | AH30: 0 | AI30: 20.74 | AJ30: 1036.8 | AK30: 0.020003858 | AL30: 0.021604167 | AM30: 0.021604167 | AN30: 20.89 | AO30: 1044.6 | AP30: 0.019998085 | AQ30: 0.021760417 | AR30: 0.021760417
A31: 12312 | B31: MD-002-RR | C31: =_xlfn.XLOOKUP(A31,[1]分配表!J:J,[1]分配表!L:L) -> 46092 | D31: =IF(_xlfn.XLOOKUP(A31,[1]分配表!J:J,[1]分配表!M:M,"未出单")=0,"未出单",_xlfn.XLOOKUP(A31,[1]分配表!J:J,[1]分配表!M:M,"未出单")) -> 46096 | E31: 俞东旭 | F31: =_xlfn.XLOOKUP(A31,[1]分配表!A:A,[1]分配表!C:C) -> 俞东旭 | G31: =IF(_xlfn.XLOOKUP($A31,[1]分配表!$A:$A,[1]分配表!D:D)=0,"未分类",_xlfn.XLOOKUP($A31,[1]分配表!$A:$A,[1]分配表!D:D)) -> 车门系统 | H31: =_xlfn.XLOOKUP(A31,[1]分配表!J:J,[1]分配表!I:I) -> 原开品 | I31: =COUNTIFS([1]月销售数据!L:L,A31,[1]月销售数据!M:M,">=2026-4-1",[1]月销售数据!M:M,"<=2026-4-30") -> 5 | J31: =COUNTIFS([1]月销售数据!L:L,A31,[1]月销售数据!M:M,">=2026-5-1",[1]月销售数据!M:M,"<=2026-5-31") -> 4 | K31: Y | L31: Y | M31: 竞争无优势 | N31: 无市场 | O31: 3 | P31: 3 | Q31: 1436 | R31: 1428 | S31: 7 | T31: 8 | U31: 10 | V31: =T31+P31 -> 11 | W31: 0.3 | X31: 0.27272727 | Y31: 1 | Z31: 478 | AA31: 17.86 | AB31: 0.037364017 | AC31: 0.012437326 | AD31: 2 | AE31: 1030.16 | AF31: 24.32 | AG31: 0.023607983 | AH31: 0.017030812 | AI31: 25.66 | AJ31: 1026.24 | AK31: 0.025003898 | AL31: 0.017869081 | AM31: 0.030654596 | AN31: 12.91 | AO31: 516.56 | AP31: 0.024992256 | AQ31: 0.0090406162 | AR31: 0.026491597
A32: 12441 | B32: LYAM-X2862 | C32: =_xlfn.XLOOKUP(A32,[1]分配表!J:J,[1]分配表!L:L) -> 46093 | D32: =IF(_xlfn.XLOOKUP(A32,[1]分配表!J:J,[1]分配表!M:M,"未出单")=0,"未出单",_xlfn.XLOOKUP(A32,[1]分配表!J:J,[1]分配表!M:M,"未出单")) -> 46100 | E32: 张潇 | F32: =_xlfn.XLOOKUP(A32,[1]分配表!A:A,[1]分配表!C:C) -> 张潇 | G32: =IF(_xlfn.XLOOKUP($A32,[1]分配表!$A:$A,[1]分配表!D:D)=0,"未分类",_xlfn.XLOOKUP($A32,[1]分配表!$A:$A,[1]分配表!D:D)) -> 机盖及附件 | H32: =_xlfn.XLOOKUP(A32,[1]分配表!J:J,[1]分配表!I:I) -> 原开品 | I32: =COUNTIFS([1]月销售数据!L:L,A32,[1]月销售数据!M:M,">=2026-4-1",[1]月销售数据!M:M,"<=2026-4-30") -> 2 | J32: =COUNTIFS([1]月销售数据!L:L,A32,[1]月销售数据!M:M,">=2026-5-1",[1]月销售数据!M:M,"<=2026-5-31") -> 3 | K32: Y | L32: Y | M32: 正常 | N32: 竞争无优势 | O32: 6 | P32: 3 | Q32: 838 | R32: 413 | S32: 3 | T32: 2 | U32: 9 | V32: =T32+P32 -> 5 | W32: 0.66666667 | X32: 0.6 | Y32: 2 | Z32: 299.89 | AA32: 3.5 | AB32: 0.011670946 | AC32: 0.004176611 | AD32: 2 | AE32: 303.19 | AF32: 0.7 | AG32: 0.0023087833 | AH32: 0.0016949153 | AI32: 17.84 | AJ32: 892.04 | AK32: 0.019999103 | AL32: 0.021288783 | AM32: 0.025465394 | AN32: 0 | AO32: 0 | AP32: #DIV/0! | AQ32: 0 | AR32: 0.0016949153
A33: 12271 | B33: LYAP-X1651-1L | C33: =_xlfn.XLOOKUP(A33,[1]分配表!J:J,[1]分配表!L:L) -> 46097 | D33: =IF(_xlfn.XLOOKUP(A33,[1]分配表!J:J,[1]分配表!M:M,"未出单")=0,"未出单",_xlfn.XLOOKUP(A33,[1]分配表!J:J,[1]分配表!M:M,"未出单")) -> 46098 | E33: 俞东旭 | F33: =_xlfn.XLOOKUP(A33,[1]分配表!A:A,[1]分配表!C:C) -> 俞东旭 | G33: =IF(_xlfn.XLOOKUP($A33,[1]分配表!$A:$A,[1]分配表!D:D)=0,"未分类",_xlfn.XLOOKUP($A33,[1]分配表!$A:$A,[1]分配表!D:D)) -> 车门系统 | H33: =_xlfn.XLOOKUP(A33,[1]分配表!J:J,[1]分配表!I:I) -> 原开品 | I33: =COUNTIFS([1]月销售数据!L:L,A33,[1]月销售数据!M:M,">=2026-4-1",[1]月销售数据!M:M,"<=2026-4-30") -> 2 | J33: =COUNTIFS([1]月销售数据!L:L,A33,[1]月销售数据!M:M,">=2026-5-1",[1]月销售数据!M:M,"<=2026-5-31") -> 2 | K33: Y | L33: Y | M33: 竞争无优势 | N33: 竞争无优势 | O33: 31 | P33: 8 | Q33: 9300 | R33: 2400 | S33: 2 | T33: 3 | U33: 33 | V33: =T33+P33 -> 11 | W33: 0.93939394 | X33: 0.72727273 | Y33: 0 | Z33: 0 | AA33: 0 | AB33: #DIV/0! | AC33: 0 | AD33: 0 | AE33: 0 | AF33: 0 | AG33: #DIV/0! | AH33: 0 | AI33: 206.03 | AJ33: 10298.32 | AK33: 0.020006176 | AL33: 0.022153763 | AM33: 0.022153763 | AN33: 71.44 | AO33: 3570.45 | AP33: 0.020008682 | AQ33: 0.029766667 | AR33: 0.029766667
A34: 12270 | B34: LYAP-X1651-1R | C34: =_xlfn.XLOOKUP(A34,[1]分配表!J:J,[1]分配表!L:L) -> 46097 | D34: =IF(_xlfn.XLOOKUP(A34,[1]分配表!J:J,[1]分配表!M:M,"未出单")=0,"未出单",_xlfn.XLOOKUP(A34,[1]分配表!J:J,[1]分配表!M:M,"未出单")) -> 46100 | E34: 俞东旭 | F34: =_xlfn.XLOOKUP(A34,[1]分配表!A:A,[1]分配表!C:C) -> 俞东旭 | G34: =IF(_xlfn.XLOOKUP($A34,[1]分配表!$A:$A,[1]分配表!D:D)=0,"未分类",_xlfn.XLOOKUP($A34,[1]分配表!$A:$A,[1]分配表!D:D)) -> 车门系统 | H34: =_xlfn.XLOOKUP(A34,[1]分配表!J:J,[1]分配表!I:I) -> 原开品 | I34: =COUNTIFS([1]月销售数据!L:L,A34,[1]月销售数据!M:M,">=2026-4-1",[1]月销售数据!M:M,"<=2026-4-30") -> 2 | J34: =COUNTIFS([1]月销售数据!L:L,A34,[1]月销售数据!M:M,">=2026-5-1",[1]月销售数据!M:M,"<=2026-5-31") -> 2 | K34: Y | L34: Y | M34: 站外出单 | N34: 站外出单 | O34: 3 | P34: 2 | Q34: 810 | R34: 540 | S34: 0 | T34: 0 | U34: 3 | V34: =T34+P34 -> 2 | W34: 1 | X34: 1 | Y34: 0 | Z34: 0 | AA34: 0 | AB34: #DIV/0! | AC34: 0 | AD34: 0 | AE34: 0 | AF34: 0 | AG34: #DIV/0! | AH34: 0 | AI34: 17.55 | AJ34: 876.97 | AK34: 0.020012087 | AL34: 0.021666667 | AM34: 0.030753086 | AN34: 11.71 | AO34: 585.43 | AP34: 0.020002391 | AQ34: 0.021685185 | AR34: 0.042981481
A35: 12318 | B35: LYAP-X1676 | C35: =_xlfn.XLOOKUP(A35,[1]分配表!J:J,[1]分配表!L:L) -> 46097 | D35: =IF(_xlfn.XLOOKUP(A35,[1]分配表!J:J,[1]分配表!M:M,"未出单")=0,"未出单",_xlfn.XLOOKUP(A35,[1]分配表!J:J,[1]分配表!M:M,"未出单")) -> 46103 | E35: 胡煜星 | F35: =_xlfn.XLOOKUP(A35,[1]分配表!A:A,[1]分配表!C:C) -> 胡煜星 | G35: =IF(_xlfn.XLOOKUP($A35,[1]分配表!$A:$A,[1]分配表!D:D)=0,"未分类",_xlfn.XLOOKUP($A35,[1]分配表!$A:$A,[1]分配表!D:D)) -> 车门系统 | H35: =_xlfn.XLOOKUP(A35,[1]分配表!J:J,[1]分配表!I:I) -> 原开品 | I35: =COUNTIFS([1]月销售数据!L:L,A35,[1]月销售数据!M:M,">=2026-4-1",[1]月销售数据!M:M,"<=2026-4-30") -> 4 | J35: =COUNTIFS([1]月销售数据!L:L,A35,[1]月销售数据!M:M,">=2026-5-1",[1]月销售数据!M:M,"<=2026-5-31") -> 2 | K35: Y | L35: Y | M35: 无市场 | N35: 无市场 | O35: 0 | P35: 2 | Q35: 0 | R35: 920 | S35: 0 | T35: 0 | U35: 0 | V35: =T35+P35 -> 2 | W35: 0 | X35: 1 | Y35: 0 | Z35: 0 | AA35: 44.63 | AB35: #DIV/0! | AC35: #DIV/0! | AD35: 1 | AE35: 501.86 | AF35: 6.78 | AG35: 0.013509744 | AH35: 0.0073695652 | AI35: 0 | AJ35: 0 | AK35: #DIV/0! | AL35: #DIV/0! | AM35: #DIV/0! | AN35: 0 | AO35: 0 | AP35: #DIV/0! | AQ35: 0 | AR35: 0.007923913
A36: 12320 | B36: LYAP-X2417 | C36: =_xlfn.XLOOKUP(A36,[1]分配表!J:J,[1]分配表!L:L) -> 46097 | D36: =IF(_xlfn.XLOOKUP(A36,[1]分配表!J:J,[1]分配表!M:M,"未出单")=0,"未出单",_xlfn.XLOOKUP(A36,[1]分配表!J:J,[1]分配表!M:M,"未出单")) -> 46131 | E36: 朱培源 | F36: =_xlfn.XLOOKUP(A36,[1]分配表!A:A,[1]分配表!C:C) -> 朱培源 | G36: =IF(_xlfn.XLOOKUP($A36,[1]分配表!$A:$A,[1]分配表!D:D)=0,"未分类",_xlfn.XLOOKUP($A36,[1]分配表!$A:$A,[1]分配表!D:D)) -> 挡泥板 | H36: =_xlfn.XLOOKUP(A36,[1]分配表!J:J,[1]分配表!I:I) -> 原开品 | I36: =COUNTIFS([1]月销售数据!L:L,A36,[1]月销售数据!M:M,">=2026-4-1",[1]月销售数据!M:M,"<=2026-4-30") -> 4 | J36: =COUNTIFS([1]月销售数据!L:L,A36,[1]月销售数据!M:M,">=2026-5-1",[1]月销售数据!M:M,"<=2026-5-31") -> 1 | K36: N | L36: N | M36: 无市场 | N36: 正常 | O36: 1 | P36: 3 | Q36: 75 | R36: 225 | S36: 0 | T36: 2 | U36: 1 | V36: =T36+P36 -> 5 | W36: 1 | X36: 0.6 | Y36: 0 | Z36: 0 | AA36: 0 | AB36: #DIV/0! | AC36: 0 | AD36: 0 | AE36: 0 | AF36: 0 | AG36: #DIV/0! | AH36: 0 | AI36: 3.22 | AJ36: 80.44 | AK36: 0.040029836 | AL36: 0.042933333 | AM36: 0.046933333 | AN36: 9.77 | AO36: 244.13 | AP36: 0.040019662 | AQ36: 0.043422222 | AR36: 0.045155556
A37: 12305 | B37: MD-001-FL | C37: =_xlfn.XLOOKUP(A37,[1]分配表!J:J,[1]分配表!L:L) -> 46097 | D37: =IF(_xlfn.XLOOKUP(A37,[1]分配表!J:J,[1]分配表!M:M,"未出单")=0,"未出单",_xlfn.XLOOKUP(A37,[1]分配表!J:J,[1]分配表!M:M,"未出单")) -> 46100 | E37: 俞东旭 | F37: =_xlfn.XLOOKUP(A37,[1]分配表!A:A,[1]分配表!C:C) -> 俞东旭 | G37: =IF(_xlfn.XLOOKUP($A37,[1]分配表!$A:$A,[1]分配表!D:D)=0,"未分类",_xlfn.XLOOKUP($A37,[1]分配表!$A:$A,[1]分配表!D:D)) -> 车门系统 | H37: =_xlfn.XLOOKUP(A37,[1]分配表!J:J,[1]分配表!I:I) -> 原开品 | I37: =COUNTIFS([1]月销售数据!L:L,A37,[1]月销售数据!M:M,">=2026-4-1",[1]月销售数据!M:M,"<=2026-4-30") -> 2 | J37: =COUNTIFS([1]月销售数据!L:L,A37,[1]月销售数据!M:M,">=2026-5-1",[1]月销售数据!M:M,"<=2026-5-31") -> 1 | K37: Y | L37: Y | M37: 竞争无优势 | N37: #N/A | O37: 10 | P37: 3 | Q37: 5860 | R37: 1770 | S37: 3 | T37: 10 | U37: 13 | V37: =T37+P37 -> 13 | W37: 0.76923077 | X37: 0.23076923 | Y37: 1 | Z37: 627.41 | AA37: 0 | AB37: 0 | AC37: 0 | AD37: 0 | AE37: 0 | AF37: 0 | AG37: #DIV/0! | AH37: 0 | AI37: 125.23 | AJ37: 6260.84 | AK37: 0.020002108 | AL37: 0.021370307 | AM37: 0.021419795 | AN37: 36.98 | AO37: 1848.77 | AP37: 0.020002488 | AQ37: 0.020892655 | AR37: 0.020892655
A38: 12321 | B38: LYAP-X1788-GR | C38: =_xlfn.XLOOKUP(A38,[1]分配表!J:J,[1]分配表!L:L) -> 46097 | D38: =IF(_xlfn.XLOOKUP(A38,[1]分配表!J:J,[1]分配表!M:M,"未出单")=0,"未出单",_xlfn.XLOOKUP(A38,[1]分配表!J:J,[1]分配表!M:M,"未出单")) -> 46120 | E38: 俞东旭 | F38: =_xlfn.XLOOKUP(A38,[1]分配表!A:A,[1]分配表!C:C) -> 俞东旭 | G38: =IF(_xlfn.XLOOKUP($A38,[1]分配表!$A:$A,[1]分配表!D:D)=0,"未分类",_xlfn.XLOOKUP($A38,[1]分配表!$A:$A,[1]分配表!D:D)) -> 车门系统 | H38: =_xlfn.XLOOKUP(A38,[1]分配表!J:J,[1]分配表!I:I) -> 原开品 | I38: =COUNTIFS([1]月销售数据!L:L,A38,[1]月销售数据!M:M,">=2026-4-1",[1]月销售数据!M:M,"<=2026-4-30") -> 5 | J38: =COUNTIFS([1]月销售数据!L:L,A38,[1]月销售数据!M:M,">=2026-5-1",[1]月销售数据!M:M,"<=2026-5-31") -> 3 | K38: N | L38: N | M38: 竞争无优势 | N38: 竞争无优势 | O38: 11 | P38: 21 | Q38: 394.9 | R38: 753.9 | S38: 25 | T38: 19 | U38: 36 | V38: =T38+P38 -> 40 | W38: 0.30555556 | X38: 0.525 | Y38: 0 | Z38: 0 | AA38: 0 | AB38: #DIV/0! | AC38: 0 | AD38: 0 | AE38: 0 | AF38: 0 | AG38: #DIV/0! | AH38: 0 | AI38: 15.48 | AJ38: 386.84 | AK38: 0.040016544 | AL38: 0.039199797 | AM38: 0.046746012 | AN38: 33.84 | AO38: 846.72 | AP38: 0.039965986 | AQ38: 0.04488659 | AR38: 0.052248309
A39: 12272 | B39: LYAP-X1808 | C39: =_xlfn.XLOOKUP(A39,[1]分配表!J:J,[1]分配表!L:L) -> 46097 | D39: =IF(_xlfn.XLOOKUP(A39,[1]分配表!J:J,[1]分配表!M:M,"未出单")=0,"未出单",_xlfn.XLOOKUP(A39,[1]分配表!J:J,[1]分配表!M:M,"未出单")) -> 46099 | E39: 胡煜星 | F39: =_xlfn.XLOOKUP(A39,[1]分配表!A:A,[1]分配表!C:C) -> 胡煜星 | G39: =IF(_xlfn.XLOOKUP($A39,[1]分配表!$A:$A,[1]分配表!D:D)=0,"未分类",_xlfn.XLOOKUP($A39,[1]分配表!$A:$A,[1]分配表!D:D)) -> 车门系统 | H39: =_xlfn.XLOOKUP(A39,[1]分配表!J:J,[1]分配表!I:I) -> 原开品 | I39: =COUNTIFS([1]月销售数据!L:L,A39,[1]月销售数据!M:M,">=2026-4-1",[1]月销售数据!M:M,"<=2026-4-30") -> 2 | J39: =COUNTIFS([1]月销售数据!L:L,A39,[1]月销售数据!M:M,">=2026-5-1",[1]月销售数据!M:M,"<=2026-5-31") -> 3 | K39: Y | L39: Y | M39: 正常 | N39: 正常 | O39: 23 | P39: 24 | Q39: 1557.2 | R39: 1708.5 | S39: 0 | T39: 0 | U39: 23 | V39: =T39+P39 -> 24 | W39: 1 | X39: 1 | Y39: 4 | Z39: 292.55 | AA39: 25.73 | AB39: 0.087950778 | AC39: 0.016523247 | AD39: 0 | AE39: 0 | AF39: 0 | AG39: #DIV/0! | AH39: 0 | AI39: 32.04 | AJ39: 1309.16 | AK39: 0.024473708 | AL39: 0.020575392 | AM39: 0.040444387 | AN39: 33.66 | AO39: 1683.19 | AP39: 0.019997742 | AQ39: 0.019701493 | AR39: 0.021510097
A40: 12292 | B40: LYAP-X1879 | C40: =_xlfn.XLOOKUP(A40,[1]分配表!J:J,[1]分配表!L:L) -> 46097 | D40: =IF(_xlfn.XLOOKUP(A40,[1]分配表!J:J,[1]分配表!M:M,"未出单")=0,"未出单",_xlfn.XLOOKUP(A40,[1]分配表!J:J,[1]分配表!M:M,"未出单")) -> 46100 | E40: 朱培源 | F40: =_xlfn.XLOOKUP(A40,[1]分配表!A:A,[1]分配表!C:C) -> 朱培源 | G40: =IF(_xlfn.XLOOKUP($A40,[1]分配表!$A:$A,[1]分配表!D:D)=0,"未分类",_xlfn.XLOOKUP($A40,[1]分配表!$A:$A,[1]分配表!D:D)) -> 挡泥板 | H40: =_xlfn.XLOOKUP(A40,[1]分配表!J:J,[1]分配表!I:I) -> 原开品 | I40: =COUNTIFS([1]月销售数据!L:L,A40,[1]月销售数据!M:M,">=2026-4-1",[1]月销售数据!M:M,"<=2026-4-30") -> 4 | J40: =COUNTIFS([1]月销售数据!L:L,A40,[1]月销售数据!M:M,">=2026-5-1",[1]月销售数据!M:M,"<=2026-5-31") -> 1 | K40: Y | L40: Y | M40: 站外出单 | N40: 正常 | O40: 5 | P40: 3 | Q40: 451 | R40: 267 | S40: 0 | T40: 8 | U40: 5 | V40: =T40+P40 -> 11 | W40: 1 | X40: 0.27272727 | Y40: 2 | Z40: 192.02 | AA40: 26.35 | AB40: 0.13722529 | AC40: 0.058425721 | AD40: 0 | AE40: 0 | AF40: 29.68 | AG40: #DIV/0! | AH40: 0.11116105 | AI40: 9.67 | AJ40: 483.8 | AK40: 0.019987598 | AL40: 0.021441242 | AM40: 0.081929047 | AN40: 5.56 | AO40: 278.08 | AP40: 0.019994246 | AQ40: 0.02082397 | AR40: 0.13363296
...

Sheet 新品PLP数据
A1: 统计周期 | B1: 广告活动 | C1: SKU | D1: ID | E1: 店铺 | F1: PLP开始日期 | G1: 实际上架日期 | H1: 首次出单日期 | I1: 当月分析人 | J1: 品类 | K1: 产品拓展 | L1: 广告曝光量 | M1: 广告点击量 | N1: 广告售出数 | O1: 广告花费 | P1: 广告销售额 | Q1: 总销售额 | R1: ROAS | S1: CVR | T1: CTR | U1: CPC | V1: CPA | W1: ACOS | X1: ACOAS | Y1: 是否开启PLG
A2: 5月 | B2: 总数据 | C2: 广告链接数量： | F2: 96 | J2: 总数据： | L2: 205973 | M2: 2434 | N2: 164 | O2: 1503.67 | P2: 13463.19 | Q2: 49402.6 | R2: 8.9535536 | S2: 0.0673788 | T2: 0.011817083 | U2: 0.61777732 | V2: 9.1687195 | W2: 0.1116875 | X2: 0.030437062 | Y2: 0
A3: 5月 | B3: LYAP-X1929~张潇~smart | C3: LYAP-X1929 | D3: 177997475019 | E3: gogreenbike | F3: 46114 | G3: 46108 | H3: 46114 | I3: 张潇 | J3: 机盖及附件 | K3: 原开品 | L3: 5489 | M3: 149 | N3: 20 | O3: 54.77 | P3: 761.31 | Q3: 1610 | R3: 13.900128 | S3: 0.13422819 | T3: 0.027145199 | U3: 0.36758389 | V3: 2.7385 | W3: 0.071941785 | X3: 0.034018634
A4: 5月 | B4: LYAP-X1927~张潇~smart~bike | C4: LYAP-X1927 | D4: 177947693144 | E4: gogreenbike | F4: 46162 | G4: 46092 | H4: 46099 | I4: 张潇 | J4: 机盖及附件 | K4: 原开品 | L4: 3667 | M4: 48 | N4: 11 | O4: 15.82 | P4: 329.67 | Q4: 1594.6 | R4: 20.838812 | S4: 0.22916667 | T4: 0.013089719 | U4: 0.32958333 | V4: 1.4381818 | W4: 0.047987381 | X4: 0.0099209833
A5: 5月 | B5: LYAP-X1360-1L~章鹏~smart~bike | C5: LYAP-X1360-1L | D5: 188330683250 | E5: gogreenbike | F5: 46142 | G5: 46142 | H5: 46144 | I5: 章鹏 | J5: 饰条 | K5: 拓展品 | L5: 7891 | M5: 52 | N5: 9 | O5: 16.82 | P5: 401.05 | Q5: 468.87 | R5: 23.843639 | S5: 0.17307692 | T5: 0.0065897858 | U5: 0.32346154 | V5: 1.8688889 | W5: 0.041939908 | X5: 0.035873483
A6: 5月 | B6: LYAP-X1934~张潇~smart~via | C6: LYAP-X1934 | D6: 227255580000 | E6: viautome | F6: 46104 | G6: 46092 | H6: 46104 | I6: 张潇 | J6: 饰条 | K6: 原开品 | L6: 2250 | M6: 40 | N6: 9 | O6: 12.5 | P6: 110.33 | Q6: 342.2 | R6: 8.8264 | S6: 0.225 | T6: 0.017777778 | U6: 0.3125 | V6: 1.3888889 | W6: 0.11329647 | X6: 0.036528346
A7: 5月 | B7: LYAP-X2289~张潇~smart | C7: LYAP-X2289 | D7: 177947769950 | E7: gogreenbike | F7: 46092 | G7: 46092 | H7: 46095 | I7: 张潇 | J7: 饰条 | K7: 原开品 | L7: 12650 | M7: 62 | N7: 8 | O7: 24.46 | P7: 973.25 | Q7: 1596 | R7: 39.789452 | S7: 0.12903226 | T7: 0.0049011858 | U7: 0.39451613 | V7: 3.0575 | W7: 0.025132289 | X7: 0.015325815
A8: 5月 | B8: LYAP-X1934~张潇~smart~flash | C8: LYAP-X1934 | D8: 117085059550 | E8: flashemotor | F8: 46104 | G8: 46092 | H8: 46104 | I8: 张潇 | J8: 饰条 | K8: 原开品 | L8: 2843 | M8: 39 | N8: 8 | O8: 12.42 | P8: 97.49 | Q8: 342.2 | R8: 7.8494364 | S8: 0.20512821 | T8: 0.013717904 | U8: 0.31846154 | V8: 1.5525 | W8: 0.12739768 | X8: 0.036294565
A9: 5月 | B9: LYAM-X2254-L~张潇~smart~xauto | C9: LYAM-X2254-L | D9: 287180832245 | E9: x-autoparts1 | F9: 46097 | G9: 46085 | H9: 46100 | I9: 张潇 | J9: 车门系统 | K9: 原开品 | L9: 1351 | M9: 27 | N9: 7 | O9: 10.56 | P9: 226 | Q9: 448.96 | R9: 21.401515 | S9: 0.25925926 | T9: 0.019985196 | U9: 0.39111111 | V9: 1.5085714 | W9: 0.046725664 | X9: 0.023521026
A10: 5月 | B10: LYAP-X2527~胡煜星~flash | C10: LYAP-X2527 | D10: 117072634866 | E10: flashemotor | F10: 46095 | G10: 46085 | H10: 46086 | I10: 胡煜星 | J10: 其他 | K10: 原开品 | L10: 1298 | M10: 61 | N10: 6 | O10: 25.14 | P10: 579.93 | Q10: 3323 | R10: 23.068019 | S10: 0.098360656 | T10: 0.046995378 | U10: 0.41213115 | V10: 4.19 | W10: 0.043350059 | X10: 0.0075654529
A11: 5月 | B11: LYAM-X2452-SL～胡煜星~smart | C11: LYAM-X2452-SL | D11: 188330738159 | E11: gogreenbike | F11: 46143 | G11: 46142 | H11: 46152 | I11: 王偲涵 | J11: 车身外扩件 | K11: 原开品 | L11: 4464 | M11: 82 | N11: 5 | O11: 38.28 | P11: 676.88 | Q11: 750 | R11: 17.682341 | S11: 0.06097561 | T11: 0.018369176 | U11: 0.46682927 | V11: 7.656 | W11: 0.056553599 | X11: 0.05104
A12: 5月 | B12: LYAP-X2210-C~张潇~smart | C12: LYAP-X2210-BK | D12: 117188996115 | E12: flashemotor | F12: 46148 | G12: 46151 | H12: 46153 | I12: 张潇 | J12: 机盖及附件 | K12: 拓展品 | L12: 2945 | M12: 48 | N12: 5 | O12: 34.05 | P12: 461.02 | Q12: 1023 | R12: 13.539501 | S12: 0.10416667 | T12: 0.016298812 | U12: 0.709375 | V12: 6.81 | W12: 0.073857967 | X12: 0.033284457
A13: 5月 | B13: LYAP-X2190系列~张潇~smart~bike | C13: LYAP-X2190-R | D13: 177944141581 | E13: gogreenbike | F13: 46092 | G13: 46091 | H13: 46106 | I13: 张潇 | J13: 饰条 | K13: 原开品 | L13: 2580 | M13: 18 | N13: 5 | O13: 6.11 | P13: 199.94 | Q13: 261.82 | R13: 32.723404 | S13: 0.27777778 | T13: 0.0069767442 | U13: 0.33944444 | V13: 1.222 | W13: 0.030559168 | X13: 0.023336643
A14: 5月 | B14: LYAM-X2450-SL～胡煜星 | C14: LYAM-X2450-SL | D14: 178088445830 | E14: gogreenbike | F14: 46143 | G14: 46141 | H14: 46143 | I14: 王偲涵 | J14: 车身外扩件 | K14: 原开品 | L14: 5011 | M14: 98 | N14: 4 | O14: 66.31 | P14: 539.99 | Q14: 750 | R14: 8.1434173 | S14: 0.040816327 | T14: 0.019556975 | U14: 0.67663265 | V14: 16.5775 | W14: 0.12279857 | X14: 0.088413333
... A51: 5月 | B51: LYAP-X1916系列~章鹏~bike | C51: LYAP-X1916-R | D51: 188395435756 | E51: gogreenbike | F51: 46161 | G51: 46160 | H51: 46161 | I51: 章鹏 | J51: 饰条 | K51: 原开品 | L51: 27 | M51: 6 | N51: 1 | O51: 1.9 | P51: 103.12 | Q51: 570 | R51: 54.273684 | S51: 0.16666667 | T51: 0.22222222 | U51: 0.31666667 | V51: 1.9 | W51: 0.018425136 | X51: 0.0033333333
A52: 5月 | B52: LYAP-X1879~朱培源 | C52: LYAP-X1879 | D52: 177965595242 | E52: gogreenbike | F52: 46100 | G52: 46097 | H52: 46100 | I52: 朱培源 | J52: 挡泥板 | K52: 原开品 | L52: 3570 | M52: 47 | N52: 0 | O52: 29.68 | P52: 0 | Q52: 267 | R52: 0 | S52: 0 | T52: 0.013165266 | U52: 0.63148936 | V52: #DIV/0! | W52: #DIV/0! | X52: 0.11116105
A53: 5月 | B53: LYAP-X2316~张潇~smart | C53: LYAP-X2316 | D53: 117178509718 | E53: flashemotor | F53: 46153 | G53: 46142 | H53: 46173 | I53: 张潇 | J53: 其他 | K53: 原开品 | L53: 3277 | M53: 47 | N53: 0 | O53: 23.68 | P53: 0 | Q53: 45 | R53: 0 | S53: 0 | T53: 0.014342386 | U53: 0.50382979 | V53: #DIV/0! | W53: #DIV/0! | X53: 0.52622222
A54: 5月 | B54: LYAM-X2438-BK~胡煜星~smart | C54: LYAM-X2438-BK | D54: 188405829710 | E54: gogreenbike | F54: 46163 | G54: 46163 | H54: 未出单 | I54: 朱培源 | J54: 车身外扩件 | K54: 拓展品 | L54: 2876 | M54: 44 | N54: 0 | O54: 20.35 | P54: 0 | Q54: 0 | R54: 0 | S54: 0 | T54: 0.015299026 | U54: 0.4625 | V54: #DIV/0! | W54: #DIV/0! | X54: #DIV/0!
A55: 5月 | B55: LYAP-X2473~张潇~smart | C55: LYAP-X2473 | D55: 178118198199 | E55: gogreenbike | F55: 46151 | G55: 46151 | H55: 未出单 | I55: 张潇 | J55: 其他 | K55: 原开品 | L55: 3731 | M55: 40 | N55: 0 | O55: 17.17 | P55: 0 | Q55: 0 | R55: 0 | S55: 0 | T55: 0.010720986 | U55: 0.42925 | V55: #DIV/0! | W55: #DIV/0! | X55: #DIV/0!
A56: 5月 | B56: LYAM-X2430-BK~胡煜星 | C56: LYAM-X2430-BK | D56: 178149834463 | E56: gogreenbike | F56: 46162 | G56: 46162 | H56: 46167 | I56: 王偲涵 | J56: 车身外扩件 | K56: 原开品 | L56: 2151 | M56: 40 | N56: 0 | O56: 38.26 | P56: 0 | Q56: 234 | R56: 0 | S56: 0 | T56: 0.018596002 | U56: 0.9565 | V56: #DIV/0! | W56: #DIV/0! | X56: 0.16350427
A57: 5月 | B57: LYAM-X2445~胡煜星~smart | C57: LYAM-X2445 | D57: 188402233492 | E57: gogreenbike | F57: 46162 | G57: 46162 | H57: 46171 | I57: 胡煜星 | J57: 车身外扩件 | K57: 原开品 | L57: 1588 | M57: 35 | N57: 0 | O57: 15.23 | P57: 0 | Q57: 140 | R57: 0 | S57: 0 | T57: 0.022040302 | U57: 0.43514286 | V57: #DIV/0! | W57: #DIV/0! | X57: 0.10878571
A58: 5月 | B58: LYAM-X2450-SL～胡煜星 | C58: LYAM-X2450-BK | D58: 188370908284 | E58: gogreenbike | F58: 46143 | G58: 46153 | H58: 46164 | I58: 王偲涵 | J58: 车身外扩件 | K58: 拓展品 | L58: 1142 | M58: 27 | N58: 0 | O58: 15.93 | P58: 0 | Q58: 230 | R58: 0 | S58: 0 | T58: 0.023642732 | U58: 0.59 | V58: #DIV/0! | W58: #DIV/0! | X58: 0.06926087
A59: 5月 | B59: LYAP-X1970~张潇 | C59: LYAP-X1970 | D59: 188402268126 | E59: gogreenbike | F59: 46162 | G59: 46162 | H59: 46170 | I59: 张潇 | J59: 挡泥板 | K59: 原开品 | L59: 870 | M59: 25 | N59: 0 | O59: 35.97 | P59: 0 | Q59: 211.8 | R59: 0 | S59: 0 | T59: 0.028735632 | U59: 1.4388 | V59: #DIV/0! | W59: #DIV/0! | X59: 0.16983003
A60: 5月 | B60: LYAP-X2470~胡煜星 | C60: LYAP-X2470 | D60: 178118166060 | E60: gogreenbike | F60: 46151 | G60: 46151 | H60: 46163 | I60: 胡煜星 | J60: 其他 | K60: 原开品 | L60: 101 | M60: 22 | N60: 0 | O60: 13.14 | P60: 0 | Q60: 96 | R60: 0 | S60: 0 | T60: 0.21782178 | U60: 0.59727273 | V60: #DIV/0! | W60: #DIV/0! | X60: 0.136875
A61: 5月 | B61: LYAM-X2460～胡煜星~smart | C61: LYAM-X2460 | D61: 178090479690 | E61: gogreenbike | F61: 46143 | G61: 46142 | H61: 未出单 | I61: 王偲涵 | J61: 车身外扩件 | K61: 原开品 | L61: 1098 | M61: 20 | N61: 0 | O61: 7.55 | P61: 0 | Q61: 0 | R61: 0 | S61: 0 | T61: 0.018214936 | U61: 0.3775 | V61: #DIV/0! | W61: #DIV/0! | X61: #DIV/0!
A62: 5月 | B62: LYAP-X2385~张潇 | C62: LYAP-X2385 | D62: 178088538756 | E62: gogreenbike | F62: 46142 | G62: 46141 | H62: 46153 | I62: 张潇 | J62: 其他 | K62: 原开品 | L62: 270 | M62: 20 | N62: 0 | O62: 10.06 | P62: 0 | Q62: 480 | R62: 0 | S62: 0 | T62: 0.074074074 | U62: 0.503 | V62: #DIV/0! | W62: #DIV/0! | X62: 0.020958333
A63: 5月 | B63: LYAM-X2439～胡煜星 | C63: LYAM-X2439 | D63: 188328077040 | E63: gogreenbike | F63: 46143 | G63: 46141 | H63: 46152 | I63: 王偲涵 | J63: 车身外扩件 | K63: 原开品 | L63: 892 | M63: 19 | N63: 0 | O63: 9.11 | P63: 0 | Q63: 284 | R63: 0 | S63: 0 | T63: 0.021300448 | U63: 0.47947368 | V63: #DIV/0! | W63: #DIV/0! | X63: 0.032077465
A64: 5月 | B64: LYAP-X2319~胡煜星 | C64: LYAP-X2319 | D64: 188307744865 | E64: gogreenbike | F64: 46137 | G64: 46135 | H64: 未出单 | I64: 胡煜星 | J64: 其他 | K64: 原开品 | L64: 1015 | M64: 18 | N64: 0 | O64: 14.51 | P64: 0 | Q64: 0 | R64: 0 | S64: 0 | T64: 0.01773399 | U64: 0.80611111 | V64: #DIV/0! | W64: #DIV/0! | X64: #DIV/0!
A65: 5月 | B65: LYAP-X2210-C~张潇~smart | C65: LYAP-X2210-C | D65: 117169587615 | E65: flashemotor | F65: 46148 | G65: 46140 | H65: 46142 | I65: 张潇 | J65: 机盖及附件 | K65: 原开品 | L65: 1820 | M65: 14 | N65: 0 | O65: 10.21 | P65: 0 | Q65: 712 | R65: 0 | S65: 0 | T65: 0.0076923077 | U65: 0.72928571 | V65: #DIV/0! | W65: #DIV/0! | X65: 0.014339888
A66: 5月 | B66: LYAP-X2025~ 章鹏~bike | C66: LYAP-X2025 | D66: 178118526210 | E66: gogreenbike | F66: 46151 | G66: 46151 | H66: 46160 | I66: 章鹏 | J66: 其他 | K66: 原开品 | L66: 131 | M66: 14 | N66: 0 | O66: 7.99 | P66: 0 | Q66: 109 | R66: 0 | S66: 0 | T66: 0.10687023 | U66: 0.57071429 | V66: #DIV/0! | W66: #DIV/0! | X66: 0.073302752
A67: 5月 | B67: LYAM-X2440~胡煜星 | C67: LYAM-X2440 | D67: 188402228844 | E67: gogreenbike | F67: 46162 | G67: 46162 | H67: 46164 | I67: 胡煜星 | J67: 车身外扩件 | K67: 原开品 | L67: 765 | M67: 12 | N67: 0 | O67: 6.17 | P67: 0 | Q67: 150 | R67: 0 | S67: 0 | T67: 0.015686275 | U67: 0.51416667 | V67: #DIV/0! | W67: #DIV/0! | X67: 0.041133333
A68: 5月 | B68: LYAP-X1979~胡煜星 | C68: LYAP-X1979 | D68: 188397858058 | E68: gogreenbike | F68: 46161 | G68: 46160 | H68: 46174 | I68: 朱培源 | J68: 挡泥板 | K68: 原开品 | L68: 346 | M68: 12 | N68: 0 | O68: 6.21 | P68: 0 | Q68: 0 | R68: 0 | S68: 0 | T68: 0.034682081 | U68: 0.5175 | V68: #DIV/0! | W68: #DIV/0! | X68: #DIV/0!
A69: 5月 | B69: LYAP-X2479~张潇~smart~flash | C69: LYAP-X2479 | D69: 117210634994 | E69: flashemotor | F69: 46167 | G69: 46163 | H69: 46174 | I69: 张潇 | J69: 车门系统 | K69: 原开品 | L69: 4280 | M69: 11 | N69: 0 | O69: 5.51 | P69: 0 | Q69: 0 | R69: 0 | S69: 0 | T69: 0.0025700935 | U69: 0.50090909 | V69: #DIV/0! | W69: #DIV/0! | X69: #DIV/0!
A70: 5月 | B70: LYAP-X1961~胡煜星 | C70: LYAP-X1961 | D70: 178149860321 | E70: gogreenbike | F70: 46169 | G70: 46162 | H70: 46169 | I70: 朱培源 | J70: 挡泥板 | K70: 原开品 | L70: 73 | M70: 11 | N70: 0 | O70: 8.13 | P70: 0 | Q70: 130 | R70: 0 | S70: 0 | T70: 0.15068493 | U70: 0.73909091 | V70: #DIV/0! | W70: #DIV/0! | X70: 0.062538462
A71: 5月 | B71: LYAM-X2452-BK～胡煜星~smart | C71: LYAM-X2452-BK | D71: 188370869619 | E71: gogreenbike | F71: 46154 | G71: 46153 | H71: 46168 | I71: 王偲涵 | J71: 车身外扩件 | K71: 拓展品 | L71: 750 | M71: 10 | N71: 0 | O71: 4.24 | P71: 0 | Q71: 100 | R71: 0 | S71: 0 | T71: 0.013333333 | U71: 0.424 | V71: #DIV/0! | W71: #DIV/0! | X71: 0.0424
A72: 5月 | B72: LYAP-X2307~胡煜星 | C72: LYAP-X2307 | D72: 178072239367 | E72: gogreenbike | F72: 46137 | G72: 46135 | H72: 46157 | I72: 胡煜星 | J72: 其他 | K72: 原开品 | L72: 1692 | M72: 9 | N72: 0 | O72: 4.66 | P72: 0 | Q72: 252 | R72: 0 | S72: 0 | T72: 0.0053191489 | U72: 0.51777778 | V72: #DIV/0! | W72: #DIV/0! | X72: 0.018492063
A73: 5月 | B73: LYAM-X2449~章鹏~bike | C73: LYAM-X2449 | D73: 178152604132 | E73: gogreenbike | F73: 46164 | G73: 46163 | H73: 未出单 | I73: 章鹏 | J73: 车身外扩件 | K73: 原开品 | L73: 1202 | M73: 9 | N73: 0 | O73: 8.74 | P73: 0 | Q73: 0 | R73: 0 | S73: 0 | T73: 0.0074875208 | U73: 0.97111111 | V73: #DIV/0! | W73: #DIV/0! | X73: #DIV/0!
A74: 5月 | B74: LYAP-385~章鹏~bike | C74: LYAP-385 | D74: 178149836206 | E74: gogreenbike | F74: 46163 | G74: 46162 | H74: 46168 | I74: 章鹏 | J74: 挡泥板 | K74: 拓展品 | L74: 406 | M74: 7 | N74: 0 | O74: 4.48 | P74: 0 | Q74: 71 | R74: 0 | S74: 0 | T74: 0.017241379 | U74: 0.64 | V74: #DIV/0! | W74: #DIV/0! | X74: 0.063098592
A75: 5月 | B75: LYAM-X2444~章鹏~bike | C75: LYAM-X2444 | D75: 178152594239 | E75: gogreenbike | F75: 46164 | G75: 46163 | H75: 未出单 | I75: 章鹏 | J75: 车身外扩件 | K75: 原开品 | L75: 174 | M75: 5 | N75: 0 | O75: 2 | P75: 0 | Q75: 0 | R75: 0 | S75: 0 | T75: 0.028735632 | U75: 0.4 | V75: #DIV/0! | W75: #DIV/0! | X75: #DIV/0!
A76: 5月 | B76: LYAP-X2310系列~胡煜星 | C76: LYAP-X2310-R | D76: 178090483656 | E76: gogreenbike | F76: 46142 | G76: 46142 | H76: 46147 | I76: 胡煜星 | J76: 其他 | K76: 拓展品 | L76: 165 | M76: 5 | N76: 0 | O76: 2.11 | P76: 0 | Q76: 130 | R76: 0 | S76: 0 | T76: 0.03030303 | U76: 0.422 | V76: #DIV/0! | W76: #DIV/0! | X76: 0.016230769
...

Sheet 过往产品销售数据
A1: 销售编号 | B1: SKU | C1: 最新上架日期 | D1: 首次出单日期 | E1: 3月分析人 | F1: 4月分析人 | G1: 5月分析人 | H1: 品类 | I1: 产品拓展 | J1: 1月销量 | K1: 2月销量 | L1: 3月销量 | M1: 4月销量 | N1: 5月销量 | O1: 1月销售额 | P1: 2月销售额 | Q1: 3月销售额 | R1: 4月销售额 | S1: 5月销售额 | T1: 1月对手出单 | U1: 2月对手出单 | V1: 3月对手出单 | W1: 4月对手出单 | X1: 5月对手出单 | Y1: 1月市占比 | Z1: 2月市占比 | AA1: 3月市占比 | AB1: 4月市占比 | AC1: 5月市占比 | AD1: 1月市容 | AE1: 2月市容 | AF1: 3月市容 | AG1: 4月市容 | AH1: 5月市容
A2: 11547 | B2: LYAM-X2815-1 | C2: 46026 | D2: 46075 | E2: 朱培源 | F2: 朱培源 | G2: 朱培源 | H2: 机盖及附件 | I2: 原开品 | J2: 0 | K2: 1 | L2: 2 | M2: 6 | N2: =_xlfn.XLOOKUP($A2,[1]月销售数据!$P:$P,[1]月销售数据!$V:$V) -> 2 | O2: 0 | P2: 59 | Q2: 118 | R2: 348 | S2: =_xlfn.XLOOKUP($A2,[1]月销售数据!$P:$P,[1]月销售数据!$AA:$AA) -> 118 | T2: 2 | U2: 1 | V2: 1 | W2: 0 | X2: 2 | Y2: 0 | Z2: 0.5 | AA2: 0.66666667 | AB2: 1 | AC2: 0.5 | AD2: 2 | AE2: 2 | AF2: =V2+L2 -> 3 | AG2: 6 | AH2: 4
A3: 11650 | B3: LYAP-X1861 | C3: 46026 | D3: 46029 | E3: 朱培源 | F3: 朱培源 | G3: 朱培源 | H3: 挡泥板 | I3: 原开品 | J3: 7 | K3: 11 | L3: 14 | M3: 14 | N3: =_xlfn.XLOOKUP(A3,[1]月销售数据!$P:$P,[1]月销售数据!$V:$V) -> 12 | O3: 1050 | P3: 1594.5 | Q3: 2100 | R3: 2064.8 | S3: =_xlfn.XLOOKUP($A3,[1]月销售数据!$P:$P,[1]月销售数据!$AA:$AA) -> 1779.8 | T3: 0 | U3: 0 | V3: 0 | W3: 0 | X3: 6 | Y3: 1 | Z3: 1 | AA3: 1 | AB3: 1 | AC3: 0.66666667 | AD3: 7 | AE3: 11 | AF3: =V3+L3 -> 14 | AG3: 14 | AH3: 18
A4: 11674 | B4: LYAP-X2057 | C4: 46026 | D4: 46028 | E4: 朱培源 | F4: 朱培源 | G4: 朱培源 | H4: 机盖及附件 | I4: 原开品 | J4: 3 | K4: 11 | L4: 16 | M4: 17 | N4: =_xlfn.XLOOKUP(A4,[1]月销售数据!$P:$P,[1]月销售数据!$V:$V) -> 6 | O4: 197.52 | P4: 741.82 | Q4: 1086.81 | R4: 1240.72 | S4: =_xlfn.XLOOKUP($A4,[1]月销售数据!$P:$P,[1]月销售数据!$AA:$AA) -> 497.36 | T4: 1 | U4: 1 | V4: 6 | W4: 6 | X4: 3 | Y4: 0.75 | Z4: 0.91666667 | AA4: 0.72727273 | AB4: 0.73913043 | AC4: 0.66666667 | AD4: 4 | AE4: 12 | AF4: =V4+L4 -> 22 | AG4: 23 | AH4: 9
A5: 11668 | B5: LYAP-X2060-1 | C5: 46026 | D5: 46030 | E5: 朱培源 | F5: 朱培源 | G5: 朱培源 | H5: 机盖及附件 | I5: 原开品 | J5: 2 | K5: 2 | L5: 7 | M5: 5 | N5: =_xlfn.XLOOKUP(A5,[1]月销售数据!$P:$P,[1]月销售数据!$V:$V) -> 5 | O5: 270 | P5: 270 | Q5: 938.25 | R5: 668.25 | S5: =_xlfn.XLOOKUP($A5,[1]月销售数据!$P:$P,[1]月销售数据!$AA:$AA) -> 675 | T5: 0 | U5: 2 | V5: 6 | W5: 4 | X5: 1 | Y5: 1 | Z5: 0.5 | AA5: 0.53846154 | AB5: 0.55555556 | AC5: 0.83333333 | AD5: 2 | AE5: 4 | AF5: =V5+L5 -> 13 | AG5: 9 | AH5: 6
A6: 11681 | B6: LYAP-X1656-1 | C6: 46027 | D6: 46031 | E6: 胡煜星 | F6: 胡煜星 | G6: 胡煜星 | H6: 车门系统 | I6: 拓展品 | J6: 1 | K6: 0 | L6: 1 | M6: 1 | N6: =_xlfn.XLOOKUP(A6,[1]月销售数据!$P:$P,[1]月销售数据!$V:$V) -> 1 | O6: 289 | P6: 0 | Q6: 350 | R6: 350 | S6: =_xlfn.XLOOKUP($A6,[1]月销售数据!$P:$P,[1]月销售数据!$AA:$AA) -> 320 | T6: 0 | U6: 0 | V6: 0 | W6: 0 | X6: 0 | Y6: 1 | Z6: 0 | AA6: 1 | AB6: 1 | AC6: 1 | AD6: 1 | AE6: 0 | AF6: =V6+L6 -> 1 | AG6: 1 | AH6: 1
A7: 11742 | B7: LYAM-X2046-R | C7: 46029 | D7: 46033 | E7: 俞东旭 | F7: 俞东旭 | G7: 俞东旭 | H7: 挡泥板 | I7: 原开品 | J7: 3 | K7: 1 | L7: 11 | M7: 13 | N7: =_xlfn.XLOOKUP(A7,[1]月销售数据!$P:$P,[1]月销售数据!$V:$V) -> 8 | O7: 387 | P7: 105 | Q7: 1243 | R7: 1430 | S7: =_xlfn.XLOOKUP($A7,[1]月销售数据!$P:$P,[1]月销售数据!$AA:$AA) -> 880 | T7: 5 | U7: 9 | V7: 1 | W7: 1 | X7: 0 | Y7: 0.375 | Z7: 0.1 | AA7: 0.91666667 | AB7: 0.92857143 | AC7: 1 | AD7: 8 | AE7: 10 | AF7: =V7+L7 -> 12 | AG7: 14 | AH7: 8
A8: 11603 | B8: LYAP-X1865-1 | C8: 46031 | D8: 46041 | E8: 朱培源 | F8: 朱培源 | G8: 朱培源 | H8: 挡泥板 | I8: 原开品 | J8: 4 | K8: 2 | L8: 7 | M8: 2 | N8: =_xlfn.XLOOKUP(A8,[1]月销售数据!$P:$P,[1]月销售数据!$V:$V) -> 1 | O8: 396 | P8: 238 | Q8: 803.44 | R8: 238 | S8: =_xlfn.XLOOKUP($A8,[1]月销售数据!$P:$P,[1]月销售数据!$AA:$AA) -> 119 | T8: 0 | U8: 0 | V8: 0 | W8: 0 | X8: 0 | Y8: 1 | Z8: 1 | AA8: 1 | AB8: 1 | AC8: 1 | AD8: 4 | AE8: 2 | AF8: =V8+L8 -> 7 | AG8: 2 | AH8: 1
