Workbook

Sheet 字段说明
A1: Sheet | B1: 字段名(列) | C1: 是否必填 | D1: 说明 | E1: 示例值 | F1: 对应React数据块
A2: 四三数据累计 | B2: 销售编号(0) | C2: 是 | D2: 唯一销售编号，整数 | E2: 12073 | F2: cum43Data[].saleNo
A3: 四三数据累计 | B3: SKU(1) | C3: 是 | D3: 产品SKU编码 | E3: LYAP-X1658 | F3: cum43Data[].SKU
A4: 四三数据累计 | B4: 上架日期(2) | C4: 是 | D4: 实际的上架日期 YYYY-MM-DD | E4: 2026-03-04 | F4: cum43Data[].listDate
A5: 四三数据累计 | B5: 首次出单日期(3) | C5: 是 | D5: 首次出单日期 YYYY-MM-DD | E5: 2026-03-12 | F5: cum43Data[].firstOrderDate
A6: 四三数据累计 | B6: 分析人(4) | C6: 是 | D6: 6人: 俞东旭/张潇/朱培源/王偲涵/章鹏/胡煜星 | E6: 俞东旭 | F6: cum43Data[].analyst
A7: 四三数据累计 | B7: 品类(5) | C7: 是 | D7: 7类: 车门系统/车身外扩件/挡泥板/机盖及附件/牌照板支架/其他/饰条 | E7: 车门系统 | F7: cum43Data[].category
A8: 四三数据累计 | B8: 拓展类型(6) | C8: 是 | D8: 原开品/拓展品/组合件 | E8: 原开品 | F8: cum43Data[].expandType
A9: 四三数据累计 | B9: 销量_本周(18) | C9: 是 | D9: 当前周销量（整数），新周追加列时改C映射 | E9: 231 | F9: cum43Data[].curSalesQty
A10: 四三数据累计 | B10: 对手销量_本周(44) | C10: 是 | D10: 截止上日的对手总销量 | E10: 5 | F10: cum43Data[].curRivalQty
A11: 四三数据累计 | B11: 市占比_本周(56) | C11: 是 | E11: 48.2 | F11: cum43Data[].curMarketShare
A12: 四三数据累计 | B12: 8日出单_本周(80) | C12: 是 | D12: Y=8日内出单, N=8日外出单, 空=未出单 | E12: Y | F12: cum43Data[].cur8dStatus
A13: 四三数据累计 | B13: 市场状态_本周(117) | C13: 是 | D13: 正常/竞争无优势/无市场/站外出单 | E13: 正常 | F13: cum43Data[].curMarketStatus
A14: 四三数据累计 | B14: 运作判断_本周(129) | C14: 否 | D14: 运作状态文字判断 | E14: 无异常 | F14: cum43Data[].curOperation
A15: 四三数据累计 | B15: PLP开启(136) | C15: 否 | D15: 本周是否开启PLP广告 Y/N | E15: N | F15: cum43Data[].plpEnabled
A16: 四三数据累计 | B16: PLG费率(144) | C16: 否 | D16: PLG最高费率 百分比字符串 | E16: 2.0% | F16: cum43Data[].plgFee
A17: PLP明细 | B17: 周期(0) | C17: 是 | D17: 自然周 Mon-Sun 如 5.18-5.24 | E17: 5.18-5.24 | F17: plpDetailData[].period
A18: PLP明细 | B18: 广告系列(1) | C18: 是 | D18: 广告系列名称 | E18: LYAM-X2428-C~俞东旭 | F18: plpDetailData[].campaign
A19: PLP明细 | B19: SKU(2) | C19: 是 | D19: 产品SKU编码 | E19: LYAM-X2428-C | F19: plpDetailData[].SKU
A20: PLP明细 | B20: 曝光量(11) | C20: 是 | D20: 广告曝光次数 | E20: 794 | F20: plpDetailData[].impressions
A21: PLP明细 | B21: 点击量(12) | C21: 是 | D21: 广告点击次数 | E21: 9 | F21: plpDetailData[].clicks
A22: PLP明细 | B22: 售出件数(13) | C22: 是 | D22: 广告售出件数 | E22: 1 | F22: plpDetailData[].salesQty
A23: PLP明细 | B23: 花费(14) | C23: 是 | D23: 广告花费 USD | E23: 5.09 | F23: plpDetailData[].spend
... A31: ⚠️ 百分比规则 | B31: PLP/PLG汇总表 acos/cvr/cpc | C31: - | D31: 已是格式化字符串("11.31%")，React端直接透传 | E31: "11.31%" | F31: plpAnalysts[]
A32: ⚠️ 百分比规则 | B32: 所有市占比字段 | C32: - | E32: 52.6→52.6% | F32: totalShare4w[]
A33: 通用 | B33: 销售额 | C33: - | D33: 所有销售额为USD原值，禁止货币转换
A34: 通用 | B34: 低占比定义 | C34: - | D34: 市占比<75% 且 对手销量>0
A35: 通用 | B35: ACOAS去重 | C35: - | D35: 计算ACOAS时totalRevenue按SKU去重
A36: 通用 | B36: 分析人(6人) | C36: - | D36: 俞东旭/张潇/朱培源/王偲涵/章鹏/胡煜星
A37: 通用 | B37: 品类(7类) | C37: - | D37: 车门系统/车身外扩件/挡泥板/机盖及附件/牌照板支架/其他/饰条
A38: 私区数据 | B38: 追踪间隔 | E38: 3
A39: 私区数据 | B39: 8日出单情况 | D39: N/Y/未出单/本期不分析(减少分析频次) | E39: 未出单
A40: 私区数据 | B40: 7日频次标签 | D40: 正常/异常/本期不分析(减少分析频次) | E40: 异常
A41: 私区数据 | B41: 上架8日内新品频次标签 | D41: 正常/异常/本期不分析(减少分析频次) | E41: 正常
A42: 私区数据 | B42: 市场状态 | D42: 正常/无市场/站外出单/站内无价格优势/竞争无优势 | E42: 站外出单
A43: 私区数据 | B43: 操作判断 | D43: 降价测试-市场无对手/降价测试-市场有低价对手出单/广告-PLG/广告-PLP/链接优化/无调整/8日新品优化 | E43: 广告-PLP

Sheet 四三数据累计
A1: 销售编号 | B1: SKU | C1: 实际上架日期 | D1: 首次出单日期 | E1: 5月分析人 | F1: 品类 | G1: 产品拓展 | H1: 3.5-3.11销量 | I1: 3.12-3.18销量 | J1: 3.19-3.25销量 | K1: 3.26-4.1销量 | L1: 4.2-4.8销量 | M1: 4.9-4.15销量 | N1: 4.16-4.22销量 | O1: 4.23-4.29销量 | P1: 4.30-5.6销量 | Q1: 5.7-5.13销量 | R1: 5.14-5.20销量 | S1: 5.21-5.27销量 | T1: 环比 | U1: 3.5-3.11销售额 | V1: 3.12-3.18销售额 | W1: 3.19-3.25销售额 | X1: 3.26-4.1销售额 | Y1: 4.2-4.8销售额 | Z1: 4.9-4.15销售额 | AA1: 4.16-4.22销售额 | AB1: 4.23-4.29销售额 | AC1: 4.30-5.6销售额 | AD1: 5.7-5.13销售额 | AE1: 5.14-5.20销售额 | AF1: 5.21-5.27销售额 | AG1: 环比 | AH1: 3.11对手销量 | AI1: 3.18对手销量 | AJ1: 3.25对手销量 | AK1: 4.1对手销量 | AL1: 4.8对手销量 | AM1: 4.15对手销量 | AN1: 4.22对手销量 | AO1: 4.29对手销量 | AP1: 5.6对手销量 | AQ1: 5.13对手销量 | AR1: 5.20对手销量 | AS1: 5.27对手销量 | AT1: 3.11市占比 | AU1: 3.18市占比 | AV1: 3.25市占比 | AW1: 4.1市占比 | AX1: 4.8市占比 | AY1: 4.15市占比 | AZ1: 4.22市占比 | BA1: 4.29市占比 | BB1: 5.6市占比 | BC1: 5.13市占比 | BD1: 5.20市占比 | BE1: 5.27市占比 | BF1: 3.11追踪间隔 | BG1: 3.18追踪间隔 | BH1: 3.25追踪间隔 | BI1: 4.1追踪间隔 | BJ1: 4.8追踪间隔 | BK1: 4.15追踪间隔 | BL1: 4.22追踪间隔 | BM1: 4.29追踪间隔 | BN1: 5.6追踪间隔 | BO1: 5.13追踪间隔 | BP1: 5.20追踪间隔 | BQ1: 5.27追踪间隔 | BR1: 3.11 8日出单情况 | BS1: 3.18 8日出单情况 | BT1: 3.25 8日出单情况 | BU1: 4.1 8日出单情况 | BV1: 4.8 8日出单情况 | BW1: 4.15 8日出单情况 | BX1: 4.22 8日出单情况 | BY1: 4.29 8日出单情况 | BZ1: 5.6 8日出单情况 | CA1: 5.13 8日出单情况 | CB1: 5.20 8日出单情况 | CC1: 5.27 8日出单情况 | CD1: 3.11 7日频次标签 | CE1: 3.18 7日频次标签 | CF1: 3.25 7日频次标签 | CG1: 4.1 7日频次标签 | CH1: 4.8 7日频次标签 | CI1: 4.15 7日频次标签 | CJ1: 4.22 7日频次标签 | CK1: 4.29 7日频次标签 | CL1: 5.6 7日频次标签 | CM1: 5.13 7日频次标签 | CN1: 5.20 7日频次标签 | CO1: 5.27 7日频次标签 | CP1: 3.11 上架8日内新品频次标签 | CQ1: 3.18 上架8日内新品频次标签 | CR1: 3.25 上架8日内新品频次标签 | CS1: 4.1 上架8日内新品频次标签 | CT1: 4.8 上架8日内新品频次标签 | CU1: 4.15 上架8日内新品频次标签 | CV1: 4.22 上架8日内新品频次标签 | CW1: 4.29 上架8日内新品频次标签 | CX1: 5.6 上架8日内新品频次标签 | CY1: 5.13上架8日内新品频次标签 | CZ1: 5.20上架8日内新品频次标签 | DA1: 5.27上架8日内新品频次标签 | DB1: 3.4市场状态 | DC1: 3.11市场状态 | DD1: 3.18市场状态 | DE1: 3.25市场状态 | DF1: 4.1市场状态 | DG1: 4.8市场状态 | DH1: 4.15市场状态 | DI1: 4.22市场状态 | DJ1: 4.29市场状态 | DK1: 5.6市场状态 | DL1: 5.13市场状态 | DM1: 5.20市场状态 | DN1: 5.27市场状态 | DO1: 3.5-3.11操作判断 | DP1: 3.12-3.18操作判断 | DQ1: 3.19-3.25操作判断 | DR1: 3.26-4.1操作判断 | DS1: 4.2-4.8操作判断 | DT1: 4.9-4.15操作判断 | DU1: 4.16-4.22操作判断 | DV1: 4.23-4.29操作判断 | DW1: 4.30-5.6操作判断 | DX1: 5.7-5.13操作判断 | DY1: 5.14-5.20操作判断 | DZ1: 5.21-5.27操作判断 | EA1: 4.9-4.15开启PLP | EB1: 4.16-4.22开启PLP | EC1: 4.23-4.29开启PLP | ED1: 4.30-5.6开启PLP | EE1: 5.4-5.10开启PLP | EF1: 5.11-5.17开启PLP | EG1: 5.18-5.24开启PLP | EH1: 5.18-5.24PLP广告花费 | EI1: 5.18-5.24PLP广告销售额 | EJ1: 4.16-4.22PLG最高费率 | EK1: 4.23-4.29PLG最高费率 | EL1: 4.30-5.6PLG最高费率 | EM1: 5.4-5.10PLG最高费率 | EN1: 5.11-5.17PLG最高费率 | EO1: 5.18-5.24PLG最高费率 | EP1: 5.18-5.24PLG广告花费 | EQ1: 5.18-5.24PLG广告销售额
A2: 12073 | B2: LYAP-X1658 | C2: 46085 | D2: =IF(_xlfn.XLOOKUP(A2,[1]分配表!J:J,[1]分配表!M:M)=0,"未出单",_xlfn.XLOOKUP(A2,[1]分配表!J:J,[1]分配表!M:M)) -> 46093 | E2: =_xlfn.XLOOKUP(A2,[1]分配表!A:A,[1]分配表!C:C) -> 朱培源 | F2: =IF(_xlfn.XLOOKUP($A2,[1]分配表!$A:$A,[1]分配表!D:D)=0,"未分类",_xlfn.XLOOKUP($A2,[1]分配表!$A:$A,[1]分配表!D:D)) -> 车门系统 | G2: =_xlfn.XLOOKUP(A2,[1]分配表!J:J,[1]分配表!I:I) -> 原开品 | H2: 0 | I2: 3 | J2: 3 | K2: 4 | L2: 0 | M2: 0 | N2: 1 | O2: 0 | P2: 1 | Q2: 4 | R2: 0 | S2: 1 | T2: =IFERROR(S2-R2,S2) -> 1 | U2: 0 | V2: 1260 | W2: 1260 | X2: 1680 | Y2: 0 | Z2: 0 | AA2: 420 | AB2: 0 | AC2: 420 | AD2: 1680 | AE2: 0 | AF2: 420 | AG2: =IFERROR(AF2-AE2,AF2) -> 420 | AH2: 0 | AI2: 0 | AJ2: 0 | AK2: 0 | AL2: 0 | AM2: 0 | AN2: 0 | AO2: 0 | AP2: 0 | AQ2: 0 | AR2: 0 | AS2: 0 | AT2: 市场无出单 | AU2: 1 | AV2: 1 | AW2: 1 | AX2: 0 | AY2: 0 | AZ2: 1 | BA2: 市场无出单 | BB2: 1 | BC2: 1 | BD2: 1 | BE2: 1 | BF2: 1 | BG2: 8 | BH2: 2 | BI2: 1 | BJ2: 1 | BK2: 9 | BL2: 9 | BM2: 16 | BN2: 23 | BO2: 30 | BP2: 37 | BQ2: 4 | BR2: 未出单 | BS2: Y | BT2: Y | BU2: Y | BV2: Y | BW2: Y | BX2: Y | BY2: Y | BZ2: Y | CA2: Y | CB2: Y | CC2: Y | CD2: 正常 | CE2: 异常 | CF2: 正常 | CG2: 正常 | CH2: 正常 | CI2: 正常 | CJ2: 正常 | CK2: 正常 | CL2: 正常 | CM2: 正常 | CN2: 正常 | CO2: 正常 | CP2: 正常 | CQ2: 正常 | CR2: 正常 | CS2: 正常 | CT2: 正常 | CU2: 正常 | CV2: 正常 | CW2: 正常 | CX2: 正常 | CY2: 正常 | CZ2: 正常 | DA2: 正常 | DB2: 无市场 | DC2: 无市场 | DD2: 正常 | DE2: 正常 | DF2: 正常 | DG2: 正常 | DH2: 无市场 | DI2: 正常 | DJ2: 无市场 | DK2: 正常 | DL2: 正常 | DM2: 正常 | DN2: 正常 | DO2: 广告-PLP | DP2: 无异常 | DQ2: 未分析 | DR2: 无异常 | DS2: 无异常 | DT2: 无异常 | DU2: 无异常 | DV2: 无异常 | DW2: 无异常 | DX2: 无异常 | DY2: 无异常 | DZ2: 无异常 | EA2: N | EB2: N | EC2: N | ED2: N | EE2: N | EF2: N | EG2: N | EH2: 0 | EI2: 0 | EJ2: 0.045 | EK2: 0.02 | EL2: 0.02 | EM2: 0.02 | EN2: 0.02 | EO2: 0.02 | EP2: 20.41 | EQ2: 453.6
A3: 12074 | B3: LYAP-X1658L | C3: 46085 | D3: =IF(_xlfn.XLOOKUP(A3,[1]分配表!J:J,[1]分配表!M:M)=0,"未出单",_xlfn.XLOOKUP(A3,[1]分配表!J:J,[1]分配表!M:M)) -> 46085 | E3: =_xlfn.XLOOKUP(A3,[1]分配表!A:A,[1]分配表!C:C) -> 朱培源 | F3: =IF(_xlfn.XLOOKUP($A3,[1]分配表!$A:$A,[1]分配表!D:D)=0,"未分类",_xlfn.XLOOKUP($A3,[1]分配表!$A:$A,[1]分配表!D:D)) -> 车门系统 | G3: =_xlfn.XLOOKUP(A3,[1]分配表!J:J,[1]分配表!I:I) -> 拓展品 | H3: 8 | I3: 12 | J3: 5 | K3: 6 | L3: 3 | M3: 3 | N3: 9 | O3: 9 | P3: 8 | Q3: 8 | R3: 5 | S3: 0 | T3: =IFERROR(S3-R3,S3) -> -5 | U3: 1760 | V3: 2640 | W3: 1080 | X3: 1320 | Y3: 675 | Z3: 679.1 | AA3: 2147.72 | AB3: 2196.8 | AC3: 2010.88 | AD3: 1983.16 | AE3: 1239.08 | AF3: 0 | AG3: =IFERROR(AF3-AE3,AF3) -> -1239.08 | AH3: 0 | AI3: 1 | AJ3: 0 | AK3: 0 | AL3: 0 | AM3: 0 | AN3: 0 | AO3: 0 | AP3: 0 | AQ3: 0 | AR3: 0 | AS3: 0 | AT3: 1 | AU3: 0.9 | AV3: 1 | AW3: 1 | AX3: 1 | AY3: 1 | AZ3: 1 | BA3: 1 | BB3: 1 | BC3: 1 | BD3: 1 | BE3: 1 | BF3: 5 | BG3: 12 | BH3: 2 | BI3: 1 | BJ3: 7 | BK3: 6 | BL3: 12 | BM3: 19 | BN3: 26 | BO3: 33 | BP3: 40 | BQ3: 47 | BR3: Y | BS3: Y | BT3: Y | BU3: Y | BV3: Y | BW3: Y | BX3: Y | BY3: Y | BZ3: Y | CA3: Y | CB3: Y | CC3: Y | CD3: 正常 | CE3: 异常 | CF3: 正常 | CG3: 正常 | CH3: 正常 | CI3: 正常 | CJ3: 正常 | CK3: 正常 | CL3: 正常 | CM3: 正常 | CN3: 正常 | CO3: 正常 | CP3: 异常 | CQ3: 正常 | CR3: 正常 | CS3: 正常 | CT3: 正常 | CU3: 正常 | CV3: 正常 | CW3: 正常 | CX3: 正常 | CY3: 正常 | CZ3: 正常 | DA3: 正常 | DB3: 无市场 | DC3: 正常 | DD3: 正常 | DE3: 正常 | DF3: 正常 | DG3: 正常 | DH3: 正常 | DI3: 正常 | DJ3: 正常 | DK3: 正常 | DL3: 正常 | DM3: 正常 | DN3: 正常 | DO3: 无调整 | DP3: 无调整 | DQ3: 未分析 | DR3: 无异常 | DS3: 无异常 | DT3: 无异常 | DU3: 无异常 | DV3: 无异常 | DW3: 无异常 | DX3: 无异常 | DY3: 无异常 | DZ3: 无异常 | EA3: N | EB3: N | EC3: N | ED3: N | EE3: N | EF3: N | EG3: N | EH3: 0 | EI3: 0 | EJ3: 0.05 | EK3: 0.02 | EL3: 0.02 | EM3: 0.02 | EN3: 0 | EO3: 0 | EP3: 10.45 | EQ3: 298.55
A4: 12075 | B4: LYAP-X1658R | C4: 46085 | D4: =IF(_xlfn.XLOOKUP(A4,[1]分配表!J:J,[1]分配表!M:M)=0,"未出单",_xlfn.XLOOKUP(A4,[1]分配表!J:J,[1]分配表!M:M)) -> 46085 | E4: =_xlfn.XLOOKUP(A4,[1]分配表!A:A,[1]分配表!C:C) -> 朱培源 | F4: =IF(_xlfn.XLOOKUP($A4,[1]分配表!$A:$A,[1]分配表!D:D)=0,"未分类",_xlfn.XLOOKUP($A4,[1]分配表!$A:$A,[1]分配表!D:D)) -> 车门系统 | G4: =_xlfn.XLOOKUP(A4,[1]分配表!J:J,[1]分配表!I:I) -> 拓展品 | H4: 1 | I4: 2 | J4: 0 | K4: 0 | L4: 0 | M4: 1 | N4: 0 | O4: 0 | P4: 1 | Q4: 1 | R4: 1 | S4: 0 | T4: =IFERROR(S4-R4,S4) -> -1 | U4: 220 | V4: 440 | W4: 0 | X4: 0 | Y4: 0 | Z4: 220 | AA4: 0 | AB4: 0 | AC4: 220 | AD4: 220 | AE4: 220 | AF4: 0 | AG4: =IFERROR(AF4-AE4,AF4) -> -220 | AH4: 0 | AI4: 0 | AJ4: 0 | AK4: 0 | AL4: 0 | AM4: 0 | AN4: 0 | AO4: 0 | AP4: 0 | AQ4: 0 | AR4: 0 | AS4: 0 | AT4: 1 | AU4: 1 | AV4: 市场无出单 | AW4: 0 | AX4: 0 | AY4: 1 | AZ4: 市场无出单 | BA4: 市场无出单 | BB4: 1 | BC4: 1 | BD4: 1 | BE4: 市场无出单 | BF4: 5 | BG4: 12 | BH4: 2 | BI4: 1 | BJ4: 1 | BK4: 9 | BL4: 15 | BM4: 22 | BN4: 29 | BO4: 36 | BP4: 43 | BQ4: 50 | BR4: Y | BS4: Y | BT4: Y | BU4: Y | BV4: Y | BW4: Y | BX4: Y | BY4: Y | BZ4: Y | CA4: Y | CB4: Y | CC4: Y | CD4: 正常 | CE4: 异常 | CF4: 正常 | CG4: 正常 | CH4: 正常 | CI4: 正常 | CJ4: 正常 | CK4: 正常 | CL4: 正常 | CM4: 正常 | CN4: 正常 | CO4: 正常 | CP4: 异常 | CQ4: 正常 | CR4: 正常 | CS4: 正常 | CT4: 正常 | CU4: 正常 | CV4: 正常 | CW4: 正常 | CX4: 正常 | CY4: 正常 | CZ4: 正常 | DA4: 正常 | DB4: 无市场 | DC4: 正常 | DD4: 正常 | DE4: 正常 | DF4: 无市场 | DG4: 无市场 | DH4: 正常 | DI4: 无市场 | DJ4: 无市场 | DK4: 正常 | DL4: 正常 | DM4: 正常 | DN4: 无市场 | DO4: 无调整 | DP4: 无调整 | DQ4: 未分析 | DR4: 无异常 | DS4: 无异常 | DT4: 无异常 | DU4: 无异常 | DV4: 无异常 | DW4: 无异常 | DX4: 无异常 | DY4: 无异常 | DZ4: 无异常 | EA4: N | EB4: N | EC4: N | ED4: N | EE4: N | EF4: N | EG4: N | EH4: 0 | EI4: 0 | EJ4: 0.045 | EK4: 0.02 | EL4: 0.02 | EM4: 0.02 | EN4: 0.02 | EO4: 0.02 | EP4: 0 | EQ4: 0
A5: 12252 | B5: LYAP-X1800-1 | C5: 46085 | D5: =IF(_xlfn.XLOOKUP(A5,[1]分配表!J:J,[1]分配表!M:M)=0,"未出单",_xlfn.XLOOKUP(A5,[1]分配表!J:J,[1]分配表!M:M)) -> 46089 | E5: =_xlfn.XLOOKUP(A5,[1]分配表!A:A,[1]分配表!C:C) -> 胡煜星 | F5: =IF(_xlfn.XLOOKUP($A5,[1]分配表!$A:$A,[1]分配表!D:D)=0,"未分类",_xlfn.XLOOKUP($A5,[1]分配表!$A:$A,[1]分配表!D:D)) -> 车门系统 | G5: =_xlfn.XLOOKUP(A5,[1]分配表!J:J,[1]分配表!I:I) -> 原开品 | H5: 3 | I5: 4 | J5: 2 | K5: 1 | L5: 0 | M5: 0 | N5: 1 | O5: 0 | P5: 1 | Q5: 1 | R5: 1 | S5: 1 | T5: =IFERROR(S5-R5,S5) -> 0 | U5: 122 | V5: 160 | W5: 80 | X5: 40 | Y5: 0 | Z5: 0 | AA5: 40 | AB5: 0 | AC5: 40 | AD5: 40 | AE5: 40 | AF5: 40 | AG5: =IFERROR(AF5-AE5,AF5) -> 0 | AH5: 11 | AI5: 1 | AJ5: 4 | AK5: 10 | AL5: 1 | AM5: 12 | AN5: 12 | AO5: 9 | AP5: 7 | AQ5: 2 | AR5: 0 | AS5: 3 | AT5: 0.21428571 | AU5: 0.8571 | AV5: 0.33333333 | AW5: 0.090909091 | AX5: 0 | AY5: 0 | AZ5: 0.0769 | BA5: 0 | BB5: 0.125 | BC5: 0.3333 | BD5: 1 | BE5: 0 | BF5: 1 | BG5: 1 | BH5: 0 | BI5: 8 | BJ5: 0 | BK5: 5 | BL5: 6 | BM5: 13 | BN5: 0 | BO5: 7 | BP5: 1 | BQ5: 8 | BR5: Y | BS5: Y | BT5: Y | BU5: Y | BV5: Y | BW5: Y | BX5: Y | BY5: Y | BZ5: Y | CA5: Y | CB5: Y | CC5: Y | CD5: 正常 | CE5: 正常 | CF5: 正常 | CG5: 异常 | CH5: 正常 | CI5: 正常 | CJ5: 正常 | CK5: 异常 | CL5: 正常 | CM5: 异常 | CN5: 正常 | CO5: 异常 | CP5: 正常 | CQ5: 正常 | CR5: 正常 | CS5: 正常 | CT5: 正常 | CU5: 正常 | CV5: 正常 | CW5: 正常 | CX5: 正常 | CY5: 正常 | CZ5: 正常 | DA5: 正常 | DB5: 无市场 | DC5: 竞争无优势 | DD5: 正常 | DE5: 竞争无优势 | DF5: 竞争无优势 | DG5: 竞争无优势 | DH5: 竞争无优势 | DI5: 竞争无优势 | DJ5: 竞争无优势 | DK5: 竞争无优势 | DL5: 竞争无优势 | DM5: 正常 | DN5: 竞争无优势 | DO5: 广告-PLP | DP5: 无异常 | DQ5: 无异常 | DR5: 广告-PLG | DS5: 无异常 | DT5: 无异常 | DU5: 无异常 | DV5: 无异常 | DW5: 链接优化 | DX5: 无异常 | DY5: 本期不分析 | DZ5: 无异常 | EA5: Y | EB5: Y | EC5: Y | ED5: N | EE5: Y | EF5: Y | EG5: Y | EH5: 3.01 | EI5: 0 | EJ5: 0.08 | EK5: 0.07 | EL5: 0.05 | EM5: 0.07 | EN5: 0.07 | EO5: 0.05 | EP5: 0 | EQ5: 0
A6: 12165 | B6: LYAP-X1877 | C6: 46085 | D6: =IF(_xlfn.XLOOKUP(A6,[1]分配表!J:J,[1]分配表!M:M)=0,"未出单",_xlfn.XLOOKUP(A6,[1]分配表!J:J,[1]分配表!M:M)) -> 46093 | E6: =_xlfn.XLOOKUP(A6,[1]分配表!A:A,[1]分配表!C:C) -> 朱培源 | F6: =IF(_xlfn.XLOOKUP($A6,[1]分配表!$A:$A,[1]分配表!D:D)=0,"未分类",_xlfn.XLOOKUP($A6,[1]分配表!$A:$A,[1]分配表!D:D)) -> 挡泥板 | G6: =_xlfn.XLOOKUP(A6,[1]分配表!J:J,[1]分配表!I:I) -> 原开品 | H6: 0 | I6: 2 | J6: 0 | K6: 0 | L6: 0 | M6: 1 | N6: 2 | O6: 0 | P6: 1 | Q6: 1 | R6: 0 | S6: 1 | T6: =IFERROR(S6-R6,S6) -> 1 | U6: 0 | V6: 338 | W6: 0 | X6: 0 | Y6: 0 | Z6: 169 | AA6: 338 | AB6: 0 | AC6: 169 | AD6: 169 | AE6: 0 | AF6: 172 | AG6: =IFERROR(AF6-AE6,AF6) -> 172 | AH6: 0 | AI6: 0 | AJ6: 1 | AK6: 0 | AL6: 3 | AM6: 6 | AN6: 3 | AO6: 3 | AP6: 1 | AQ6: 2 | AR6: 1 | AS6: 1 | AT6: 市场无出单 | AU6: 1 | AV6: 0 | AW6: 0 | AX6: 0 | AY6: 0.14285714 | AZ6: 0.4 | BA6: 0 | BB6: 0 | BC6: 0.3333 | BD6: 0.5 | BE6: 0.5 | BF6: 5 | BG6: 1 | BH6: 2 | BI6: 1 | BJ6: 7 | BK6: 6 | BL6: 5 | BM6: 12 | BN6: 19 | BO6: 6 | BP6: 13 | BQ6: 0 | BR6: 未出单 | BS6: Y | BT6: Y | BU6: Y | BV6: Y | BW6: Y | BX6: Y | BY6: Y | BZ6: Y | CA6: Y | CB6: Y | CC6: Y | CD6: 正常 | CE6: 正常 | CF6: 正常 | CG6: 正常 | CH6: 异常 | CI6: 正常 | CJ6: 正常 | CK6: 异常 | CL6: 异常 | CM6: 正常 | CN6: 异常 | CO6: 正常 | CP6: 异常 | CQ6: 正常 | CR6: 正常 | CS6: 正常 | CT6: 正常 | CU6: 正常 | CV6: 正常 | CW6: 正常 | CX6: 正常 | CY6: 正常 | CZ6: 正常 | DA6: 正常 | DB6: 无市场 | DC6: 无市场 | DD6: 正常 | DE6: 竞争无优势 | DF6: 站外出单 | DG6: 竞争无优势 | DH6: 竞争无优势 | DI6: 竞争无优势 | DJ6: 竞争无优势 | DK6: 竞争无优势 | DL6: 竞争无优势 | DM6: 竞争无优势 | DN6: 竞争无优势 | DO6: 无调整 | DP6: 广告-PLG | DQ6: 无异常 | DR6: 无异常 | DS6: 广告-PLG | DT6: 广告-PLG | DU6: 无异常 | DV6: 无异常 | DW6: 广告-PLG | DX6: 广告-PLG | DY6: 无异常 | DZ6: 无调整 | EA6: N | EB6: N | EC6: N | ED6: N | EE6: N | EF6: N | EG6: N | EH6: 0 | EI6: 0 | EJ6: 0.05 | EK6: 0.05 | EL6: 0.02 | EM6: 0.045 | EN6: 0.02 | EO6: 0.02 | EP6: 11.88 | EQ6: 365.26
A7: 12247 | B7: LYAP-X2528 | C7: 46085 | D7: =IF(_xlfn.XLOOKUP(A7,[1]分配表!J:J,[1]分配表!M:M)=0,"未出单",_xlfn.XLOOKUP(A7,[1]分配表!J:J,[1]分配表!M:M)) -> 46089 | E7: =_xlfn.XLOOKUP(A7,[1]分配表!A:A,[1]分配表!C:C) -> 胡煜星 | F7: =IF(_xlfn.XLOOKUP($A7,[1]分配表!$A:$A,[1]分配表!D:D)=0,"未分类",_xlfn.XLOOKUP($A7,[1]分配表!$A:$A,[1]分配表!D:D)) -> 其他 | G7: =_xlfn.XLOOKUP(A7,[1]分配表!J:J,[1]分配表!I:I) -> 原开品 | H7: 5 | I7: 8 | J7: 3 | K7: 6 | L7: 6 | M7: 2 | N7: 7 | O7: 1 | P7: 5 | Q7: 4 | R7: 4 | S7: 5 | T7: =IFERROR(S7-R7,S7) -> 1 | U7: 475 | V7: 632 | W7: 237 | X7: 481 | Y7: 534 | Z7: 178 | AA7: 647.28 | AB7: 111.25 | AC7: 490 | AD7: 392 | AE7: 410.25 | AF7: 503.25 | AG7: =IFERROR(AF7-AE7,AF7) -> 93 | AH7: 0 | AI7: 0 | AJ7: 0 | AK7: 0 | AL7: 0 | AM7: 0 | AN7: 0 | AO7: 0 | AP7: 0 | AQ7: 0 | AR7: 0 | AS7: 0 | AT7: 1 | AU7: 1 | AV7: 1 | AW7: 1 | AX7: 1 | AY7: 1 | AZ7: 1 | BA7: 1 | BB7: 1 | BC7: 1 | BD7: 1 | BE7: 1 | BF7: 1 | BG7: 1 | BH7: 1 | BI7: 3 | BJ7: 9 | BK7: 6 | BL7: 12 | BM7: 4 | BN7: 11 | BO7: 18 | BP7: 25 | BQ7: 32 | BR7: Y | BS7: Y | BT7: Y | BU7: Y | BV7: Y | BW7: Y | BX7: Y | BY7: Y | BZ7: Y | CA7: Y | CB7: Y | CC7: Y | CD7: 正常 | CE7: 正常 | CF7: 正常 | CG7: 正常 | CH7: 正常 | CI7: 正常 | CJ7: 正常 | CK7: 正常 | CL7: 正常 | CM7: 正常 | CN7: 正常 | CO7: 正常 | CP7: 正常 | CQ7: 正常 | CR7: 正常 | CS7: 正常 | CT7: 正常 | CU7: 正常 | CV7: 正常 | CW7: 正常 | CX7: 正常 | CY7: 正常 | CZ7: 正常 | DA7: 正常 | DB7: 无市场 | DC7: 正常 | DD7: 正常 | DE7: 正常 | DF7: 正常 | DG7: 正常 | DH7: 正常 | DI7: 正常 | DJ7: 正常 | DK7: 正常 | DL7: 正常 | DM7: 正常 | DN7: 正常 | DO7: 广告-PLP | DP7: 无异常 | DQ7: 无异常 | DR7: 无异常 | DS7: 无异常 | DT7: 无异常 | DU7: 无异常 | DV7: 无异常 | DW7: 无异常 | DX7: 无异常 | DY7: 无异常 | DZ7: 无异常 | EA7: Y | EB7: Y | EC7: Y | ED7: N | EE7: N | EF7: N | EG7: Y | EH7: 0 | EI7: 0 | EJ7: 0.04 | EK7: 0.03 | EL7: 0 | EM7: 0.03 | EN7: 0 | EO7: 0 | EP7: 9.53 | EQ7: 317.67
A8: 11102 | B8: LYAM-X2254-L | C8: 46085 | D8: =IF(_xlfn.XLOOKUP(A8,[1]分配表!J:J,[1]分配表!M:M)=0,"未出单",_xlfn.XLOOKUP(A8,[1]分配表!J:J,[1]分配表!M:M)) -> 46100 | E8: =_xlfn.XLOOKUP(A8,[1]分配表!A:A,[1]分配表!C:C) -> 张潇 | F8: =IF(_xlfn.XLOOKUP($A8,[1]分配表!$A:$A,[1]分配表!D:D)=0,"未分类",_xlfn.XLOOKUP($A8,[1]分配表!$A:$A,[1]分配表!D:D)) -> 车门系统 | G8: =_xlfn.XLOOKUP(A8,[1]分配表!J:J,[1]分配表!I:I) -> 原开品 | H8: 0 | I8: 0 | J8: 2 | K8: 1 | L8: 3 | M8: 0 | N8: 3 | O8: 4 | P8: 5 | Q8: 5 | R8: 2 | S8: 3 | T8: =IFERROR(S8-R8,S8) -> 1 | U8: 0 | V8: 0 | W8: 64 | X8: 32 | Y8: 96 | Z8: 0 | AA8: 92.19 | AB8: 112.76 | AC8: 140.95 | AD8: 140.95 | AE8: 56.38 | AF8: 83.53 | AG8: =IFERROR(AF8-AE8,AF8) -> 27.15 | AH8: 2 | AI8: 5 | AJ8: 3 | AK8: 2 | AL8: 0 | AM8: 6 | AN8: 5 | AO8: 2 | AP8: 5 | AQ8: 6 | AR8: 5 | AS8: 8 | AT8: 0 | AU8: 0 | AV8: 0.4 | AW8: 0.33333333 | AX8: 1 | AY8: 0 | AZ8: 0.2857 | BA8: 0.5 | BB8: 0.5833 | BC8: 0.3333 | BD8: 0.5 | BE8: 0.2 | BF8: 7 | BG8: 2 | BH8: 2 | BI8: 3 | BJ8: 9 | BK8: 3 | BL8: 5 | BM8: 6 | BN8: 13 | BO8: 4 | BP8: 0 | BQ8: 7 | BR8: 未出单 | BS8: 未出单 | BT8: N | BU8: N | BV8: N | BW8: N | BX8: N | BY8: N | BZ8: N | CA8: N | CB8: N | CC8: N | CD8: 正常 | CE8: 正常 | CF8: 正常 | CG8: 正常 | CH8: 正常 | CI8: 正常 | CJ8: 正常 | CK8: 正常 | CL8: 异常 | CM8: 正常 | CN8: 正常 | CO8: 异常 | CP8: 异常 | CQ8: 正常 | CR8: 正常 | CS8: 正常 | CT8: 正常 | CU8: 正常 | CV8: 正常 | CW8: 正常 | CX8: 正常 | CY8: 正常 | CZ8: 正常 | DA8: 正常 | DB8: 无市场 | DC8: 站内无价格优势 | DD8: 站内无价格优势 | DE8: 竞争无优势 | DF8: 竞争无优势 | DG8: 正常 | DH8: 竞争无优势 | DI8: 竞争无优势 | DJ8: 竞争无优势 | DK8: 竞争无优势 | DL8: 竞争无优势 | DM8: 竞争无优势 | DN8: 竞争无优势 | DO8: 链接优化 | DP8: 广告-PLP | DQ8: 广告-PLG | DR8: 无异常 | DS8: 无异常 | DT8: 无异常 | DU8: 无异常 | DV8: 无异常 | DW8: 无异常 | DX8: 无调整 | DY8: 无异常 | DZ8: 无异常 | EA8: Y | EB8: Y | EC8: Y | ED8: Y | EE8: Y | EF8: Y | EG8: Y | EH8: 5.55 | EI8: 30.73 | EJ8: 0.03 | EK8: 0.03 | EL8: 0 | EM8: 0.03 | EN8: 0 | EO8: 0 | EP8: 0 | EQ8: 0
A9: 12071 | B9: LYAM-X2980-BK | C9: 46085 | D9: =IF(_xlfn.XLOOKUP(A9,[1]分配表!J:J,[1]分配表!M:M)=0,"未出单",_xlfn.XLOOKUP(A9,[1]分配表!J:J,[1]分配表!M:M)) -> 46092 | E9: =_xlfn.XLOOKUP(A9,[1]分配表!A:A,[1]分配表!C:C) -> 胡煜星 | F9: =IF(_xlfn.XLOOKUP($A9,[1]分配表!$A:$A,[1]分配表!D:D)=0,"未分类",_xlfn.XLOOKUP($A9,[1]分配表!$A:$A,[1]分配表!D:D)) -> 车身外扩件 | G9: =_xlfn.XLOOKUP(A9,[1]分配表!J:J,[1]分配表!I:I) -> 拓展品 | H9: 1 | I9: 0 | J9: 0 | K9: 1 | L9: 0 | M9: 3 | N9: 1 | O9: 0 | P9: 0 | Q9: 1 | R9: 1 | S9: 2 | T9: =IFERROR(S9-R9,S9) -> 1 | U9: 299 | V9: 0 | W9: 0 | X9: 299 | Y9: 0 | Z9: 897 | AA9: 299 | AB9: 0 | AC9: 0 | AD9: 284.05 | AE9: 299 | AF9: 598 | AG9: =IFERROR(AF9-AE9,AF9) -> 299 | AH9: 1 | AI9: 0 | AJ9: 0 | AK9: 0 | AL9: 0 | AM9: 0 | AN9: 0 | AO9: 1 | AP9: 0 | AQ9: 1 | AR9: 0 | AS9: 0 | AT9: 0.5 | AU9: 1 | AV9: 市场无出单 | AW9: 1 | AX9: 0 | AY9: 1 | AZ9: 市场无出单 | BA9: 0.5 | BB9: 市场无出单 | BC9: 0.5 | BD9: 1 | BE9: 市场无出单 | BF9: 1 | BG9: 8 | BH9: 1 | BI9: 9 | BJ9: 0 | BK9: 8 | BL9: 14 | BM9: 21 | BN9: 0 | BO9: 7 | BP9: 14 | BQ9: 21 | BR9: Y | BS9: Y | BT9: Y | BU9: Y | BV9: Y | BW9: Y | BX9: Y | BY9: Y | BZ9: Y | CA9: Y | CB9: Y | CC9: Y | CD9: 正常 | CE9: 异常 | CF9: 正常 | CG9: 异常 | CH9: 正常 | CI9: 正常 | CJ9: 正常 | CK9: 异常 | CL9: 正常 | CM9: 异常 | CN9: 正常 | CO9: 正常 | CP9: 正常 | CQ9: 正常 | CR9: 正常 | CS9: 正常 | CT9: 正常 | CU9: 正常 | CV9: 正常 | CW9: 正常 | CX9: 正常 | CY9: 正常 | CZ9: 正常 | DA9: 正常 | DB9: 无市场 | DC9: 竞争无优势 | DD9: 正常 | DE9: 无市场 | DF9: 正常 | DG9: 无市场 | DH9: 正常 | DI9: 无市场 | DJ9: 竞争无优势 | DK9: 无市场 | DL9: 竞争无优势 | DM9: 正常 | DN9: 无市场 | DO9: 8日新品优化 | DP9: 无异常 | DQ9: 无调整 | DR9: 无调整 | DS9: 无异常 | DT9: 无异常 | DU9: 无异常 | DV9: 无异常 | DW9: 广告-PLG | DX9: 无异常 | DY9: 本期不分析 | DZ9: 无异常 | EA9: N | EB9: N | EC9: N | ED9: N | EE9: N | EF9: N | EG9: N | EH9: 0 | EI9: 0 | EJ9: 0 | EK9: 0 | EL9: 0 | EM9: 0.02 | EN9: 0 | EO9: 0 | EP9: 0 | EQ9: 0
A10: 12072 | B10: LYAM-X2980-GR | C10: 46085 | D10: =IF(_xlfn.XLOOKUP(A10,[1]分配表!J:J,[1]分配表!M:M)=0,"未出单",_xlfn.XLOOKUP(A10,[1]分配表!J:J,[1]分配表!M:M)) -> 46112 | E10: =_xlfn.XLOOKUP(A10,[1]分配表!A:A,[1]分配表!C:C) -> 胡煜星 | F10: =IF(_xlfn.XLOOKUP($A10,[1]分配表!$A:$A,[1]分配表!D:D)=0,"未分类",_xlfn.XLOOKUP($A10,[1]分配表!$A:$A,[1]分配表!D:D)) -> 车身外扩件 | G10: =_xlfn.XLOOKUP(A10,[1]分配表!J:J,[1]分配表!I:I) -> 原开品 | H10: 0 | I10: 0 | J10: 0 | K10: 1 | L10: 0 | M10: 1 | N10: 1 | O10: 1 | P10: 0 | Q10: 2 | R10: 0 | S10: 0 | T10: =IFERROR(S10-R10,S10) -> 0 | U10: 0 | V10: 0 | W10: 0 | X10: 299 | Y10: 0 | Z10: 299 | AA10: 299 | AB10: 299 | AC10: 0 | AD10: 598 | AE10: 0 | AF10: 0 | AG10: =IFERROR(AF10-AE10,AF10) -> 0 | AH10: 0 | AI10: 0 | AJ10: 0 | AK10: 0 | AL10: 0 | AM10: 0 | AN10: 0 | AO10: 0 | AP10: 0 | AQ10: 0 | AR10: 0 | AS10: 0 | AT10: 市场无出单 | AU10: 市场无出单 | AV10: 市场无出单 | AW10: 1 | AX10: 0 | AY10: 1 | AZ10: 1 | BA10: 1 | BB10: 市场无出单 | BC10: 1 | BD10: 市场无出单 | BE10: 市场无出单 | BF10: 1 | BG10: 8 | BH10: 不分析 | BI10: 9 | BJ10: 0 | BK10: 8 | BL10: 14 | BM10: 21 | BN10: 28 | BO10: 35 | BP10: 42 | BQ10: 49 | BR10: 未出单 | BS10: 未出单 | BT10: 未出单 | BU10: N | BV10: N | BW10: N | BX10: N | BY10: N | BZ10: N | CA10: N | CB10: N | CC10: N | CD10: 正常 | CE10: 异常 | CF10: 不分析 | CG10: 异常 | CH10: 正常 | CI10: 正常 | CJ10: 正常 | CK10: 正常 | CL10: 正常 | CM10: 正常 | CN10: 正常 | CO10: 正常 | CP10: 正常 | CQ10: 正常 | CR10: 不分析 | CS10: 正常 | CT10: 正常 | CU10: 正常 | CV10: 正常 | CW10: 正常 | CX10: 正常 | CY10: 正常 | CZ10: 正常 | DA10: 正常 | DB10: 无市场 | DC10: 无市场 | DD10: 无市场 | DE10: 无市场 | DF10: 无市场 | DG10: 无市场 | DH10: 无市场 | DI10: 正常 | DJ10: 正常 | DK10: 无市场 | DL10: 正常 | DM10: 无市场 | DN10: 无市场 | DO10: 8日新品优化 | DP10: 无异常 | DQ10: 无调整 | DR10: 无调整 | DS10: 无异常 | DT10: 无异常 | DU10: 无异常 | DV10: 无异常 | DW10: 无异常 | DX10: 无异常 | DY10: 无异常 | DZ10: 无异常 | EA10: N | EB10: N | EC10: N | ED10: N | EE10: N | EF10: N | EG10: N | EH10: 0 | EI10: 0 | EJ10: 0.02 | EK10: 0 | EL10: 0 | EM10: 0 | EN10: 0 | EO10: 0 | EP10: 0 | EQ10: 0
A11: 12248 | B11: LYAP-X2308 | C11: 46085 | D11: =IF(_xlfn.XLOOKUP(A11,[1]分配表!J:J,[1]分配表!M:M)=0,"未出单",_xlfn.XLOOKUP(A11,[1]分配表!J:J,[1]分配表!M:M)) -> 46091 | E11: =_xlfn.XLOOKUP(A11,[1]分配表!A:A,[1]分配表!C:C) -> 胡煜星 | F11: =IF(_xlfn.XLOOKUP($A11,[1]分配表!$A:$A,[1]分配表!D:D)=0,"未分类",_xlfn.XLOOKUP($A11,[1]分配表!$A:$A,[1]分配表!D:D)) -> 其他 | G11: =_xlfn.XLOOKUP(A11,[1]分配表!J:J,[1]分配表!I:I) -> 原开品 | H11: 3 | I11: 1 | J11: 3 | K11: 3 | L11: 5 | M11: 5 | N11: 5 | O11: 3 | P11: 3 | Q11: 2 | R11: 4 | S11: 7 | T11: =IFERROR(S11-R11,S11) -> 3 | U11: 255 | V11: 85 | W11: 255 | X11: 255 | Y11: 425 | Z11: 425 | AA11: 429 | AB11: 258 | AC11: 257 | AD11: 170 | AE11: 341 | AF11: 601 | AG11: =IFERROR(AF11-AE11,AF11) -> 260 | AH11: 1 | AI11: 1 | AJ11: 0 | AK11: 4 | AL11: 1 | AM11: 3 | AN11: 1 | AO11: 4 | AP11: 1 | AQ11: 3 | AR11: 2 | AS11: 5 | AT11: 0.75 | AU11: 0.8 | AV11: 1 | AW11: 0.42857143 | AX11: 0.83333333 | AY11: 0.625 | AZ11: 0.8333 | BA11: 0.5 | BB11: 0.75 | BC11: 0.25 | BD11: 0.6 | BE11: 0.5833 | BF11: 1 | BG11: 7 | BH11: 7 | BI11: 15 | BJ11: 0 | BK11: 8 | BL11: 5 | BM11: 12 | BN11: 0 | BO11: 7 | BP11: 1 | BQ11: 8 | BR11: Y | BS11: Y | BT11: Y | BU11: Y | BV11: Y | BW11: Y | BX11: Y | BY11: Y | BZ11: Y | CA11: Y | CB11: Y | CC11: Y | CD11: 正常 | CE11: 正常 | CF11: 正常 | CG11: 异常 | CH11: 正常 | CI11: 异常 | CJ11: 正常 | CK11: 异常 | CL11: 正常 | CM11: 异常 | CN11: 正常 | CO11: 异常 | CP11: 正常 | CQ11: 正常 | CR11: 正常 | CS11: 正常 | CT11: 正常 | CU11: 正常 | CV11: 正常 | CW11: 正常 | CX11: 正常 | CY11: 正常 | CZ11: 正常 | DA11: 正常 | DB11: 无市场 | DC11: 竞争无优势 | DD11: 正常 | DE11: 正常 | DF11: 竞争无优势 | DG11: 正常 | DH11: 竞争无优势 | DI11: 正常 | DJ11: 竞争无优势 | DK11: 正常 | DL11: 竞争无优势 | DM11: 竞争无优势 | DN11: 竞争无优势 | DO11: 广告-PLP | DP11: 无异常 | DQ11: 无异常 | DR11: 广告-PLP | DS11: 无异常 | DT11: 无异常 | DU11: 广告-PLG | DV11: 无异常 | DW11: 链接优化 | DX11: 无异常 | DY11: 本期不分析 | DZ11: 无异常 | EA11: Y | EB11: Y | EC11: Y | ED11: N | EE11: N | EF11: Y | EG11: Y | EH11: 0 | EI11: 0 | EJ11: 0.04 | EK11: 0.04 | EL11: 0.02 | EM11: 0.04 | EN11: 0.02 | EO11: 0.02 | EP11: 14.43 | EQ11: 450.52
A12: 12246 | B12: LYAP-X2527 | C12: 46085 | D12: =IF(_xlfn.XLOOKUP(A12,[1]分配表!J:J,[1]分配表!M:M)=0,"未出单",_xlfn.XLOOKUP(A12,[1]分配表!J:J,[1]分配表!M:M)) -> 46086 | E12: =_xlfn.XLOOKUP(A12,[1]分配表!A:A,[1]分配表!C:C) -> 胡煜星 | F12: =IF(_xlfn.XLOOKUP($A12,[1]分配表!$A:$A,[1]分配表!D:D)=0,"未分类",_xlfn.XLOOKUP($A12,[1]分配表!$A:$A,[1]分配表!D:D)) -> 其他 | G12: =_xlfn.XLOOKUP(A12,[1]分配表!J:J,[1]分配表!I:I) -> 原开品 | H12: 11 | I12: 8 | J12: 8 | K12: 9 | L12: 15 | M12: 8 | N12: 12 | O12: 10 | P12: 9 | Q12: 9 | R12: 7 | S12: 7 | T12: =IFERROR(S12-R12,S12) -> 0 | U12: 1185 | V12: 686 | W12: 690 | X12: 772 | Y12: 1296 | Z12: 685.75 | AA12: 1033 | AB12: 879 | AC12: 833.5 | AD12: 846 | AE12: 663 | AF12: 627.1 | AG12: =IFERROR(AF12-AE12,AF12) -> -35.9 | AH12: 2 | AI12: 0 | AJ12: 0 | AK12: 0 | AL12: 0 | AM12: 0 | AN12: 0 | AO12: 0 | AP12: 0 | AQ12: 1 | AR12: 1 | AS12: 0 | AT12: 0.84615385 | AU12: 1 | AV12: 1 | AW12: 1 | AX12: 1 | AY12: 1 | AZ12: 1 | BA12: 1 | BB12: 1 | BC12: 0.9231 | BD12: 0.8333 | BE12: 1 | BF12: 1 | BG12: 4 | BH12: 11 | BI12: 1 | BJ12: 7 | BK12: 5 | BL12: 11 | BM12: 4 | BN12: 1 | BO12: 1 | BP12: 8 | BQ12: 0 | BR12: Y | BS12: Y | BT12: Y | BU12: Y | BV12: Y | BW12: Y | BX12: Y | BY12: Y | BZ12: Y | CA12: Y | CB12: Y | CC12: Y | CD12: 正常 | CE12: 正常 | CF12: 异常 | CG12: 正常 | CH12: 正常 | CI12: 正常 | CJ12: 正常 | CK12: 正常 | CL12: 正常 | CM12: 正常 | CN12: 正常 | CO12: 正常 | CP12: 正常 | CQ12: 正常 | CR12: 正常 | CS12: 正常 | CT12: 正常 | CU12: 正常 | CV12: 正常 | CW12: 正常 | CX12: 正常 | CY12: 正常 | CZ12: 正常 | DA12: 正常 | DB12: 无市场 | DC12: 正常 | DD12: 正常 | DE12: 正常 | DF12: 正常 | DG12: 正常 | DH12: 正常 | DI12: 正常 | DJ12: 正常 | DK12: 正常 | DL12: 正常 | DM12: 正常 | DN12: 正常 | DO12: 广告-PLP | DP12: 无异常 | DQ12: 无异常 | DR12: 无异常 | DS12: 无异常 | DT12: 无异常 | DU12: 无异常 | DV12: 无异常 | DW12: 无异常 | DX12: 无异常 | DY12: 无异常 | DZ12: 无异常 | EA12: Y | EB12: Y | EC12: Y | ED12: Y | EE12: Y | EF12: Y | EG12: Y | EH12: 3.93 | EI12: 199.66 | EJ12: 0.02 | EK12: 0 | EL12: 0 | EM12: 0 | EN12: 0 | EO12: 0.02 | EP12: 0 | EQ12: 0
A13: 12205 | B13: LYAP-X1800S-1L | C13: 46086 | D13: =IF(_xlfn.XLOOKUP(A13,[1]分配表!J:J,[1]分配表!M:M)=0,"未出单",_xlfn.XLOOKUP(A13,[1]分配表!J:J,[1]分配表!M:M)) -> 46089 | E13: =_xlfn.XLOOKUP(A13,[1]分配表!A:A,[1]分配表!C:C) -> 胡煜星 | F13: =IF(_xlfn.XLOOKUP($A13,[1]分配表!$A:$A,[1]分配表!D:D)=0,"未分类",_xlfn.XLOOKUP($A13,[1]分配表!$A:$A,[1]分配表!D:D)) -> 车门系统 | G13: =_xlfn.XLOOKUP(A13,[1]分配表!J:J,[1]分配表!I:I) -> 原开品 | H13: 2 | I13: 9 | J13: 0 | K13: 7 | L13: 6 | M13: 1 | N13: 8 | O13: 15 | P13: 10 | Q13: 3 | R13: 3 | S13: 2 | T13: =IFERROR(S13-R13,S13) -> -1 | U13: 44 | V13: 196 | W13: 0 | X13: 152 | Y13: 132 | Z13: 22 | AA13: 176 | AB13: 330 | AC13: 220 | AD13: 66 | AE13: 68 | AF13: 42.68 | AG13: =IFERROR(AF13-AE13,AF13) -> -25.32 | AH13: 29 | AI13: 34 | AJ13: 32 | AK13: 34 | AL13: 23 | AM13: 30 | AN13: 23 | AO13: 21 | AP13: 20 | AQ13: 11 | AR13: 17 | AS13: 9 | AT13: 0.064516129 | AU13: 0.2093 | AV13: 0 | AW13: 0.17073171 | AX13: 0.20689655 | AY13: 0.032258065 | AZ13: 0.2333 | BA13: 0.3824 | BB13: 0.3548 | BC13: 0.3125 | BD13: 0.1053 | BE13: 0.1818 | BF13: 1 | BG13: 1 | BH13: 0 | BI13: 5 | BJ13: 1 | BK13: 5 | BL13: 1 | BM13: 8 | BN13: 0 | BO13: 1 | BP13: 1 | BQ13: 8 | BR13: Y | BS13: Y | BT13: Y | BU13: Y | BV13: Y | BW13: Y | BX13: Y | BY13: Y | BZ13: Y | CA13: Y | CB13: Y | CC13: Y | CD13: 正常 | CE13: 正常 | CF13: 正常 | CG13: 正常 | CH13: 正常 | CI13: 正常 | CJ13: 正常 | CK13: 异常 | CL13: 正常 | CM13: 正常 | CN13: 正常 | CO13: 异常 | CP13: 正常 | CQ13: 正常 | CR13: 正常 | CS13: 正常 | CT13: 正常 | CU13: 正常 | CV13: 正常 | CW13: 正常 | CX13: 正常 | CY13: 正常 | CZ13: 正常 | DA13: 正常 | DB13: 未上架 | DC13: 竞争无优势 | DD13: 竞争无优势 | DE13: 竞争无优势 | DF13: 竞争无优势 | DG13: 竞争无优势 | DH13: 竞争无优势 | DI13: 竞争无优势 | DJ13: 竞争无优势 | DK13: 竞争无优势 | DL13: 竞争无优势 | DM13: 竞争无优势 | DN13: 竞争无优势 | DO13: 未上架 | DP13: 无异常 | DQ13: 无异常 | DR13: 无异常 | DS13: 无异常 | DT13: 无异常 | DU13: 无异常 | DV13: 无异常 | DW13: 链接优化 | DX13: 无异常 | DY13: 无异常 | DZ13: 无异常 | EA13: Y | EB13: Y | EC13: Y | ED13: N | EE13: Y | EF13: Y | EG13: Y | EH13: 1.66 | EI13: 26.15 | EJ13: 0.07 | EK13: 0.07 | EL13: 0.05 | EM13: 0.07 | EN13: 0.07 | EO13: 0.07 | EP13: 2.54 | EQ13: 49.33
A14: 12206 | B14: LYAP-X1800S-1R | C14: 46086 | D14: =IF(_xlfn.XLOOKUP(A14,[1]分配表!J:J,[1]分配表!M:M)=0,"未出单",_xlfn.XLOOKUP(A14,[1]分配表!J:J,[1]分配表!M:M)) -> 46094 | E14: =_xlfn.XLOOKUP(A14,[1]分配表!A:A,[1]分配表!C:C) -> 胡煜星 | F14: =IF(_xlfn.XLOOKUP($A14,[1]分配表!$A:$A,[1]分配表!D:D)=0,"未分类",_xlfn.XLOOKUP($A14,[1]分配表!$A:$A,[1]分配表!D:D)) -> 车门系统 | G14: =_xlfn.XLOOKUP(A14,[1]分配表!J:J,[1]分配表!I:I) -> 原开品 | H14: 0 | I14: 2 | J14: 0 | K14: 0 | L14: 1 | M14: 1 | N14: 0 | O14: 2 | P14: 2 | Q14: 1 | R14: 1 | S14: 4 | T14: =IFERROR(S14-R14,S14) -> 3 | U14: 0 | V14: 44 | W14: 0 | X14: 0 | Y14: 22 | Z14: 22 | AA14: 0 | AB14: 44 | AC14: 44 | AD14: 22 | AE14: 22 | AF14: 88 | AG14: =IFERROR(AF14-AE14,AF14) -> 66 | AH14: 7 | AI14: 6 | AJ14: 8 | AK14: 11 | AL14: 3 | AM14: 5 | AN14: 10 | AO14: 9 | AP14: 6 | AQ14: 4 | AR14: 3 | AS14: 4 | AT14: 0 | AU14: 0.25 | AV14: 0 | AW14: 0 | AX14: 0.25 | AY14: 0.16666667 | AZ14: 0 | BA14: 0.1818 | BB14: 0.25 | BC14: 0.2 | BD14: 0.25 | BE14: 0.4286 | BF14: 1 | BG14: 1 | BH14: 0 | BI14: 8 | BJ14: 0 | BK14: 6 | BL14: 1 | BM14: 8 | BN14: 0 | BO14: 7 | BP14: 1 | BQ14: 8 | BR14: 未出单 | BS14: Y | BT14: Y | BU14: Y | BV14: Y | BW14: Y | BX14: Y | BY14: Y | BZ14: Y | CA14: Y | CB14: Y | CC14: Y | CD14: 正常 | CE14: 正常 | CF14: 正常 | CG14: 异常 | CH14: 正常 | CI14: 正常 | CJ14: 正常 | CK14: 异常 | CL14: 正常 | CM14: 异常 | CN14: 正常 | CO14: 异常 | CP14: 正常 | CQ14: 正常 | CR14: 正常 | CS14: 正常 | CT14: 正常 | CU14: 正常 | CV14: 正常 | CW14: 正常 | CX14: 正常 | CY14: 正常 | CZ14: 正常 | DA14: 正常 | DB14: 未上架 | DC14: 竞争无优势 | DD14: 竞争无优势 | DE14: 竞争无优势 | DF14: 竞争无优势 | DG14: 竞争无优势 | DH14: 竞争无优势 | DI14: 竞争无优势 | DJ14: 竞争无优势 | DK14: 竞争无优势 | DL14: 竞争无优势 | DM14: 竞争无优势 | DN14: 竞争无优势 | DO14: 未上架 | DP14: 无异常 | DQ14: 无异常 | DR14: 广告-PLG | DS14: 无异常 | DT14: 无异常 | DU14: 无异常 | DV14: 无异常 | DW14: 链接优化 | DX14: 无异常 | DY14: 本期不分析 | DZ14: 无异常 | EA14: Y | EB14: Y | EC14: Y | ED14: N | EE14: Y | EF14: Y | EG14: Y | EH14: 0 | EI14: 0 | EJ14: 0.07 | EK14: 0.05 | EL14: 0.04 | EM14: 0.05 | EN14: 0.05 | EO14: 0.06 | EP14: 3.33 | EQ14: 71.46
A15: 11997 | B15: LYAM-X2896 | C15: 46091 | D15: =IF(_xlfn.XLOOKUP(A15,[1]分配表!J:J,[1]分配表!M:M)=0,"未出单",_xlfn.XLOOKUP(A15,[1]分配表!J:J,[1]分配表!M:M)) -> 46105 | E15: =_xlfn.XLOOKUP(A15,[1]分配表!A:A,[1]分配表!C:C) -> 张潇 | F15: =IF(_xlfn.XLOOKUP($A15,[1]分配表!$A:$A,[1]分配表!D:D)=0,"未分类",_xlfn.XLOOKUP($A15,[1]分配表!$A:$A,[1]分配表!D:D)) -> 饰条 | G15: =_xlfn.XLOOKUP(A15,[1]分配表!J:J,[1]分配表!I:I) -> 原开品 | H15: 0 | I15: 0 | J15: 1 | K15: 0 | L15: 2 | M15: 2 | N15: 3 | O15: 0 | P15: 1 | Q15: 1 | R15: 3 | S15: 1 | T15: =IFERROR(S15-R15,S15) -> -2 | U15: 0 | V15: 0 | W15: 139 | X15: 0 | Y15: 278 | Z15: 278 | AA15: 410.05 | AB15: 0 | AC15: 139 | AD15: 132.05 | AE15: 417 | AF15: 139 | AG15: =IFERROR(AF15-AE15,AF15) -> -278 | AH15: 0 | AI15: 1 | AJ15: 0 | AK15: 2 | AL15: 0 | AM15: 1 | AN15: 0 | AO15: 0 | AP15: 0 | AQ15: 0 | AR15: 0 | AS15: 0 | AT15: 市场无出单 | AU15: 0 | AV15: 1 | AW15: 0 | AX15: 1 | AY15: 0.66666667 | AZ15: 1 | BA15: 1 | BB15: 1 | BC15: 市场无出单 | BD15: 1 | BE15: 1 | BF15: 未分析 | BG15: 7 | BH15: 7 | BI15: 15 | BJ15: 1 | BK15: 9 | BL15: 2 | BM15: 9 | BN15: 16 | BO15: 23 | BP15: 30 | BQ15: 37 | BR15: 未出单 | BS15: 未出单 | BT15: N | BU15: N | BV15: N | BW15: N | BX15: N | BY15: N | BZ15: N | CA15: N | CB15: N | CC15: N | CD15: 异常 | CE15: 正常 | CF15: 正常 | CG15: 异常 | CH15: 正常 | CI15: 异常 | CJ15: 正常 | CK15: 正常 | CL15: 正常 | CM15: 正常 | CN15: 正常 | CO15: 正常 | CP15: 异常 | CQ15: 正常 | CR15: 正常 | CS15: 正常 | CT15: 正常 | CU15: 正常 | CV15: 正常 | CW15: 正常 | CX15: 正常 | CY15: 正常 | CZ15: 正常 | DA15: 正常 | DB15: 未上架 | DC15: 无市场 | DD15: 竞争无优势 | DE15: 无市场 | DF15: 正常 | DG15: 正常 | DH15: 竞争无优势 | DI15: 正常 | DJ15: 正常 | DK15: 正常 | DL15: 无市场 | DM15: 正常 | DN15: 正常 | DO15: 未上架 | DP15: 降价测试-市场无对手 | DQ15: 未分析 | DR15: 无调整 | DS15: 无异常 | DT15: 无异常 | DU15: 无调整 | DV15: 无异常 | DW15: 无异常 | DX15: 无异常 | DY15: 无异常 | DZ15: 无异常 | EA15: N | EB15: N | EC15: N | ED15: N | EE15: N | EF15: N | EG15: N | EH15: 0 | EI15: 0 | EJ15: 0.02 | EK15: 0.02 | EL15: 0.02 | EM15: 0.02 | EN15: 0.02 | EO15: 0.02 | EP15: 8.79 | EQ15: 439.94
A16: 12262 | B16: LYAP-X2170 | C16: 46091 | D16: =IF(_xlfn.XLOOKUP(A16,[1]分配表!J:J,[1]分配表!M:M)=0,"未出单",_xlfn.XLOOKUP(A16,[1]分配表!J:J,[1]分配表!M:M)) -> 46094 | E16: =_xlfn.XLOOKUP(A16,[1]分配表!A:A,[1]分配表!C:C) -> 张潇 | F16: =IF(_xlfn.XLOOKUP($A16,[1]分配表!$A:$A,[1]分配表!D:D)=0,"未分类",_xlfn.XLOOKUP($A16,[1]分配表!$A:$A,[1]分配表!D:D)) -> 机盖及附件 | G16: =_xlfn.XLOOKUP(A16,[1]分配表!J:J,[1]分配表!I:I) -> 原开品 | H16: 0 | I16: 1 | J16: 1 | K16: 1 | L16: 2 | M16: 2 | N16: 0 | O16: 0 | P16: 1 | Q16: 0 | R16: 1 | S16: 1 | T16: =IFERROR(S16-R16,S16) -> 0 | U16: 0 | V16: 142 | W16: 142 | X16: 142 | Y16: 284 | Z16: 284 | AA16: 0 | AB16: 0 | AC16: 142 | AD16: 0 | AE16: 142 | AF16: 142 | AG16: =IFERROR(AF16-AE16,AF16) -> 0 | AH16: 0 | AI16: 1 | AJ16: 0 | AK16: 0 | AL16: 1 | AM16: 0 | AN16: 0 | AO16: 0 | AP16: 0 | AQ16: 1 | AR16: 0 | AS16: 1 | AT16: 市场无出单 | AU16: 0.5 | AV16: 1 | AW16: 1 | AX16: 0.66666667 | AY16: 1 | AZ16: 1 | BA16: 市场无出单 | BB16: 市场无出单 | BC16: 0.5 | BD16: 1 | BE16: 0.5 | BF16: 未分析 | BG16: 7 | BH16: 14 | BI16: 3 | BJ16: 9 | BK16: 5 | BL16: 11 | BM16: 18 | BN16: 25 | BO16: 32 | BP16: 39 | BQ16: 46 | BR16: 未出单 | BS16: Y | BT16: Y | BU16: Y | BV16: Y | BW16: Y | BX16: Y | BY16: Y | BZ16: Y | CA16: Y | CB16: Y | CC16: Y | CD16: 异常 | CE16: 正常 | CF16: 异常 | CG16: 正常 | CH16: 异常 | CI16: 正常 | CJ16: 正常 | CK16: 正常 | CL16: 正常 | CM16: 异常 | CN16: 正常 | CO16: 异常 | CP16: 异常 | CQ16: 正常 | CR16: 正常 | CS16: 正常 | CT16: 正常 | CU16: 正常 | CV16: 正常 | CW16: 正常 | CX16: 正常 | CY16: 正常 | CZ16: 正常 | DA16: 正常 | DB16: 未上架 | DC16: 无市场 | DD16: 竞争无优势 | DE16: 正常 | DF16: 正常 | DG16: 竞争无优势 | DH16: 正常 | DI16: 正常 | DJ16: 无市场 | DK16: 站外出单 | DL16: 竞争无优势 | DM16: 正常 | DN16: 竞争无优势 | DO16: 未上架 | DP16: 无调整 | DQ16: 无异常 | DR16: 无异常 | DS16: 无异常 | DT16: 无调整 | DU16: 无异常 | DV16: 无异常 | DW16: 无异常 | DX16: 无异常 | DY16: 本期不分析 | DZ16: 无异常 | EA16: N | EB16: N | EC16: N | ED16: N | EE16: N | EF16: N | EG16: N | EH16: 0 | EI16: 0 | EJ16: 0.02 | EK16: 0.02 | EL16: 0.02 | EM16: 0.02 | EN16: 0.02 | EO16: 0.02 | EP16: 0 | EQ16: 0
A17: 12244 | B17: LYAP-X2190-L | C17: 46091 | D17: =IF(_xlfn.XLOOKUP(A17,[1]分配表!J:J,[1]分配表!M:M)=0,"未出单",_xlfn.XLOOKUP(A17,[1]分配表!J:J,[1]分配表!M:M)) -> 46101 | E17: =_xlfn.XLOOKUP(A17,[1]分配表!A:A,[1]分配表!C:C) -> 张潇 | F17: =IF(_xlfn.XLOOKUP($A17,[1]分配表!$A:$A,[1]分配表!D:D)=0,"未分类",_xlfn.XLOOKUP($A17,[1]分配表!$A:$A,[1]分配表!D:D)) -> 饰条 | G17: =_xlfn.XLOOKUP(A17,[1]分配表!J:J,[1]分配表!I:I) -> 原开品 | H17: 0 | I17: 0 | J17: 1 | K17: 3 | L17: 2 | M17: 0 | N17: 1 | O17: 0 | P17: 0 | Q17: 1 | R17: 0 | S17: 0 | T17: =IFERROR(S17-R17,S17) -> 0 | U17: 0 | V17: 0 | W17: 38 | X17: 114 | Y17: 76 | Z17: 0 | AA17: 38 | AB17: 0 | AC17: 0 | AD17: 38 | AE17: 0 | AF17: 0 | AG17: =IFERROR(AF17-AE17,AF17) -> 0 | AH17: 0 | AI17: 0 | AJ17: 1 | AK17: 0 | AL17: 0 | AM17: 0 | AN17: 1 | AO17: 0 | AP17: 1 | AQ17: 0 | AR17: 1 | AS17: 3 | AT17: 市场无出单 | AU17: 市场无出单 | AV17: 0.5 | AW17: 1 | AX17: 1 | AY17: 0 | AZ17: 0.5 | BA17: 市场无出单 | BB17: 0 | BC17: 市场无出单 | BD17: 0.5 | BE17: 0 | BF17: 未分析 | BG17: 7 | BH17: 7 | BI17: 15 | BJ17: 0 | BK17: 8 | BL17: 0 | BM17: 0 | BN17: 7 | BO17: 2 | BP17: 5 | BQ17: 12 | BR17: 未出单 | BS17: 未出单 | BT17: N | BU17: N | BV17: N | BW17: N | BX17: N | BY17: N | BZ17: N | CA17: N | CB17: N | CC17: N | CD17: 异常 | CE17: 正常 | CF17: 正常 | CG17: 异常 | CH17: 正常 | CI17: 正常 | CJ17: 正常 | CK17: 正常 | CL17: 异常 | CM17: 正常 | CN17: 正常 | CO17: 异常 | CP17: 异常 | CQ17: 正常 | CR17: 正常 | CS17: 正常 | CT17: 正常 | CU17: 正常 | CV17: 正常 | CW17: 正常 | CX17: 正常 | CY17: 正常 | CZ17: 正常 | DA17: 正常 | DB17: 未上架 | DC17: 无市场 | DD17: 无市场 | DE17: 竞争无优势 | DF17: 正常 | DG17: 正常 | DH17: 正常 | DI17: 竞争无优势 | DJ17: 无市场 | DK17: 竞争无优势 | DL17: 无市场 | DM17: 竞争无优势 | DN17: 竞争无优势 | DO17: 未上架 | DP17: 8日新品优化 | DQ17: 未分析 | DR17: 无调整 | DS17: 无异常 | DT17: 无异常 | DU17: 无异常 | DV17: 无异常 | DW17: 无异常 | DX17: 无调整 | DY17: 无异常 | DZ17: 无异常 | EA17: Y | EB17: Y | EC17: Y | ED17: Y | EE17: Y | EF17: Y | EG17: Y | EH17: 0.36 | EI17: 0 | EJ17: 0.02 | EK17: 0 | EL17: 0 | EM17: 0 | EN17: 0.02 | EO17: 0.02 | EP17: 0 | EQ17: 0
A18: 12243 | B18: LYAP-X2190-R | C18: 46091 | D18: =IF(_xlfn.XLOOKUP(A18,[1]分配表!J:J,[1]分配表!M:M)=0,"未出单",_xlfn.XLOOKUP(A18,[1]分配表!J:J,[1]分配表!M:M)) -> 46106 | E18: =_xlfn.XLOOKUP(A18,[1]分配表!A:A,[1]分配表!C:C) -> 张潇 | F18: =IF(_xlfn.XLOOKUP($A18,[1]分配表!$A:$A,[1]分配表!D:D)=0,"未分类",_xlfn.XLOOKUP($A18,[1]分配表!$A:$A,[1]分配表!D:D)) -> 饰条 | G18: =_xlfn.XLOOKUP(A18,[1]分配表!J:J,[1]分配表!I:I) -> 原开品 | H18: 0 | I18: 0 | J18: 1 | K18: 5 | L18: 0 | M18: 0 | N18: 1 | O18: 1 | P18: 1 | Q18: 2 | R18: 1 | S18: 2 | T18: =IFERROR(S18-R18,S18) -> 1 | U18: 0 | V18: 0 | W18: 38 | X18: 190 | Y18: 0 | Z18: 0 | AA18: 38 | AB18: 38 | AC18: 38 | AD18: 76 | AE18: 36.1 | AF18: 74.86 | AG18: =IFERROR(AF18-AE18,AF18) -> 38.76 | AH18: 0 | AI18: 3 | AJ18: 1 | AK18: 0 | AL18: 2 | AM18: 2 | AN18: 1 | AO18: 2 | AP18: 1 | AQ18: 2 | AR18: 1 | AS18: 1 | AT18: 市场无出单 | AU18: 0 | AV18: 0.5 | AW18: 1 | AX18: 0 | AY18: 0 | AZ18: 0.5 | BA18: 0.3333 | BB18: 0.5 | BC18: 0.5 | BD18: 0.5 | BE18: 0.6667 | BF18: 未分析 | BG18: 7 | BH18: 7 | BI18: 15 | BJ18: 0 | BK18: 8 | BL18: 14 | BM18: 0 | BN18: 7 | BO18: 2 | BP18: 0 | BQ18: 7 | BR18: 未出单 | BS18: 未出单 | BT18: N | BU18: N | BV18: N | BW18: N | BX18: N | BY18: N | BZ18: N | CA18: N | CB18: N | CC18: N | CD18: 异常 | CE18: 正常 | CF18: 正常 | CG18: 异常 | CH18: 正常 | CI18: 正常 | CJ18: 异常 | CK18: 正常 | CL18: 异常 | CM18: 正常 | CN18: 正常 | CO18: 异常 | CP18: 异常 | CQ18: 正常 | CR18: 正常 | CS18: 正常 | CT18: 正常 | CU18: 正常 | CV18: 正常 | CW18: 正常 | CX18: 正常 | CY18: 正常 | CZ18: 正常 | DA18: 正常 | DB18: 未上架 | DC18: 无市场 | DD18: 竞争无优势 | DE18: 竞争无优势 | DF18: 正常 | DG18: 竞争无优势 | DH18: 无市场 | DI18: 竞争无优势 | DJ18: 竞争无优势 | DK18: 竞争无优势 | DL18: 竞争无优势 | DM18: 竞争无优势 | DN18: 竞争无优势 | DO18: 未上架 | DP18: 8日新品优化 | DQ18: 未分析 | DR18: 无调整 | DS18: 无异常 | DT18: 无异常 | DU18: 无异常 | DV18: 无调整 | DW18: 无异常 | DX18: 无调整 | DY18: 无异常 | DZ18: 无异常 | EA18: Y | EB18: Y | EC18: Y | ED18: Y | EE18: Y | EF18: Y | EG18: Y | EH18: 1.84 | EI18: 41.15 | EJ18: 0.02 | EK18: 0.02 | EL18: 0 | EM18: 0.02 | EN18: 0.02 | EO18: 0.02 | EP18: 0.77 | EQ18: 38.36
A19: 12304 | B19: LYAP-X1642-GR | C19: 46092 | D19: =IF(_xlfn.XLOOKUP(A19,[1]分配表!J:J,[1]分配表!M:M)=0,"未出单",_xlfn.XLOOKUP(A19,[1]分配表!J:J,[1]分配表!M:M)) -> 46095 | E19: =_xlfn.XLOOKUP(A19,[1]分配表!A:A,[1]分配表!C:C) -> 俞东旭 | F19: =IF(_xlfn.XLOOKUP($A19,[1]分配表!$A:$A,[1]分配表!D:D)=0,"未分类",_xlfn.XLOOKUP($A19,[1]分配表!$A:$A,[1]分配表!D:D)) -> 车门系统 | G19: =_xlfn.XLOOKUP(A19,[1]分配表!J:J,[1]分配表!I:I) -> 原开品 | H19: 0 | I19: 2 | J19: 3 | K19: 2 | L19: 2 | M19: 0 | N19: 0 | O19: 1 | P19: 0 | Q19: 1 | R19: 1 | S19: 1 | T19: =IFERROR(S19-R19,S19) -> 0 | U19: 0 | V19: 998 | W19: 1497 | X19: 998 | Y19: 998 | Z19: 0 | AA19: 0 | AB19: 499 | AC19: 0 | AD19: 474.05 | AE19: 499 | AF19: 499 | AG19: =IFERROR(AF19-AE19,AF19) -> 0 | AH19: 0 | AI19: 0 | AJ19: 0 | AK19: 0 | AL19: 1 | AM19: 1 | AN19: 1 | AO19: 0 | AP19: 1 | AQ19: 1 | AR19: 0 | AS19: 0 | AT19: 市场无出单 | AU19: 1 | AV19: 1 | AW19: 1 | AX19: 0.66666667 | AY19: 0 | AZ19: 0 | BA19: 1 | BB19: 0 | BC19: 0.5 | BD19: 1 | BE19: 1 | BF19: 未上架 | BG19: 6 | BH19: 0 | BI19: 8 | BJ19: 0 | BK19: 8 | BL19: 5 | BM19: 12 | BN19: 19 | BO19: 1 | BP19: 8 | BQ19: 15 | BR19: 未上架 | BS19: Y | BT19: Y | BU19: Y | BV19: Y | BW19: Y | BX19: Y | BY19: Y | BZ19: Y | CA19: Y | CB19: Y | CC19: Y | CD19: 未上架 | CE19: 正常 | CF19: 正常 | CG19: 异常 | CH19: 正常 | CI19: 异常 | CJ19: 正常 | CK19: 正常 | CL19: 异常 | CM19: 正常 | CN19: 正常 | CO19: 正常 | CP19: 未上架 | CQ19: 异常 | CR19: 正常 | CS19: 正常 | CT19: 正常 | CU19: 正常 | CV19: 正常 | CW19: 正常 | CX19: 正常 | CY19: 正常 | CZ19: 正常 | DA19: 正常 | DB19: 未上架 | DC19: 未上架 | DD19: 正常 | DE19: 正常 | DF19: 正常 | DG19: 竞争无优势 | DH19: 竞争无优势 | DI19: 竞争无优势 | DJ19: 正常 | DK19: 竞争无优势 | DL19: 竞争无优势 | DM19: 正常 | DN19: 正常 | DO19: 未上架 | DP19: 未上架 | DQ19: 无调整 | DR19: 链接优化 | DS19: 无异常 | DT19: 无异常 | DU19: 链接优化 | DV19: 无异常 | DW19: 无异常 | DX19: 无调整 | DY19: 无异常 | DZ19: 无异常 | EA19: N | EB19: N | EC19: N | ED19: N | EE19: N | EF19: N | EG19: N | EH19: 0 | EI19: 0 | EJ19: 0.02 | EK19: 0.02 | EL19: 0.02 | EM19: 0.02 | EN19: 0.02 | EO19: 0.02 | EP19: 10.8 | EQ19: 540.17
A20: 12085 | B20: LYAP-X1911-BK | C20: 46092 | D20: =IF(_xlfn.XLOOKUP(A20,[1]分配表!J:J,[1]分配表!M:M)=0,"未出单",_xlfn.XLOOKUP(A20,[1]分配表!J:J,[1]分配表!M:M)) -> 46099 | E20: =_xlfn.XLOOKUP(A20,[1]分配表!A:A,[1]分配表!C:C) -> 张潇 | F20: =IF(_xlfn.XLOOKUP($A20,[1]分配表!$A:$A,[1]分配表!D:D)=0,"未分类",_xlfn.XLOOKUP($A20,[1]分配表!$A:$A,[1]分配表!D:D)) -> 机盖及附件 | G20: =_xlfn.XLOOKUP(A20,[1]分配表!J:J,[1]分配表!I:I) -> 拓展品 | H20: 0 | I20: 1 | J20: 2 | K20: 2 | L20: 2 | M20: 6 | N20: 1 | O20: 1 | P20: 2 | Q20: 2 | R20: 4 | S20: 1 | T20: =IFERROR(S20-R20,S20) -> -3 | U20: 0 | V20: 85 | W20: 170 | X20: 170 | Y20: 170 | Z20: 505.75 | AA20: 85 | AB20: 85 | AC20: 170 | AD20: 170 | AE20: 335.75 | AF20: 85 | AG20: =IFERROR(AF20-AE20,AF20) -> -250.75 | AH20: 0 | AI20: 3 | AJ20: 0 | AK20: 3 | AL20: 4 | AM20: 2 | AN20: 1 | AO20: 3 | AP20: 1 | AQ20: 1 | AR20: 1 | AS20: 2 | AT20: 市场无出单 | AU20: 0 | AV20: 1 | AW20: 0.4 | AX20: 0.33333333 | AY20: 0.75 | AZ20: 0.6667 | BA20: 0 | BB20: 0.6667 | BC20: 0.6667 | BD20: 0.8 | BE20: 0.5 | BF20: 未上架 | BG20: 6 | BH20: 2 | BI20: 10 | BJ20: 0 | BK20: 8 | BL20: 5 | BM20: 12 | BN20: 1 | BO20: 8 | BP20: 0 | BQ20: 7 | BR20: 未上架 | BS20: 未出单 | BT20: Y | BU20: Y | BV20: Y | BW20: Y | BX20: Y | BY20: Y | BZ20: Y | CA20: Y | CB20: Y | CC20: Y | CD20: 未上架 | CE20: 正常 | CF20: 正常 | CG20: 异常 | CH20: 正常 | CI20: 正常 | CJ20: 正常 | CK20: 异常 | CL20: 正常 | CM20: 异常 | CN20: 正常 | CO20: 异常 | CP20: 未上架 | CQ20: 异常 | CR20: 正常 | CS20: 正常 | CT20: 正常 | CU20: 正常 | CV20: 正常 | CW20: 正常 | CX20: 正常 | CY20: 正常 | CZ20: 正常 | DA20: 正常 | DB20: 未上架 | DC20: 未上架 | DD20: 竞争无优势 | DE20: 竞争无优势 | DF20: 竞争无优势 | DG20: 竞争无优势 | DH20: 正常 | DI20: 竞争无优势 | DJ20: 竞争无优势 | DK20: 竞争无优势 | DL20: 竞争无优势 | DM20: 正常 | DN20: 竞争无优势 | DO20: 未上架 | DP20: 未上架 | DQ20: 广告-PLP | DR20: 无调整 | DS20: 无异常 | DT20: 无异常 | DU20: 无异常 | DV20: 无异常 | DW20: 无调整 | DX20: 无异常 | DY20: 本期不分析 | DZ20: 无异常 | EA20: N | EB20: N | EC20: N | ED20: N | EE20: N | EF20: N | EG20: N | EH20: 0 | EI20: 0 | EJ20: 0.02 | EK20: 0.02 | EL20: 0.02 | EM20: 0.02 | EN20: 0.02 | EO20: 0.02 | EP20: 7.21 | EQ20: 360.4
A21: 12086 | B21: LYAP-X1911-C | C21: 46092 | D21: =IF(_xlfn.XLOOKUP(A21,[1]分配表!J:J,[1]分配表!M:M)=0,"未出单",_xlfn.XLOOKUP(A21,[1]分配表!J:J,[1]分配表!M:M)) -> 46100 | E21: =_xlfn.XLOOKUP(A21,[1]分配表!A:A,[1]分配表!C:C) -> 张潇 | F21: =IF(_xlfn.XLOOKUP($A21,[1]分配表!$A:$A,[1]分配表!D:D)=0,"未分类",_xlfn.XLOOKUP($A21,[1]分配表!$A:$A,[1]分配表!D:D)) -> 机盖及附件 | G21: =_xlfn.XLOOKUP(A21,[1]分配表!J:J,[1]分配表!I:I) -> 原开品 | H21: 0 | I21: 0 | J21: 2 | K21: 4 | L21: 2 | M21: 2 | N21: 3 | O21: 8 | P21: 3 | Q21: 2 | R21: 1 | S21: 1 | T21: =IFERROR(S21-R21,S21) -> 0 | U21: 0 | V21: 0 | W21: 150 | X21: 300 | Y21: 146.25 | Z21: 150 | AA21: 225 | AB21: 600 | AC21: 225 | AD21: 150 | AE21: 75 | AF21: 73.99 | AG21: =IFERROR(AF21-AE21,AF21) -> -1.01 | AH21: 0 | AI21: 3 | AJ21: 7 | AK21: 5 | AL21: 5 | AM21: 5 | AN21: 6 | AO21: 4 | AP21: 1 | AQ21: 8 | AR21: 5 | AS21: 8 | AT21: 市场无出单 | AU21: 0 | AV21: 0.22222222 | AW21: 0.44444444 | AX21: 0.28571429 | AY21: 0.28571429 | AZ21: 0.25 | BA21: 0.6364 | BB21: 0.75 | BC21: 0.3333 | BD21: 0.1667 | BE21: 0.1111 | BF21: 未上架 | BG21: 6 | BH21: 2 | BI21: 10 | BJ21: 0 | BK21: 8 | BL21: 2 | BM21: 9 | BN21: 1 | BO21: 8 | BP21: 0 | BQ21: 7 | BR21: 未上架 | BS21: 未出单 | BT21: Y | BU21: Y | BV21: Y | BW21: Y | BX21: Y | BY21: Y | BZ21: Y | CA21: Y | CB21: Y | CC21: Y | CD21: 未上架 | CE21: 正常 | CF21: 正常 | CG21: 异常 | CH21: 正常 | CI21: 异常 | CJ21: 正常 | CK21: 异常 | CL21: 正常 | CM21: 异常 | CN21: 正常 | CO21: 异常 | CP21: 未上架 | CQ21: 异常 | CR21: 正常 | CS21: 正常 | CT21: 正常 | CU21: 正常 | CV21: 正常 | CW21: 正常 | CX21: 正常 | CY21: 正常 | CZ21: 正常 | DA21: 正常 | DB21: 未上架 | DC21: 未上架 | DD21: 竞争无优势 | DE21: 竞争无优势 | DF21: 竞争无优势 | DG21: 竞争无优势 | DH21: 竞争无优势 | DI21: 竞争无优势 | DJ21: 竞争无优势 | DK21: 正常 | DL21: 竞争无优势 | DM21: 竞争无优势 | DN21: 竞争无优势 | DO21: 未上架 | DP21: 未上架 | DQ21: 链接优化 | DR21: 广告-PLP | DS21: 无异常 | DT21: 无异常 | DU21: 链接优化 | DV21: 无异常 | DW21: 无调整 | DX21: 无异常 | DY21: 本期不分析 | DZ21: 无异常 | EA21: N | EB21: N | EC21: N | ED21: N | EE21: N | EF21: N | EG21: Y | EH21: 0 | EI21: 0 | EJ21: 0.02 | EK21: 0.02 | EL21: 0.02 | EM21: 0.02 | EN21: 0.02 | EO21: 0.02 | EP21: 3.17 | EQ21: 158.34
A22: 12258 | B22: LYAP-X1927 | C22: 46092 | D22: =IF(_xlfn.XLOOKUP(A22,[1]分配表!J:J,[1]分配表!M:M)=0,"未出单",_xlfn.XLOOKUP(A22,[1]分配表!J:J,[1]分配表!M:M)) -> 46099 | E22: =_xlfn.XLOOKUP(A22,[1]分配表!A:A,[1]分配表!C:C) -> 张潇 | F22: =IF(_xlfn.XLOOKUP($A22,[1]分配表!$A:$A,[1]分配表!D:D)=0,"未分类",_xlfn.XLOOKUP($A22,[1]分配表!$A:$A,[1]分配表!D:D)) -> 机盖及附件 | G22: =_xlfn.XLOOKUP(A22,[1]分配表!J:J,[1]分配表!I:I) -> 原开品 | H22: 0 | I22: 1 | J22: 7 | K22: 3 | L22: 8 | M22: 8 | N22: 7 | O22: 7 | P22: 13 | Q22: 15 | R22: 2 | S22: 12 | T22: =IFERROR(S22-R22,S22) -> 10 | U22: 0 | V22: 28 | W22: 196 | X22: 84 | Y22: 224 | Z22: 224 | AA22: 196 | AB22: 196 | AC22: 364 | AD22: 420 | AE22: 56 | AF22: 336 | AG22: =IFERROR(AF22-AE22,AF22) -> 280 | AH22: 0 | AI22: 14 | AJ22: 12 | AK22: 12 | AL22: 13 | AM22: 17 | AN22: 16 | AO22: 19 | AP22: 17 | AQ22: 43 | AR22: 23 | AS22: 10 | AT22: 市场无出单 | AU22: 0 | AV22: 0.36842105 | AW22: 0.2 | AX22: 0.38095238 | AY22: 0.32 | AZ22: 0.2727 | BA22: 0.24 | BB22: 0.3462 | BC22: 0.2833 | BD22: 0.2581 | BE22: 0.4444 | BF22: 未上架 | BG22: 6 | BH22: 2 | BI22: 10 | BJ22: 0 | BK22: 8 | BL22: 2 | BM22: 9 | BN22: 0 | BO22: 7 | BP22: 0 | BQ22: 4 | BR22: 未上架 | BS22: Y | BT22: Y | BU22: Y | BV22: Y | BW22: Y | BX22: Y | BY22: Y | BZ22: Y | CA22: Y | CB22: Y | CC22: Y | CD22: 未上架 | CE22: 正常 | CF22: 正常 | CG22: 异常 | CH22: 正常 | CI22: 异常 | CJ22: 正常 | CK22: 异常 | CL22: 正常 | CM22: 异常 | CN22: 正常 | CO22: 正常 | CP22: 未上架 | CQ22: 异常 | CR22: 正常 | CS22: 正常 | CT22: 正常 | CU22: 正常 | CV22: 正常 | CW22: 正常 | CX22: 正常 | CY22: 正常 | CZ22: 正常 | DA22: 正常 | DB22: 未上架 | DC22: 未上架 | DD22: 竞争无优势 | DE22: 竞争无优势 | DF22: 竞争无优势 | DG22: 竞争无优势 | DH22: 竞争无优势 | DI22: 竞争无优势 | DJ22: 竞争无优势 | DK22: 竞争无优势 | DL22: 竞争无优势 | DM22: 竞争无优势 | DN22: 竞争无优势 | DO22: 未上架 | DP22: 未上架 | DQ22: 无调整 | DR22: 无调整 | DS22: 无异常 | DT22: 无异常 | DU22: 无调整 | DV22: 无异常 | DW22: 链接优化 | DX22: 无异常 | DY22: 本期不分析 | DZ22: 无异常 | EA22: N | EB22: N | EC22: N | ED22: N | EE22: N | EF22: Y | EG22: Y | EH22: 9.71 | EI22: 90.87 | EJ22: 0.02 | EK22: 0.02 | EL22: 0.02 | EM22: 0.02 | EN22: 0.02 | EO22: 0.02 | EP22: 0.6 | EQ22: 29.96
A23: 12210 | B23: LYAP-X1934 | C23: 46092 | D23: =IF(_xlfn.XLOOKUP(A23,[1]分配表!J:J,[1]分配表!M:M)=0,"未出单",_xlfn.XLOOKUP(A23,[1]分配表!J:J,[1]分配表!M:M)) -> 46104 | E23: =_xlfn.XLOOKUP(A23,[1]分配表!A:A,[1]分配表!C:C) -> 张潇 | F23: =IF(_xlfn.XLOOKUP($A23,[1]分配表!$A:$A,[1]分配表!D:D)=0,"未分类",_xlfn.XLOOKUP($A23,[1]分配表!$A:$A,[1]分配表!D:D)) -> 饰条 | G23: =_xlfn.XLOOKUP(A23,[1]分配表!J:J,[1]分配表!I:I) -> 原开品 | H23: 0 | I23: 0 | J23: 1 | K23: 3 | L23: 17 | M23: 5 | N23: 4 | O23: 2 | P23: 6 | Q23: 8 | R23: 5 | S23: 9 | T23: =IFERROR(S23-R23,S23) -> 4 | U23: 0 | V23: 0 | W23: 12 | X23: 36 | Y23: 204 | Z23: 60 | AA23: 47.59 | AB23: 23.08 | AC23: 69.04 | AD23: 92.12 | AE23: 57.95 | AF23: 101.13 | AG23: =IFERROR(AF23-AE23,AF23) -> 43.18 | AH23: 0 | AI23: 39 | AJ23: 28 | AK23: 40 | AL23: 23 | AM23: 24 | AN23: 25 | AO23: 26 | AP23: 20 | AQ23: 16 | AR23: 32 | AS23: 36 | AT23: 市场无出单 | AU23: 0 | AV23: 0.034482759 | AW23: 0.069767442 | AX23: 0.425 | AY23: 0.17241379 | AZ23: 0.1667 | BA23: 0.0714 | BB23: 0.1667 | BC23: 0.3043 | BD23: 0.2 | BE23: 0.0526 | BF23: 未上架 | BG23: 6 | BH23: 2 | BI23: 10 | BJ23: 0 | BK23: 3 | BL23: 5 | BM23: 12 | BN23: 0 | BO23: 7 | BP23: 0 | BQ23: 4 | BR23: 未上架 | BS23: 未出单 | BT23: N | BU23: N | BV23: N | BW23: N | BX23: N | BY23: N | BZ23: N | CA23: N | CB23: N | CC23: N | CD23: 未上架 | CE23: 正常 | CF23: 正常 | CG23: 异常 | CH23: 正常 | CI23: 正常 | CJ23: 正常 | CK23: 异常 | CL23: 正常 | CM23: 异常 | CN23: 正常 | CO23: 正常 | CP23: 未上架 | CQ23: 异常 | CR23: 正常 | CS23: 正常 | CT23: 正常 | CU23: 正常 | CV23: 正常 | CW23: 正常 | CX23: 正常 | CY23: 正常 | CZ23: 正常 | DA23: 正常 | DB23: 未上架 | DC23: 未上架 | DD23: 竞争无优势 | DE23: 竞争无优势 | DF23: 竞争无优势 | DG23: 竞争无优势 | DH23: 竞争无优势 | DI23: 竞争无优势 | DJ23: 竞争无优势 | DK23: 竞争无优势 | DL23: 竞争无优势 | DM23: 竞争无优势 | DN23: 竞争无优势 | DO23: 未上架 | DP23: 未上架 | DQ23: 广告-PLP | DR23: 无调整 | DS23: 无异常 | DT23: 无异常 | DU23: 无异常 | DV23: 无异常 | DW23: 链接优化 | DX23: 无异常 | DY23: 本期不分析 | DZ23: 无异常 | EA23: Y | EB23: Y | EC23: Y | ED23: Y | EE23: Y | EF23: Y | EG23: Y | EH23: 6.06 | EI23: 24.76 | EJ23: 0.02 | EK23: 0 | EL23: 0 | EM23: 0.02 | EN23: 0.05 | EO23: 0.05 | EP23: 0 | EQ23: 0
A24: 12250 | B24: LYAP-X2148-1L | C24: 46092 | D24: =IF(_xlfn.XLOOKUP(A24,[1]分配表!J:J,[1]分配表!M:M)=0,"未出单",_xlfn.XLOOKUP(A24,[1]分配表!J:J,[1]分配表!M:M)) -> 46096 | E24: =_xlfn.XLOOKUP(A24,[1]分配表!A:A,[1]分配表!C:C) -> 王偲涵 | F24: =IF(_xlfn.XLOOKUP($A24,[1]分配表!$A:$A,[1]分配表!D:D)=0,"未分类",_xlfn.XLOOKUP($A24,[1]分配表!$A:$A,[1]分配表!D:D)) -> 饰条 | G24: =_xlfn.XLOOKUP(A24,[1]分配表!J:J,[1]分配表!I:I) -> 拓展品 | H24: 0 | I24: 1 | J24: 0 | K24: 1 | L24: 1 | M24: 0 | N24: 0 | O24: 0 | P24: 2 | Q24: 0 | R24: 1 | S24: 2 | T24: =IFERROR(S24-R24,S24) -> 1 | U24: 0 | V24: 39 | W24: 0 | X24: 39 | Y24: 39 | Z24: 0 | AA24: 0 | AB24: 0 | AC24: 78 | AD24: 0 | AE24: 34 | AF24: 68 | AG24: =IFERROR(AF24-AE24,AF24) -> 34 | AH24: 0 | AI24: 1 | AJ24: 2 | AK24: 0 | AL24: 1 | AM24: 0 | AN24: 0 | AO24: 0 | AP24: 2 | AQ24: 1 | AR24: 0 | AS24: 0 | AT24: 市场无出单 | AU24: 0.5 | AV24: 0 | AW24: 1 | AX24: 0.5 | AY24: 0 | AZ24: 市场无出单 | BA24: 市场无出单 | BB24: 0.5 | BC24: 0 | BD24: 1 | BE24: 1 | BF24: 未上架 | BG24: 7 | BH24: 14 | BI24: 22 | BJ24: 28 | BK24: 7 | BL24: 5 | BM24: 0 | BN24: 0 | BO24: 7 | BP24: 2 | BQ24: 9 | BR24: 未上架 | BS24: Y | BT24: Y | BU24: Y | BV24: Y | BW24: Y | BX24: Y | BY24: Y | BZ24: Y | CA24: Y | CB24: Y | CC24: Y | CD24: 未上架 | CE24: 正常 | CF24: 异常 | CG24: 异常 | CH24: 异常 | CI24: 正常 | CJ24: 正常 | CK24: 正常 | CL24: 正常 | CM24: 异常 | CN24: 正常 | CO24: 正常 | CP24: 未上架 | CQ24: 异常 | CR24: 正常 | CS24: 正常 | CT24: 正常 | CU24: 正常 | CV24: 正常 | CW24: 正常 | CX24: 正常 | CY24: 正常 | CZ24: 正常 | DA24: 正常 | DB24: 未上架 | DC24: 未上架 | DD24: 竞争无优势 | DE24: 竞争无优势 | DF24: 无市场 | DG24: 竞争无优势 | DH24: 无市场 | DI24: 无市场 | DJ24: 站外出单 | DK24: 竞争无优势 | DL24: 竞争无优势 | DM24: 正常 | DN24: 正常 | DO24: 未上架 | DP24: 未上架 | DQ24: 未分析 | DR24: 广告-PLP | DS24: 广告-PLP | DT24: 广告-PLP | DU24: 无异常 | DV24: 无异常 | DW24: 无异常 | DX24: 无异常 | DY24: 本期不分析 | DZ24: 无异常 | EA24: Y | EB24: Y | EC24: Y | ED24: Y | EE24: Y | EF24: Y | EG24: Y | EH24: 0 | EI24: 0 | EJ24: 0.02 | EK24: 0 | EL24: 0 | EM24: 0 | EN24: 0.02 | EO24: 0.02 | EP24: 0 | EQ24: 0
A25: 12251 | B25: LYAP-X2148-1R | C25: 46092 | D25: =IF(_xlfn.XLOOKUP(A25,[1]分配表!J:J,[1]分配表!M:M)=0,"未出单",_xlfn.XLOOKUP(A25,[1]分配表!J:J,[1]分配表!M:M)) -> 46112 | E25: =_xlfn.XLOOKUP(A25,[1]分配表!A:A,[1]分配表!C:C) -> 王偲涵 | F25: =IF(_xlfn.XLOOKUP($A25,[1]分配表!$A:$A,[1]分配表!D:D)=0,"未分类",_xlfn.XLOOKUP($A25,[1]分配表!$A:$A,[1]分配表!D:D)) -> 饰条 | G25: =_xlfn.XLOOKUP(A25,[1]分配表!J:J,[1]分配表!I:I) -> 拓展品 | H25: 0 | I25: 0 | J25: 0 | K25: 1 | L25: 0 | M25: 2 | N25: 0 | O25: 0 | P25: 0 | Q25: 0 | R25: 1 | S25: 0 | T25: =IFERROR(S25-R25,S25) -> -1 | U25: 0 | V25: 0 | W25: 0 | X25: 39 | Y25: 0 | Z25: 78 | AA25: 0 | AB25: 0 | AC25: 0 | AD25: 0 | AE25: 34 | AF25: 0 | AG25: =IFERROR(AF25-AE25,AF25) -> -34 | AH25: 0 | AI25: 1 | AJ25: 1 | AK25: 2 | AL25: 0 | AM25: 1 | AN25: 0 | AO25: 0 | AP25: 0 | AQ25: 0 | AR25: 1 | AS25: 1 | AT25: 市场无出单 | AU25: 0 | AV25: 0 | AW25: 0.33333333 | AX25: 0 | AY25: 0.66666667 | AZ25: 1 | BA25: 市场无出单 | BB25: 市场无出单 | BC25: 市场无出单 | BD25: 0.5 | BE25: 0 | BF25: 未上架 | BG25: 7 | BH25: 14 | BI25: 22 | BJ25: 28 | BK25: 7 | BL25: 5 | BM25: 4 | BN25: 0 | BO25: 7 | BP25: 2 | BQ25: 1 | BR25: 未上架 | BS25: 未出单 | BT25: 未出单 | BU25: N | BV25: N | BW25: N | BX25: N | BY25: N | BZ25: N | CA25: N | CB25: N | CC25: N | CD25: 未上架 | CE25: 正常 | CF25: 异常 | CG25: 异常 | CH25: 异常 | CI25: 正常 | CJ25: 正常 | CK25: 正常 | CL25: 正常 | CM25: 正常 | CN25: 正常 | CO25: 正常 | CP25: 未上架 | CQ25: 异常 | CR25: 正常 | CS25: 正常 | CT25: 正常 | CU25: 正常 | CV25: 正常 | CW25: 正常 | CX25: 正常 | CY25: 正常 | CZ25: 正常 | DA25: 正常 | DB25: 未上架 | DC25: 未上架 | DD25: 竞争无优势 | DE25: 竞争无优势 | DF25: 竞争无优势 | DG25: 无市场 | DH25: 无市场 | DI25: 正常 | DJ25: 站外出单 | DK25: 无市场 | DL25: 无市场 | DM25: 竞争无优势 | DN25: 竞争无优势 | DO25: 未上架 | DP25: 未上架 | DQ25: 未分析 | DR25: 广告-PLP | DS25: 广告-PLP | DT25: 广告-PLP | DU25: 无异常 | DV25: 无异常 | DW25: 无异常 | DX25: 无异常 | DY25: 无异常 | DZ25: 无异常 | EA25: Y | EB25: Y | EC25: Y | ED25: Y | EE25: Y | EF25: Y | EG25: Y | EH25: 1.3 | EI25: 0 | EJ25: 0.02 | EK25: 0.02 | EL25: 0.02 | EM25: 0.02 | EN25: 0.02 | EO25: 0.02 | EP25: 0.72 | EQ25: 36.21
A26: 12332 | B26: LYAP-X2289 | C26: 46092 | D26: =IF(_xlfn.XLOOKUP(A26,[1]分配表!J:J,[1]分配表!M:M)=0,"未出单",_xlfn.XLOOKUP(A26,[1]分配表!J:J,[1]分配表!M:M)) -> 46095 | E26: =_xlfn.XLOOKUP(A26,[1]分配表!A:A,[1]分配表!C:C) -> 张潇 | F26: =IF(_xlfn.XLOOKUP($A26,[1]分配表!$A:$A,[1]分配表!D:D)=0,"未分类",_xlfn.XLOOKUP($A26,[1]分配表!$A:$A,[1]分配表!D:D)) -> 饰条 | G26: =_xlfn.XLOOKUP(A26,[1]分配表!J:J,[1]分配表!I:I) -> 原开品 | H26: 0 | I26: 3 | J26: 6 | K26: 5 | L26: 5 | M26: 5 | N26: 5 | O26: 3 | P26: 2 | Q26: 4 | R26: 4 | S26: 4 | T26: =IFERROR(S26-R26,S26) -> 0 | U26: 0 | V26: 327 | W26: 654 | X26: 545 | Y26: 570 | Z26: 570 | AA26: 570 | AB26: 342 | AC26: 228 | AD26: 456 | AE26: 456 | AF26: 456 | AG26: =IFERROR(AF26-AE26,AF26) -> 0 | AH26: 0 | AI26: 2 | AJ26: 1 | AK26: 0 | AL26: 0 | AM26: 1 | AN26: 2 | AO26: 1 | AP26: 3 | AQ26: 0 | AR26: 1 | AS26: 1 | AT26: 市场无出单 | AU26: 0.3333 | AV26: 0.85714286 | AW26: 1 | AX26: 1 | AY26: 0.83333333 | AZ26: 0.7143 | BA26: 0.8 | BB26: 0.5 | BC26: 1 | BD26: 0.8 | BE26: 0.8 | BF26: 未上架 | BG26: 7 | BH26: 14 | BI26: 22 | BJ26: 0 | BK26: 8 | BL26: 14 | BM26: 2 | BN26: 9 | BO26: 2 | BP26: 9 | BQ26: 16 | BR26: 未上架 | BS26: Y | BT26: Y | BU26: Y | BV26: Y | BW26: Y | BX26: Y | BY26: Y | BZ26: Y | CA26: Y | CB26: Y | CC26: Y | CD26: 未上架 | CE26: 正常 | CF26: 异常 | CG26: 异常 | CH26: 正常 | CI26: 正常 | CJ26: 异常 | CK26: 正常 | CL26: 异常 | CM26: 正常 | CN26: 正常 | CO26: 正常 | CP26: 未上架 | CQ26: 异常 | CR26: 正常 | CS26: 正常 | CT26: 正常 | CU26: 正常 | CV26: 正常 | CW26: 正常 | CX26: 正常 | CY26: 正常 | CZ26: 正常 | DA26: 正常 | DB26: 未上架 | DC26: 未上架 | DD26: 站内无价格优势 | DE26: 正常 | DF26: 正常 | DG26: 正常 | DH26: 正常 | DI26: 正常 | DJ26: 正常 | DK26: 竞争无优势 | DL26: 正常 | DM26: 正常 | DN26: 正常 | DO26: 未上架 | DP26: 未上架 | DQ26: 未分析 | DR26: 无调整 | DS26: 无异常 | DT26: 无异常 | DU26: 无异常 | DV26: 无调整 | DW26: 无异常 | DX26: 广告-PLP | DY26: 无异常 | DZ26: 无异常 | EA26: Y | EB26: Y | EC26: Y | ED26: Y | EE26: Y | EF26: Y | EG26: Y | EH26: 4.48 | EI26: 124.97 | EJ26: 0.02 | EK26: 0.02 | EL26: 0 | EM26: 0.02 | EN26: 0.02 | EO26: 0.02 | EP26: 2.43 | EQ26: 121.55
A27: 12227 | B27: LYAP-X2418 | C27: 46092 | D27: =IF(_xlfn.XLOOKUP(A27,[1]分配表!J:J,[1]分配表!M:M)=0,"未出单",_xlfn.XLOOKUP(A27,[1]分配表!J:J,[1]分配表!M:M)) -> 46097 | E27: =_xlfn.XLOOKUP(A27,[1]分配表!A:A,[1]分配表!C:C) -> 章鹏 | F27: =IF(_xlfn.XLOOKUP($A27,[1]分配表!$A:$A,[1]分配表!D:D)=0,"未分类",_xlfn.XLOOKUP($A27,[1]分配表!$A:$A,[1]分配表!D:D)) -> 其他 | G27: =_xlfn.XLOOKUP(A27,[1]分配表!J:J,[1]分配表!I:I) -> 原开品 | H27: 0 | I27: 2 | J27: 4 | K27: 2 | L27: 3 | M27: 1 | N27: 4 | O27: 3 | P27: 5 | Q27: 4 | R27: 3 | S27: 5 | T27: =IFERROR(S27-R27,S27) -> 2 | U27: 0 | V27: 138 | W27: 276 | X27: 138 | Y27: 207 | Z27: 69 | AA27: 276 | AB27: 197 | AC27: 345 | AD27: 262.55 | AE27: 221.97 | AF27: 362.55 | AG27: =IFERROR(AF27-AE27,AF27) -> 140.58 | AH27: 0 | AI27: 4 | AJ27: 0 | AK27: 0 | AL27: 1 | AM27: 1 | AN27: 3 | AO27: 1 | AP27: 0 | AQ27: 1 | AR27: 2 | AS27: 0 | AT27: 市场无出单 | AU27: 0.3333 | AV27: 1 | AW27: 1 | AX27: 0.75 | AY27: 0.5 | AZ27: 0.5 | BA27: 0.6667 | BB27: 1 | BC27: 0.8333 | BD27: 0.5 | BE27: 1 | BF27: 未上架 | BG27: 6 | BH27: 2 | BI27: 10 | BJ27: 5 | BK27: 13 | BL27: 19 | BM27: 6 | BN27: 13 | BO27: 20 | BP27: 5 | BQ27: 12 | BR27: 未上架 | BS27: Y | BT27: Y | BU27: Y | BV27: Y | BW27: Y | BX27: Y | BY27: Y | BZ27: Y | CA27: Y | CB27: Y | CC27: Y | CD27: 未上架 | CE27: 正常 | CF27: 正常 | CG27: 异常 | CH27: 正常 | CI27: 正常 | CJ27: 异常 | CK27: 正常 | CL27: 正常 | CM27: 正常 | CN27: 正常 | CO27: 正常 | CP27: 未上架 | CQ27: 异常 | CR27: 正常 | CS27: 正常 | CT27: 正常 | CU27: 正常 | CV27: 正常 | CW27: 正常 | CX27: 正常 | CY27: 正常 | CZ27: 正常 | DA27: 正常 | DB27: 未上架 | DC27: 未上架 | DD27: 竞争无优势 | DE27: 正常 | DF27: 正常 | DG27: 正常 | DH27: 正常 | DI27: 竞争无优势 | DJ27: 竞争无优势 | DK27: 正常 | DL27: 正常 | DM27: 竞争无优势 | DN27: 正常 | DO27: 未上架 | DP27: 未上架 | DQ27: 无调整 | DR27: 链接优化 | DS27: 无异常 | DT27: 无异常 | DU27: 无异常 | DV27: 无调整 | DW27: 无异常 | DX27: 无异常 | DY27: 无异常 | DZ27: 无异常 | EA27: N | EB27: N | EC27: N | ED27: N | EE27: N | EF27: N | EG27: N | EH27: 0 | EI27: 0 | EJ27: 0.02 | EK27: 0.02 | EL27: 0.02 | EM27: 0.02 | EN27: 0.02 | EO27: 0.02 | EP27: 9.5 | EQ27: 475.91
A28: 12309 | B28: MD-002-FL | C28: 46092 | D28: =IF(_xlfn.XLOOKUP(A28,[1]分配表!J:J,[1]分配表!M:M)=0,"未出单",_xlfn.XLOOKUP(A28,[1]分配表!J:J,[1]分配表!M:M)) -> 46101 | E28: =_xlfn.XLOOKUP(A28,[1]分配表!A:A,[1]分配表!C:C) -> 俞东旭 | F28: =IF(_xlfn.XLOOKUP($A28,[1]分配表!$A:$A,[1]分配表!D:D)=0,"未分类",_xlfn.XLOOKUP($A28,[1]分配表!$A:$A,[1]分配表!D:D)) -> 车门系统 | G28: =_xlfn.XLOOKUP(A28,[1]分配表!J:J,[1]分配表!I:I) -> 原开品 | H28: 0 | I28: 0 | J28: 2 | K28: 2 | L28: 1 | M28: 0 | N28: 0 | O28: 1 | P28: 0 | Q28: 0 | R28: 0 | S28: 2 | T28: =IFERROR(S28-R28,S28) -> 2 | U28: 0 | V28: 0 | W28: 960 | X28: 960 | Y28: 480 | Z28: 0 | AA28: 0 | AB28: 480 | AC28: 0 | AD28: 0 | AE28: 0 | AF28: 957 | AG28: =IFERROR(AF28-AE28,AF28) -> 957 | AH28: 0 | AI28: 3 | AJ28: 2 | AK28: 0 | AL28: 1 | AM28: 1 | AN28: 1 | AO28: 1 | AP28: 1 | AQ28: 1 | AR28: 1 | AS28: 4 | AT28: 市场无出单 | AU28: 0 | AV28: 0.5 | AW28: 1 | AX28: 0.5 | AY28: 0 | AZ28: 0 | BA28: 0.5 | BB28: 0 | BC28: 0 | BD28: 0 | BE28: 0.2 | BF28: 未上架 | BG28: 6 | BH28: 0 | BI28: 8 | BJ28: 0 | BK28: 8 | BL28: 14 | BM28: 0 | BN28: 1 | BO28: 1 | BP28: 8 | BQ28: 15 | BR28: 未上架 | BS28: 未出单 | BT28: N | BU28: N | BV28: N | BW28: N | BX28: N | BY28: N | BZ28: N | CA28: N | CB28: N | CC28: N | CD28: 未上架 | CE28: 正常 | CF28: 正常 | CG28: 异常 | CH28: 正常 | CI28: 正常 | CJ28: 异常 | CK28: 正常 | CL28: 正常 | CM28: 正常 | CN28: 异常 | CO28: 异常 | CP28: 未上架 | CQ28: 异常 | CR28: 正常 | CS28: 正常 | CT28: 正常 | CU28: 正常 | CV28: 正常 | CW28: 正常 | CX28: 正常 | CY28: 正常 | CZ28: 正常 | DA28: 正常 | DB28: 未上架 | DC28: 未上架 | DD28: 竞争无优势 | DE28: 竞争无优势 | DF28: 正常 | DG28: 竞争无优势 | DH28: 无市场 | DI28: 竞争无优势 | DJ28: 竞争无优势 | DK28: 竞争无优势 | DL28: 竞争无优势 | DM28: 竞争无优势 | DN28: 竞争无优势 | DO28: 未上架 | DP28: 未上架 | DQ28: 无调整 | DR28: 无调整 | DS28: 无异常 | DT28: 无异常 | DU28: 无异常 | DV28: 无调整 | DW28: 无异常 | DX28: 无异常 | DY28: 无异常 | DZ28: 无调整 | EA28: N | EB28: N | EC28: N | ED28: N | EE28: N | EF28: N | EG28: N | EH28: 0 | EI28: 0 | EJ28: 0.02 | EK28: 0.02 | EL28: 0.02 | EM28: 0.02 | EN28: 0.02 | EO28: 0.02 | EP28: 10.37 | EQ28: 518.4
